Workbook

Sheet Strategic View
A1: HYPERSCALER SELECTION TEMPLATE | Select scores 1-5 for each criterion
A2: LEGEND: | B2: TEAL = Input | C2: ORANGE = AWS | D2: BLUE = Azure | E2: GREEN = GCP | F2: Scale: | G2: 1 = Low | H2: 5 = High | I2: Replace [bracketed] placeholders
A3: Customer - Hyperscaler Selection: Strategic View
A4: Strategic Goal | B4: Customer Priority | C4: AWS | D4: Azure | E4: GCP | F4: AWS Fit | G4: Azure Fit | H4: GCP Fit | I4: Key Differentiator
A5: Uptime | B5: =IF(ScoringSummary!B4="","[Select Priority]",ScoringSummary!B4) -> 4 | C5: =IF(ScoringSummary!C4="","[0.0]",ScoringSummary!C4) -> 4 | D5: =IF(ScoringSummary!D4="","[0.0]",ScoringSummary!D4) -> 4 | E5: =IF(ScoringSummary!E4="","[0.0]",ScoringSummary!E4) -> 4 | F5: =IF(OR(ScoringSummary!C4="",ScoringSummary!C4=0),"[---%]",ScoringSummary!C4/5) -> 0.8 | G5: =IF(OR(ScoringSummary!D4="",ScoringSummary!D4=0),"[---%]",ScoringSummary!D4/5) -> 0.8 | H5: =IF(OR(ScoringSummary!E4="",ScoringSummary!E4=0),"[---%]",ScoringSummary!E4/5) -> 0.8 | I5: [Enter key differentiator analysis for this strategic goal...] | J5: 3.6
A6: Reliability | B6: =IF(ScoringSummary!B5="","[Select Priority]",ScoringSummary!B5) -> [Select Priority] | C6: =IF(ScoringSummary!C5="","[0.0]",ScoringSummary!C5) -> [0.0] | D6: =IF(ScoringSummary!D5="","[0.0]",ScoringSummary!D5) -> [0.0] | E6: =IF(ScoringSummary!E5="","[0.0]",ScoringSummary!E5) -> [0.0] | F6: =IF(OR(ScoringSummary!C5="",ScoringSummary!C5=0),"[---%]",ScoringSummary!C5/5) -> [---%] | G6: =IF(OR(ScoringSummary!D5="",ScoringSummary!D5=0),"[---%]",ScoringSummary!D5/5) -> [---%] | H6: =IF(OR(ScoringSummary!E5="",ScoringSummary!E5=0),"[---%]",ScoringSummary!E5/5) -> [---%] | I6: [Enter key differentiator analysis for this strategic goal...] | J6: 3.3333333
A7: Scalability | B7: =IF(ScoringSummary!B6="","[Select Priority]",ScoringSummary!B6) -> [Select Priority] | C7: =IF(ScoringSummary!C6="","[0.0]",ScoringSummary!C6) -> [0.0] | D7: =IF(ScoringSummary!D6="","[0.0]",ScoringSummary!D6) -> [0.0] | E7: =IF(ScoringSummary!E6="","[0.0]",ScoringSummary!E6) -> [0.0] | F7: =IF(OR(ScoringSummary!C6="",ScoringSummary!C6=0),"[---%]",ScoringSummary!C6/5) -> [---%] | G7: =IF(OR(ScoringSummary!D6="",ScoringSummary!D6=0),"[---%]",ScoringSummary!D6/5) -> [---%] | H7: =IF(OR(ScoringSummary!E6="",ScoringSummary!E6=0),"[---%]",ScoringSummary!E6/5) -> [---%] | I7: [Enter key differentiator analysis for this strategic goal...] | J7: 2.5
A8: Security | B8: =IF(ScoringSummary!B7="","[Select Priority]",ScoringSummary!B7) -> [Select Priority] | C8: =IF(ScoringSummary!C7="","[0.0]",ScoringSummary!C7) -> [0.0] | D8: =IF(ScoringSummary!D7="","[0.0]",ScoringSummary!D7) -> [0.0] | E8: =IF(ScoringSummary!E7="","[0.0]",ScoringSummary!E7) -> [0.0] | F8: =IF(OR(ScoringSummary!C7="",ScoringSummary!C7=0),"[---%]",ScoringSummary!C7/5) -> [---%] | G8: =IF(OR(ScoringSummary!D7="",ScoringSummary!D7=0),"[---%]",ScoringSummary!D7/5) -> [---%] | H8: =IF(OR(ScoringSummary!E7="",ScoringSummary!E7=0),"[---%]",ScoringSummary!E7/5) -> [---%] | I8: [Enter key differentiator analysis for this strategic goal...] | J8: 3.2
A9: Performance | B9: =IF(ScoringSummary!B8="","[Select Priority]",ScoringSummary!B8) -> [Select Priority] | C9: =IF(ScoringSummary!C8="","[0.0]",ScoringSummary!C8) -> [0.0] | D9: =IF(ScoringSummary!D8="","[0.0]",ScoringSummary!D8) -> [0.0] | E9: =IF(ScoringSummary!E8="","[0.0]",ScoringSummary!E8) -> [0.0] | F9: =IF(OR(ScoringSummary!C8="",ScoringSummary!C8=0),"[---%]",ScoringSummary!C8/5) -> [---%] | G9: =IF(OR(ScoringSummary!D8="",ScoringSummary!D8=0),"[---%]",ScoringSummary!D8/5) -> [---%] | H9: =IF(OR(ScoringSummary!E8="",ScoringSummary!E8=0),"[---%]",ScoringSummary!E8/5) -> [---%] | I9: [Enter key differentiator analysis for this strategic goal...] | J9: 3.75
A10: Business Analytics | B10: =IF(ScoringSummary!B9="","[Select Priority]",ScoringSummary!B9) -> [Select Priority] | C10: =IF(ScoringSummary!C9="","[0.0]",ScoringSummary!C9) -> [0.0] | D10: =IF(ScoringSummary!D9="","[0.0]",ScoringSummary!D9) -> [0.0] | E10: =IF(ScoringSummary!E9="","[0.0]",ScoringSummary!E9) -> [0.0] | F10: =IF(OR(ScoringSummary!C9="",ScoringSummary!C9=0),"[---%]",ScoringSummary!C9/5) -> [---%] | G10: =IF(OR(ScoringSummary!D9="",ScoringSummary!D9=0),"[---%]",ScoringSummary!D9/5) -> [---%] | H10: =IF(OR(ScoringSummary!E9="",ScoringSummary!E9=0),"[---%]",ScoringSummary!E9/5) -> [---%] | I10: [Enter key differentiator analysis for this strategic goal...] | J10: 2.75
A11: Transparency | B11: =IF(ScoringSummary!B10="","[Select Priority]",ScoringSummary!B10) -> [Select Priority] | C11: =IF(ScoringSummary!C10="","[0.0]",ScoringSummary!C10) -> [0.0] | D11: =IF(ScoringSummary!D10="","[0.0]",ScoringSummary!D10) -> [0.0] | E11: =IF(ScoringSummary!E10="","[0.0]",ScoringSummary!E10) -> [0.0] | F11: =IF(OR(ScoringSummary!C10="",ScoringSummary!C10=0),"[---%]",ScoringSummary!C10/5) -> [---%] | G11: =IF(OR(ScoringSummary!D10="",ScoringSummary!D10=0),"[---%]",ScoringSummary!D10/5) -> [---%] | H11: =IF(OR(ScoringSummary!E10="",ScoringSummary!E10=0),"[---%]",ScoringSummary!E10/5) -> [---%] | I11: [Enter key differentiator analysis for this strategic goal...] | J11: 3.3333333
A12: Cost | B12: =IF(ScoringSummary!B11="","[Select Priority]",ScoringSummary!B11) -> [Select Priority] | C12: =IF(ScoringSummary!C11="","[0.0]",ScoringSummary!C11) -> [0.0] | D12: =IF(ScoringSummary!D11="","[0.0]",ScoringSummary!D11) -> [0.0] | E12: =IF(ScoringSummary!E11="","[0.0]",ScoringSummary!E11) -> [0.0] | F12: =IF(OR(ScoringSummary!C11="",ScoringSummary!C11=0),"[---%]",ScoringSummary!C11/5) -> [---%] | G12: =IF(OR(ScoringSummary!D11="",ScoringSummary!D11=0),"[---%]",ScoringSummary!D11/5) -> [---%] | H12: =IF(OR(ScoringSummary!E11="",ScoringSummary!E11=0),"[---%]",ScoringSummary!E11/5) -> [---%] | I12: [Enter key differentiator analysis for this strategic goal...] | J12: 4.8333333
A13: Sovereignty | B13: =IF(ScoringSummary!B12="","[Select Priority]",ScoringSummary!B12) -> [Select Priority] | C13: =IF(ScoringSummary!C12="","[0.0]",ScoringSummary!C12) -> [0.0] | D13: =IF(ScoringSummary!D12="","[0.0]",ScoringSummary!D12) -> [0.0] | E13: =IF(ScoringSummary!E12="","[0.0]",ScoringSummary!E12) -> [0.0] | F13: =IF(OR(ScoringSummary!C12="",ScoringSummary!C12=0),"[---%]",ScoringSummary!C12/5) -> [---%] | G13: =IF(OR(ScoringSummary!D12="",ScoringSummary!D12=0),"[---%]",ScoringSummary!D12/5) -> [---%] | H13: =IF(OR(ScoringSummary!E12="",ScoringSummary!E12=0),"[---%]",ScoringSummary!E12/5) -> [---%] | I13: [Enter key differentiator analysis for this strategic goal...] | J13: 3.3333333
A14: Business Fit | B14: =IF(ScoringSummary!B13="","[Select Priority]",ScoringSummary!B13) -> [Select Priority] | C14: =IF(ScoringSummary!C13="","[0.0]",ScoringSummary!C13) -> [0.0] | D14: =IF(ScoringSummary!D13="","[0.0]",ScoringSummary!D13) -> [0.0] | E14: =IF(ScoringSummary!E13="","[0.0]",ScoringSummary!E13) -> [0.0] | F14: =IF(OR(ScoringSummary!C13="",ScoringSummary!C13=0),"[---%]",ScoringSummary!C13/5) -> [---%] | G14: =IF(OR(ScoringSummary!D13="",ScoringSummary!D13=0),"[---%]",ScoringSummary!D13/5) -> [---%] | H14: =IF(OR(ScoringSummary!E13="",ScoringSummary!E13=0),"[---%]",ScoringSummary!E13/5) -> [---%] | I14: [Enter key differentiator analysis for this strategic goal...] | J14: 3.4444444
A15: Sustainability | B15: =IF(ScoringSummary!B14="","[Select Priority]",ScoringSummary!B14) -> [Select Priority] | C15: =IF(ScoringSummary!C14="","[0.0]",ScoringSummary!C14) -> [0.0] | D15: =IF(ScoringSummary!D14="","[0.0]",ScoringSummary!D14) -> [0.0] | E15: =IF(ScoringSummary!E14="","[0.0]",ScoringSummary!E14) -> [0.0] | F15: =IF(OR(ScoringSummary!C14="",ScoringSummary!C14=0),"[---%]",ScoringSummary!C14/5) -> [---%] | G15: =IF(OR(ScoringSummary!D14="",ScoringSummary!D14=0),"[---%]",ScoringSummary!D14/5) -> [---%] | H15: =IF(OR(ScoringSummary!E14="",ScoringSummary!E14=0),"[---%]",ScoringSummary!E14/5) -> [---%] | I15: [Enter key differentiator analysis for this strategic goal...] | J15: 2
A16: Licensing | B16: =IF(ScoringSummary!B15="","[Select Priority]",ScoringSummary!B15) -> [Select Priority] | C16: =IF(ScoringSummary!C15="","[0.0]",ScoringSummary!C15) -> [0.0] | D16: =IF(ScoringSummary!D15="","[0.0]",ScoringSummary!D15) -> [0.0] | E16: =IF(ScoringSummary!E15="","[0.0]",ScoringSummary!E15) -> [0.0] | F16: =IF(OR(ScoringSummary!C15="",ScoringSummary!C15=0),"[---%]",ScoringSummary!C15/5) -> [---%] | G16: =IF(OR(ScoringSummary!D15="",ScoringSummary!D15=0),"[---%]",ScoringSummary!D15/5) -> [---%] | H16: =IF(OR(ScoringSummary!E15="",ScoringSummary!E15=0),"[---%]",ScoringSummary!E15/5) -> [---%] | I16: [Enter key differentiator analysis for this strategic goal...] | J16: 4
A17: Velocity | B17: =IF(ScoringSummary!B16="","[Select Priority]",ScoringSummary!B16) -> [Select Priority] | C17: =IF(ScoringSummary!C16="","[0.0]",ScoringSummary!C16) -> [0.0] | D17: =IF(ScoringSummary!D16="","[0.0]",ScoringSummary!D16) -> [0.0] | E17: =IF(ScoringSummary!E16="","[0.0]",ScoringSummary!E16) -> [0.0] | F17: =IF(OR(ScoringSummary!C16="",ScoringSummary!C16=0),"[---%]",ScoringSummary!C16/5) -> [---%] | G17: =IF(OR(ScoringSummary!D16="",ScoringSummary!D16=0),"[---%]",ScoringSummary!D16/5) -> [---%] | H17: =IF(OR(ScoringSummary!E16="",ScoringSummary!E16=0),"[---%]",ScoringSummary!E16/5) -> [---%] | I17: [Enter key differentiator analysis for this strategic goal...] | J17: 4.2
A19: WEIGHTED AVERAGE | C19: =ScoringSummary!C18 -> 4 | D19: =ScoringSummary!D18 -> 4 | E19: =ScoringSummary!E18 -> 4 | F19: =ScoringSummary!F18 -> 0.8 | G19: =ScoringSummary!G18 -> 0.8 | H19: =ScoringSummary!H18 -> 0.8
A20: ABSOLUTE SCORE | C20: =ScoringSummary!C19 -> 4 | D20: =ScoringSummary!D19 -> 4 | E20: =ScoringSummary!E19 -> 4 | F20: =ScoringSummary!F19 -> 0.061538462 | G20: =ScoringSummary!G19 -> 0.061538462 | H20: =ScoringSummary!H19 -> 0.061538462
A21: PLACING | F21: =ScoringSummary!F20 -> 1 | G21: =ScoringSummary!G20 -> 1 | H21: =ScoringSummary!H20 -> 1
A23: Methodology:
A24: Each value dial within a strategic goal is scored 1-5 per cloud by the architect team. The strategic goal score is a weighted average of its value dials, using Customer's assigned priority per dial. The overall total weights each strategic goal by its average priority. The Fit Meter shows the result as a percentage of the maximum possible score. Scores are linked to the Selection Criteria sheet.

Sheet ScoringSummary
A1: SCORING SUMMARY | Enter scores 1-5 for each strategic goal
A2: LEGEND: | B2: TEAL = Input | C2: ORANGE = AWS | D2: BLUE = Azure | E2: GREEN = GCP | F2: Scale: | G2: 1 = Low | H2: 5 = High | I2: FIT % = Score ÷ 5
A3: Strategic Goal | B3: Customer Priority | C3: AWS | D3: Azure | E3: GCP | F3: AWS Fit | G3: Azure Fit | H3: GCP Fit
A4: Uptime | B4: 4 | C4: 4 | D4: 4 | E4: 4 | F4: =IF(OR(C4="",C4=0),"[---%]",C4/5) -> 0.8 | G4: =IF(OR(D4="",D4=0),"[---%]",D4/5) -> 0.8 | H4: =IF(OR(E4="",E4=0),"[---%]",E4/5) -> 0.8 | I4: 3.6
A5: Reliability | F5: =IF(OR(C5="",C5=0),"[---%]",C5/5) -> [---%] | G5: =IF(OR(D5="",D5=0),"[---%]",D5/5) -> [---%] | H5: =IF(OR(E5="",E5=0),"[---%]",E5/5) -> [---%] | I5: 3.3333333
A6: Scalability | F6: =IF(OR(C6="",C6=0),"[---%]",C6/5) -> [---%] | G6: =IF(OR(D6="",D6=0),"[---%]",D6/5) -> [---%] | H6: =IF(OR(E6="",E6=0),"[---%]",E6/5) -> [---%] | I6: 2.5
A7: Security | F7: =IF(OR(C7="",C7=0),"[---%]",C7/5) -> [---%] | G7: =IF(OR(D7="",D7=0),"[---%]",D7/5) -> [---%] | H7: =IF(OR(E7="",E7=0),"[---%]",E7/5) -> [---%] | I7: 3.2
A8: Performance | F8: =IF(OR(C8="",C8=0),"[---%]",C8/5) -> [---%] | G8: =IF(OR(D8="",D8=0),"[---%]",D8/5) -> [---%] | H8: =IF(OR(E8="",E8=0),"[---%]",E8/5) -> [---%] | I8: 3.75
A9: Business Analytics | F9: =IF(OR(C9="",C9=0),"[---%]",C9/5) -> [---%] | G9: =IF(OR(D9="",D9=0),"[---%]",D9/5) -> [---%] | H9: =IF(OR(E9="",E9=0),"[---%]",E9/5) -> [---%] | I9: 2.75
A10: Transparency | F10: =IF(OR(C10="",C10=0),"[---%]",C10/5) -> [---%] | G10: =IF(OR(D10="",D10=0),"[---%]",D10/5) -> [---%] | H10: =IF(OR(E10="",E10=0),"[---%]",E10/5) -> [---%] | I10: 3.3333333
A11: Cost | F11: =IF(OR(C11="",C11=0),"[---%]",C11/5) -> [---%] | G11: =IF(OR(D11="",D11=0),"[---%]",D11/5) -> [---%] | H11: =IF(OR(E11="",E11=0),"[---%]",E11/5) -> [---%] | I11: 4.8333333
A12: Sovereignty | F12: =IF(OR(C12="",C12=0),"[---%]",C12/5) -> [---%] | G12: =IF(OR(D12="",D12=0),"[---%]",D12/5) -> [---%] | H12: =IF(OR(E12="",E12=0),"[---%]",E12/5) -> [---%] | I12: 3.3333333
A13: Business Fit | F13: =IF(OR(C13="",C13=0),"[---%]",C13/5) -> [---%] | G13: =IF(OR(D13="",D13=0),"[---%]",D13/5) -> [---%] | H13: =IF(OR(E13="",E13=0),"[---%]",E13/5) -> [---%] | I13: 3.4444444
A14: Sustainability | F14: =IF(OR(C14="",C14=0),"[---%]",C14/5) -> [---%] | G14: =IF(OR(D14="",D14=0),"[---%]",D14/5) -> [---%] | H14: =IF(OR(E14="",E14=0),"[---%]",E14/5) -> [---%] | I14: 2
A15: Licensing | F15: =IF(OR(C15="",C15=0),"[---%]",C15/5) -> [---%] | G15: =IF(OR(D15="",D15=0),"[---%]",D15/5) -> [---%] | H15: =IF(OR(E15="",E15=0),"[---%]",E15/5) -> [---%] | I15: 4
A16: Velocity | F16: =IF(OR(C16="",C16=0),"[---%]",C16/5) -> [---%] | G16: =IF(OR(D16="",D16=0),"[---%]",D16/5) -> [---%] | H16: =IF(OR(E16="",E16=0),"[---%]",E16/5) -> [---%] | I16: 4.2
A18: WEIGHTED AVERAGE | C18: =IF(SUM(B4:B16)=0,"[Calc]",SUMPRODUCT(B4:B16,C4:C16)/SUM(B4:B16)) -> 4 | D18: =IF(SUM(B4:B16)=0,"[Calc]",SUMPRODUCT(B4:B16,D4:D16)/SUM(B4:B16)) -> 4 | E18: =IF(SUM(B4:B16)=0,"[Calc]",SUMPRODUCT(B4:B16,E4:E16)/SUM(B4:B16)) -> 4 | F18: =IF(OR(C18="[Calc]",C18=0),"[---%]",C18/5) -> 0.8 | G18: =IF(OR(D18="[Calc]",D18=0),"[---%]",D18/5) -> 0.8 | H18: =IF(OR(E18="[Calc]",E18=0),"[---%]",E18/5) -> 0.8
A19: ABSOLUTE SCORE | C19: =IF(COUNTA(C4:C16)=0,"[Calc]",SUM(C4:C16)) -> 4 | D19: =IF(COUNTA(D4:D16)=0,"[Calc]",SUM(D4:D16)) -> 4 | E19: =IF(COUNTA(E4:E16)=0,"[Calc]",SUM(E4:E16)) -> 4 | F19: =IF(OR(C19="[Calc]",C19=0),"[---%]",C19/65) -> 0.061538462 | G19: =IF(OR(D19="[Calc]",D19=0),"[---%]",D19/65) -> 0.061538462 | H19: =IF(OR(E19="[Calc]",E19=0),"[---%]",E19/65) -> 0.061538462
A20: PLACING | F20: =IF(OR(C18="[Calc]",SUM(C18:E18)=0),"[---]",RANK(C18,C18:E18,0)) -> 1 | G20: =IF(OR(D18="[Calc]",SUM(C18:E18)=0),"[---]",RANK(D18,C18:E18,0)) -> 1 | H20: =IF(OR(E18="[Calc]",SUM(C18:E18)=0),"[---]",RANK(E18,C18:E18,0)) -> 1

Sheet High+VHigh
A1: HIGH PRIORITY CRITERIA | Enter Scores & Justifications | Scale: 1=Low to 5=High
A2: LEGEND: | B2: TEAL = User Input | D2: ORANGE = AWS | F2: AWS Scores | H2: BLUE = Azure | J2: Azure Scores | L2: GREEN = GCP | N2: JUSTIFICATIONS (Provider Assessments)
A3: TOTAL | G3: =SUM(G4:G100) -> 760 | H3: =SUM(H4:H100) -> 0 | I3: =SUM(I4:I100) -> 0 | J3: =SUM(J4:J100) -> 0 | K3: =SUM(K4:K100) -> 0 | L3: =SUM(L4:L100) -> 0 | M3: =SUM(M4:M100) -> 0 | N3: — | O3: — | P3: —
A4: Uptime | B4: UPT-3 | C4: Multi-Region Resilience | D4: Required RTO/RPO targets. Is active-active multi-region failover mandatory? Automated or manual recovery? | E4: [Select Importance] | F4: [1-5] | G4: 25 | H4: [1-5] | I4: [Auto] | J4: [1-5] | K4: [Auto] | L4: [1-5] | M4: [Auto] | N4: [Enter AWS assessment: capabilities, strengths, limitations, and scoring rationale...] | O4: [Enter Azure assessment: capabilities, strengths, limitations, and scoring rationale...] | P4: [Enter GCP assessment: capabilities, strengths, limitations, and scoring rationale...]
B5: UPT-4 | C5: Planned Maintenance Transparency | D5: Required advance notice for maintenance. Is zero-downtime patching mandatory? | E5: [Select Importance] | F5: [1-5] | G5: 20 | H5: [1-5] | I5: [Auto] | J5: [1-5] | K5: [Auto] | L5: [1-5] | M5: [Auto] | N5: [Enter AWS assessment: capabilities, strengths, limitations, and scoring rationale...] | O5: [Enter Azure assessment: capabilities, strengths, limitations, and scoring rationale...] | P5: [Enter GCP assessment: capabilities, strengths, limitations, and scoring rationale...]
B6: UPT-5 | C6: Dependency Resilience | D6: Hyperscaler tolerance for outages in identity, DNS, or control plane services. Must services be independently redundant? | E6: [Select Importance] | F6: [1-5] | G6: 20 | H6: [1-5] | I6: [Auto] | J6: [1-5] | K6: [Auto] | L6: [1-5] | M6: [Auto] | N6: [Enter AWS assessment: capabilities, strengths, limitations, and scoring rationale...] | O6: [Enter Azure assessment: capabilities, strengths, limitations, and scoring rationale...] | P6: [Enter GCP assessment: capabilities, strengths, limitations, and scoring rationale...]
A7: Reliability | B7: REL-1 | C7: Data Durability | D7: Evaluate the providers data durability features, eg: number of copies, replication across regions or availability zones to ensure the integrity of data over time. | E7: [Select Importance] | F7: [1-5] | G7: 20 | H7: [1-5] | I7: [Auto] | J7: [1-5] | K7: [Auto] | L7: [1-5] | M7: [Auto] | N7: [Enter AWS assessment: capabilities, strengths, limitations, and scoring rationale...] | O7: [Enter Azure assessment: capabilities, strengths, limitations, and scoring rationale...] | P7: [Enter GCP assessment: capabilities, strengths, limitations, and scoring rationale...]
B8: REL-2 | C8: Backup and Recovery | D8: Measure the providers backup solutions, including frequency, data retention policies, and geographical replication to ensure data integrity and availability in case of failure. | E8: [Select Importance] | F8: [1-5] | G8: 20 | H8: [1-5] | I8: [Auto] | J8: [1-5] | K8: [Auto] | L8: [1-5] | M8: [Auto] | N8: [Enter AWS assessment: capabilities, strengths, limitations, and scoring rationale...] | O8: [Enter Azure assessment: capabilities, strengths, limitations, and scoring rationale...] | P8: [Enter GCP assessment: capabilities, strengths, limitations, and scoring rationale...]
A9: Scalability | B9: SCL-3 | C9: Data Scale Growth Curve | D9: Projected TB/PB growth per year. Archival and tiering requirements. | E9: [Select Importance] | F9: [1-5] | G9: 20 | H9: [1-5] | I9: [Auto] | J9: [1-5] | K9: [Auto] | L9: [1-5] | M9: [Auto] | N9: [Enter AWS assessment: capabilities, strengths, limitations, and scoring rationale...] | O9: [Enter Azure assessment: capabilities, strengths, limitations, and scoring rationale...] | P9: [Enter GCP assessment: capabilities, strengths, limitations, and scoring rationale...]
A10: Security | B10: SEC-1 | C10: Regulatory Compliance Alignment | D10: Evaluate the providers certifications (ISO 27001, SOC 2, PCI DSS) and regulatory compliance (e.g., GDPR, HIPAA, CCPA) with industry and regional requirements. | E10: [Select Importance] | F10: [1-5] | G10: 25 | H10: [1-5] | I10: [Auto] | J10: [1-5] | K10: [Auto] | L10: [1-5] | M10: [Auto] | N10: [Enter AWS assessment: capabilities, strengths, limitations, and scoring rationale...] | O10: [Enter Azure assessment: capabilities, strengths, limitations, and scoring rationale...] | P10: [Enter GCP assessment: capabilities, strengths, limitations, and scoring rationale...]
B11: SEC-2 | C11: Identity & Access Maturity | D11: Enterprise IdP integration. Zero-trust and conditional access requirements. | E11: [Select Importance] | F11: [1-5] | G11: 20 | H11: [1-5] | I11: [Auto] | J11: [1-5] | K11: [Auto] | L11: [1-5] | M11: [Auto] | N11: [Enter AWS assessment: capabilities, strengths, limitations, and scoring rationale...] | O11: [Enter Azure assessment: capabilities, strengths, limitations, and scoring rationale...] | P11: [Enter GCP assessment: capabilities, strengths, limitations, and scoring rationale...]
B12: SEC-4 | C12: Threat Detection & SOC Integration | D12: Native SIEM/XDR maturity or integration with existing SOC tooling. | E12: [Select Importance] | F12: [1-5] | G12: 20 | H12: [1-5] | I12: [Auto] | J12: [1-5] | K12: [Auto] | L12: [1-5] | M12: [Auto] | N12: [Enter AWS assessment: capabilities, strengths, limitations, and scoring rationale...] | O12: [Enter Azure assessment: capabilities, strengths, limitations, and scoring rationale...] | P12: [Enter GCP assessment: capabilities, strengths, limitations, and scoring rationale...]
A13: Performance | B13: PERF-1 | C13: Latency Sensitivity | D13: Maximum acceptable latency (ms). Requirement for edge locations or local zones. | E13: [Select Importance] | F13: [1-5] | G13: 20 | H13: [1-5] | I13: [Auto] | J13: [1-5] | K13: [Auto] | L13: [1-5] | M13: [Auto] | N13: [Enter AWS assessment: capabilities, strengths, limitations, and scoring rationale...] | O13: [Enter Azure assessment: capabilities, strengths, limitations, and scoring rationale...] | P13: [Enter GCP assessment: capabilities, strengths, limitations, and scoring rationale...]
B14: PERF-3 | C14: Storage Throughput | D14: Required IOPS and throughput for core databases or analytics platforms. | E14: [Select Importance] | F14: [1-5] | G14: 20 | H14: [1-5] | I14: [Auto] | J14: [1-5] | K14: [Auto] | L14: [1-5] | M14: [Auto] | N14: [Enter AWS assessment: capabilities, strengths, limitations, and scoring rationale...] | O14: [Enter Azure assessment: capabilities, strengths, limitations, and scoring rationale...] | P14: [Enter GCP assessment: capabilities, strengths, limitations, and scoring rationale...]
B15: PERF-4 | C15: Network Backbone Quality | D15: Requirement for deterministic private backbone routing vs public internet transit. | E15: [Select Importance] | F15: [1-5] | G15: 20 | H15: [1-5] | I15: [Auto] | J15: [1-5] | K15: [Auto] | L15: [1-5] | M15: [Auto] | N15: [Enter AWS assessment: capabilities, strengths, limitations, and scoring rationale...] | O15: [Enter Azure assessment: capabilities, strengths, limitations, and scoring rationale...] | P15: [Enter GCP assessment: capabilities, strengths, limitations, and scoring rationale...]
A16: Transparency | B16: TRN-2 | C16: Incident Reporting Detail | D16: Required depth of RCA and incident transparency. | E16: [Select Importance] | F16: [1-5] | G16: 20 | H16: [1-5] | I16: [Auto] | J16: [1-5] | K16: [Auto] | L16: [1-5] | M16: [Auto] | N16: [Enter AWS assessment: capabilities, strengths, limitations, and scoring rationale...] | O16: [Enter Azure assessment: capabilities, strengths, limitations, and scoring rationale...] | P16: [Enter GCP assessment: capabilities, strengths, limitations, and scoring rationale...]
B17: TRN-3 | C17: Billing Granularity | D17: Near-real-time cost visibility at workload or tag level required? | E17: [Select Importance] | F17: [1-5] | G17: 20 | H17: [1-5] | I17: [Auto] | J17: [1-5] | K17: [Auto] | L17: [1-5] | M17: [Auto] | N17: [Enter AWS assessment: capabilities, strengths, limitations, and scoring rationale...] | O17: [Enter Azure assessment: capabilities, strengths, limitations, and scoring rationale...] | P17: [Enter GCP assessment: capabilities, strengths, limitations, and scoring rationale...]
A18: Cost | B18: CST-1 | C18: TCO | D18: Evaluate overall TCO, including, infrastructure, storage, licensing, networking, backup, support and hyperscaler credits, over a 3-year period. | E18: [Select Importance] | F18: [1-5] | G18: 25 | H18: [1-5] | I18: [Auto] | J18: [1-5] | K18: [Auto] | L18: [1-5] | M18: [Auto] | N18: [Enter AWS assessment: capabilities, strengths, limitations, and scoring rationale...] | O18: [Enter Azure assessment: capabilities, strengths, limitations, and scoring rationale...] | P18: [Enter GCP assessment: capabilities, strengths, limitations, and scoring rationale...]
B19: CST-2 | C19: Predictability vs Elasticity | D19: Preference for reserved/committed pricing vs fully elastic consumption, including spot pricing | E19: [Select Importance] | F19: [1-5] | G19: 25 | H19: [1-5] | I19: [Auto] | J19: [1-5] | K19: [Auto] | L19: [1-5] | M19: [Auto] | N19: [Enter AWS assessment: capabilities, strengths, limitations, and scoring rationale...] | O19: [Enter Azure assessment: capabilities, strengths, limitations, and scoring rationale...] | P19: [Enter GCP assessment: capabilities, strengths, limitations, and scoring rationale...]
B20: CST-3 | C20: Egress Sensitivity | D20: Network Traffic Cost comparison: Hybrid networking, Cross-cloud traffic, Data Egress | E20: [Select Importance] | F20: [1-5] | G20: 25 | H20: [1-5] | I20: [Auto] | J20: [1-5] | K20: [Auto] | L20: [1-5] | M20: [Auto] | N20: [Enter AWS assessment: capabilities, strengths, limitations, and scoring rationale...] | O20: [Enter Azure assessment: capabilities, strengths, limitations, and scoring rationale...] | P20: [Enter GCP assessment: capabilities, strengths, limitations, and scoring rationale...]
B21: CST-4 | C21: Discount Programs | D21: Enterprise agreement leverage or committed spend incentives required? | E21: [Select Importance] | F21: [1-5] | G21: 25 | H21: [1-5] | I21: [Auto] | J21: [1-5] | K21: [Auto] | L21: [1-5] | M21: [Auto] | N21: [Enter AWS assessment: capabilities, strengths, limitations, and scoring rationale...] | O21: [Enter Azure assessment: capabilities, strengths, limitations, and scoring rationale...] | P21: [Enter GCP assessment: capabilities, strengths, limitations, and scoring rationale...]
B22: CST-5 | C22: Migration Costs | D22: Assess one-time costs for migration, including tools, labor, re-architecting, and incentives offered by providers. (Data Center Exit incentives, Funding Programs.) | E22: [Select Importance] | F22: [1-5] | G22: 25 | H22: [1-5] | I22: [Auto] | J22: [1-5] | K22: [Auto] | L22: [1-5] | M22: [Auto] | N22: [Enter AWS assessment: capabilities, strengths, limitations, and scoring rationale...] | O22: [Enter Azure assessment: capabilities, strengths, limitations, and scoring rationale...] | P22: [Enter GCP assessment: capabilities, strengths, limitations, and scoring rationale...]
B23: CST-6 | C23: FinOps Tooling | D23: Native cost optimization tooling sufficient or external integration required? | E23: [Select Importance] | F23: [1-5] | G23: 20 | H23: [1-5] | I23: [Auto] | J23: [1-5] | K23: [Auto] | L23: [1-5] | M23: [Auto] | N23: [Enter AWS assessment: capabilities, strengths, limitations, and scoring rationale...] | O23: [Enter Azure assessment: capabilities, strengths, limitations, and scoring rationale...] | P23: [Enter GCP assessment: capabilities, strengths, limitations, and scoring rationale...]
A24: Sovereignty | B24: SOV-1 | C24: Data Residency Requirements | D24: Support for Mandated data storage countries or regions. | E24: [Select Importance] | F24: [1-5] | G24: 20 | H24: [1-5] | I24: [Auto] | J24: [1-5] | K24: [Auto] | L24: [1-5] | M24: [Auto] | N24: [Enter AWS assessment: capabilities, strengths, limitations, and scoring rationale...] | O24: [Enter Azure assessment: capabilities, strengths, limitations, and scoring rationale...] | P24: [Enter GCP assessment: capabilities, strengths, limitations, and scoring rationale...]
A25: Business Fit | B25: FIT-3 | C25: 3rd Party Integration | D25: Does the provider offer native support for application layer tools (eg: CDN, DNS, Certificate Management, Firewall) | E25: [Select Importance] | F25: [1-5] | G25: 20 | H25: [1-5] | I25: [Auto] | J25: [1-5] | K25: [Auto] | L25: [1-5] | M25: [Auto] | N25: [Enter AWS assessment: capabilities, strengths, limitations, and scoring rationale...] | O25: [Enter Azure assessment: capabilities, strengths, limitations, and scoring rationale...] | P25: [Enter GCP assessment: capabilities, strengths, limitations, and scoring rationale...]
B26: FIT-5 | C26: Partner & Talent Availability | D26: Local skilled labor and partner ecosystem maturity. (SI Partners, MSPs etc) | E26: [Select Importance] | F26: [1-5] | G26: 20 | H26: [1-5] | I26: [Auto] | J26: [1-5] | K26: [Auto] | L26: [1-5] | M26: [Auto] | N26: [Enter AWS assessment: capabilities, strengths, limitations, and scoring rationale...] | O26: [Enter Azure assessment: capabilities, strengths, limitations, and scoring rationale...] | P26: [Enter GCP assessment: capabilities, strengths, limitations, and scoring rationale...]
B27: FIT-6 | C27: Executive Relationship & Strategic Alignment | D27: Does the provider demonstrate executive engagement aligned to the customers 35 year strategy? Is there a named account team and industry specialist coverage? | E27: [Select Importance] | F27: [1-5] | G27: 25 | H27: [1-5] | I27: [Auto] | J27: [1-5] | K27: [Auto] | L27: [1-5] | M27: [Auto] | N27: [Enter AWS assessment: capabilities, strengths, limitations, and scoring rationale...] | O27: [Enter Azure assessment: capabilities, strengths, limitations, and scoring rationale...] | P27: [Enter GCP assessment: capabilities, strengths, limitations, and scoring rationale...]
B28: FIT-8 | C28: Day 0,1,2 Operations | D28: How well is Customer positioned to support Day 0/Day 1/Day 2 operations? | E28: [Select Importance] | F28: [1-5] | G28: 25 | H28: [1-5] | I28: [Auto] | J28: [1-5] | K28: [Auto] | L28: [1-5] | M28: [Auto] | N28: [Enter AWS assessment: capabilities, strengths, limitations, and scoring rationale...] | O28: [Enter Azure assessment: capabilities, strengths, limitations, and scoring rationale...] | P28: [Enter GCP assessment: capabilities, strengths, limitations, and scoring rationale...]
B29: FIT-9 | C29: Target Operating Model | D29: Evaluate customer ability to enforce new operating model and reduce shadow IT across each of the hypervisors | E29: [Select Importance] | F29: [1-5] | G29: 20 | H29: [1-5] | I29: [Auto] | J29: [1-5] | K29: [Auto] | L29: [1-5] | M29: [Auto] | N29: [Enter AWS assessment: capabilities, strengths, limitations, and scoring rationale...] | O29: [Enter Azure assessment: capabilities, strengths, limitations, and scoring rationale...] | P29: [Enter GCP assessment: capabilities, strengths, limitations, and scoring rationale...]
B30: FIT-10 | C30: Database Migration Path | D30: Native tooling and managed services for migrating Oracle/SQL Server databases to cloud-native alternatives (e.g., PostgreSQL). Includes schema conversion, data replication, and performance validation. | E30: [Select Importance] | F30: [1-5] | G30: 25 | H30: [1-5] | I30: [Auto] | J30: [1-5] | K30: [Auto] | L30: [1-5] | M30: [Auto] | N30: [Enter AWS assessment: capabilities, strengths, limitations, and scoring rationale...] | O30: [Enter Azure assessment: capabilities, strengths, limitations, and scoring rationale...] | P30: [Enter GCP assessment: capabilities, strengths, limitations, and scoring rationale...]
A31: Licensing | B31: LIC-1 | C31: BYOL Flexibility | D31: Ability to port existing enterprise licenses without penalty. | E31: [Select Importance] | F31: [1-5] | G31: 20 | H31: [1-5] | I31: [Auto] | J31: [1-5] | K31: [Auto] | L31: [1-5] | M31: [Auto] | N31: [Enter AWS assessment: capabilities, strengths, limitations, and scoring rationale...] | O31: [Enter Azure assessment: capabilities, strengths, limitations, and scoring rationale...] | P31: [Enter GCP assessment: capabilities, strengths, limitations, and scoring rationale...]
B32: LIC-2 | C32: Hybrid Licensing Benefits | D32: Cost advantages for hybrid/on-prem integrated usage. (eg: Oracle Licenses) | E32: [Select Importance] | F32: [1-5] | G32: 25 | H32: [1-5] | I32: [Auto] | J32: [1-5] | K32: [Auto] | L32: [1-5] | M32: [Auto] | N32: [Enter AWS assessment: capabilities, strengths, limitations, and scoring rationale...] | O32: [Enter Azure assessment: capabilities, strengths, limitations, and scoring rationale...] | P32: [Enter GCP assessment: capabilities, strengths, limitations, and scoring rationale...]
A33: Velocity | B33: VEL-1 | C33: DevOps Toolchain Integration | D33: Native integration with existing CI/CD and DevOps pipelines. | E33: [Select Importance] | F33: [1-5] | G33: 20 | H33: [1-5] | I33: [Auto] | J33: [1-5] | K33: [Auto] | L33: [1-5] | M33: [Auto] | N33: [Enter AWS assessment: capabilities, strengths, limitations, and scoring rationale...] | O33: [Enter Azure assessment: capabilities, strengths, limitations, and scoring rationale...] | P33: [Enter GCP assessment: capabilities, strengths, limitations, and scoring rationale...]
B34: VEL-2 | C34: Infrastructure as Code Maturity | D34: Depth and maturity of native IaC tooling and ecosystem support. | E34: [Select Importance] | F34: [1-5] | G34: 20 | H34: [1-5] | I34: [Auto] | J34: [1-5] | K34: [Auto] | L34: [1-5] | M34: [Auto] | N34: [Enter AWS assessment: capabilities, strengths, limitations, and scoring rationale...] | O34: [Enter Azure assessment: capabilities, strengths, limitations, and scoring rationale...] | P34: [Enter GCP assessment: capabilities, strengths, limitations, and scoring rationale...]
B35: VEL-3 | C35: Managed Service Abstraction | D35: Preference for PaaS/serverless over IaaS-heavy models. | E35: [Select Importance] | F35: [1-5] | G35: 20 | H35: [1-5] | I35: [Auto] | J35: [1-5] | K35: [Auto] | L35: [1-5] | M35: [Auto] | N35: [Enter AWS assessment: capabilities, strengths, limitations, and scoring rationale...] | O35: [Enter Azure assessment: capabilities, strengths, limitations, and scoring rationale...] | P35: [Enter GCP assessment: capabilities, strengths, limitations, and scoring rationale...]
B36: VEL-4 | C36: Time-to-Prototype | D36: Expected time to deploy MVP workloads (days vs weeks). | E36: [Select Importance] | F36: [1-5] | G36: 20 | H36: [1-5] | I36: [Auto] | J36: [1-5] | K36: [Auto] | L36: [1-5] | M36: [Auto] | N36: [Enter AWS assessment: capabilities, strengths, limitations, and scoring rationale...] | O36: [Enter Azure assessment: capabilities, strengths, limitations, and scoring rationale...] | P36: [Enter GCP assessment: capabilities, strengths, limitations, and scoring rationale...]
B37: VEL-5 | C37: AI Tooling Integration | D37: Availability, ease-of-use, and platform-wide-integration Cloud Native AI Development (vibe coding) Tooling | E37: [Select Importance] | F37: [1-5] | G37: 25 | H37: [1-5] | I37: [Auto] | J37: [1-5] | K37: [Auto] | L37: [1-5] | M37: [Auto] | N37: [Enter AWS assessment: capabilities, strengths, limitations, and scoring rationale...] | O37: [Enter Azure assessment: capabilities, strengths, limitations, and scoring rationale...] | P37: [Enter GCP assessment: capabilities, strengths, limitations, and scoring rationale...]
B38: VEL-6 | C38: Container & Kubernetes Maturity | D38: Maturity of managed Kubernetes, serverless containers, and container ecosystem. Includes autoscaling, networking, observability, and operational overhead for container workloads. | E38: [Select Importance] | F38: [1-5] | G38: 20 | H38: [1-5] | I38: [Auto] | J38: [1-5] | K38: [Auto] | L38: [1-5] | M38: [Auto] | N38: [Enter AWS assessment: capabilities, strengths, limitations, and scoring rationale...] | O38: [Enter Azure assessment: capabilities, strengths, limitations, and scoring rationale...] | P38: [Enter GCP assessment: capabilities, strengths, limitations, and scoring rationale...]

Sheet Selection Criteria
A1: SELECTION CRITERIA | Complete Scoring Template | Scale: 1=Low to 5=High
A2: LEGEND: | B2: TEAL = User Input | D2: ORANGE = AWS | F2: AWS Scores | H2: BLUE = Azure | J2: Azure Scores | L2: GREEN = GCP | N2: JUSTIFICATIONS (Provider Assessments)
A3: TOTAL | F3: =SUMIF(F5:F61,">0") -> 0 | G3: =SUM(G5:G61) -> 1045 | H3: =SUMIF(H5:H61,">0") -> 0 | I3: =SUMIF(I5:I61,">0") -> 0 | J3: =SUMIF(J5:J61,">0") -> 0 | K3: =SUMIF(K5:K61,">0") -> 0 | L3: =SUMIF(L5:L61,">0") -> 0 | N3: — | O3: — | P3: —
A4: Strategic Goal | B4: Criteria Code | C4: Value Dial | D4: Question / Description | E4: Importance | F4: AWS Score | G4: Max | H4: AWS Weighted | I4: Azure Score | J4: Azure Weighted | K4: GCP Score | L4: GCP Weighted | N4: AWS Justification | O4: Azure Justification | P4: GCP Justification
A5: Uptime | B5: UPT-1 | C5: SLA Commitment | D5: Required SLA percentage (e.g., 99.95%, 99.99%). Financial penalty expectations if breached. | G5: 25 | H5: =IF(ISNUMBER(F5),F5*G5/5,"[Auto]") -> [Auto] | J5: =IF(ISNUMBER(I5),I5*G5/5,"[Auto]") -> [Auto] | L5: =IF(ISNUMBER(K5),K5*G5/5,"[Auto]") -> [Auto] | N5: [Enter AWS assessment...] | O5: [Enter Azure assessment...] | P5: [Enter GCP assessment...]
B6: UPT-2 | C6: Historical Availability | D6: Review provider's historical uptime and recent outages affecting critical services. | G6: 20 | H6: =IF(ISNUMBER(F6),F6*G6/5,"[Auto]") -> [Auto] | J6: =IF(ISNUMBER(I6),I6*G6/5,"[Auto]") -> [Auto] | L6: =IF(ISNUMBER(K6),K6*G6/5,"[Auto]") -> [Auto] | N6: [Enter AWS assessment...] | O6: [Enter Azure assessment...] | P6: [Enter GCP assessment...]
B7: UPT-3 | C7: Multi-Region Resilience | D7: Required RTO/RPO targets. Is active-active multi-region failover mandatory? | G7: 25 | H7: =IF(ISNUMBER(F7),F7*G7/5,"[Auto]") -> [Auto] | J7: =IF(ISNUMBER(I7),I7*G7/5,"[Auto]") -> [Auto] | L7: =IF(ISNUMBER(K7),K7*G7/5,"[Auto]") -> [Auto] | N7: [Enter AWS assessment...] | O7: [Enter Azure assessment...] | P7: [Enter GCP assessment...]
B8: UPT-4 | C8: Planned Maintenance Transparency | D8: Required advance notice for maintenance. Is zero-downtime patching mandatory? | G8: 20 | H8: =IF(ISNUMBER(F8),F8*G8/5,"[Auto]") -> [Auto] | J8: =IF(ISNUMBER(I8),I8*G8/5,"[Auto]") -> [Auto] | L8: =IF(ISNUMBER(K8),K8*G8/5,"[Auto]") -> [Auto] | N8: [Enter AWS assessment...] | O8: [Enter Azure assessment...] | P8: [Enter GCP assessment...]
B9: UPT-5 | C9: Dependency Resilience | D9: Hyperscaler tolerance for outages in identity, DNS, or control plane services. | G9: 20 | H9: =IF(ISNUMBER(F9),F9*G9/5,"[Auto]") -> [Auto] | J9: =IF(ISNUMBER(I9),I9*G9/5,"[Auto]") -> [Auto] | L9: =IF(ISNUMBER(K9),K9*G9/5,"[Auto]") -> [Auto] | N9: [Enter AWS assessment...] | O9: [Enter Azure assessment...] | P9: [Enter GCP assessment...]
A10: Reliability | B10: REL-1 | C10: Data Durability | D10: Evaluate data durability features: number of copies, replication across regions/AZs. | G10: 20 | H10: =IF(ISNUMBER(F10),F10*G10/5,"[Auto]") -> [Auto] | J10: =IF(ISNUMBER(I10),I10*G10/5,"[Auto]") -> [Auto] | L10: =IF(ISNUMBER(K10),K10*G10/5,"[Auto]") -> [Auto] | N10: [Enter AWS assessment...] | O10: [Enter Azure assessment...] | P10: [Enter GCP assessment...]
B11: REL-2 | C11: Backup and Recovery | D11: Backup solutions including frequency, retention policies, and geo-replication. | G11: 20 | H11: =IF(ISNUMBER(F11),F11*G11/5,"[Auto]") -> [Auto] | J11: =IF(ISNUMBER(I11),I11*G11/5,"[Auto]") -> [Auto] | L11: =IF(ISNUMBER(K11),K11*G11/5,"[Auto]") -> [Auto] | N11: [Enter AWS assessment...] | O11: [Enter Azure assessment...] | P11: [Enter GCP assessment...]
B12: REL-3 | C12: Fault Isolation | D12: Evaluate blast radius containment and fault domain isolation capabilities. | G12: 15 | H12: =IF(ISNUMBER(F12),F12*G12/5,"[Auto]") -> [Auto] | J12: =IF(ISNUMBER(I12),I12*G12/5,"[Auto]") -> [Auto] | L12: =IF(ISNUMBER(K12),K12*G12/5,"[Auto]") -> [Auto] | N12: [Enter AWS assessment...] | O12: [Enter Azure assessment...] | P12: [Enter GCP assessment...]
A13: Scalability | B13: SCL-1 | C13: Horizontal Scaling | D13: Ability to scale out workloads automatically based on demand. | G13: 20 | H13: =IF(ISNUMBER(F13),F13*G13/5,"[Auto]") -> [Auto] | J13: =IF(ISNUMBER(I13),I13*G13/5,"[Auto]") -> [Auto] | L13: =IF(ISNUMBER(K13),K13*G13/5,"[Auto]") -> [Auto] | N13: [Enter AWS assessment...] | O13: [Enter Azure assessment...] | P13: [Enter GCP assessment...]
B14: SCL-2 | C14: Vertical Scaling | D14: Ability to scale up resources with minimal disruption. | G14: 15 | H14: =IF(ISNUMBER(F14),F14*G14/5,"[Auto]") -> [Auto] | J14: =IF(ISNUMBER(I14),I14*G14/5,"[Auto]") -> [Auto] | L14: =IF(ISNUMBER(K14),K14*G14/5,"[Auto]") -> [Auto] | N14: [Enter AWS assessment...] | O14: [Enter Azure assessment...] | P14: [Enter GCP assessment...]
B15: SCL-3 | C15: Data Scale Growth Curve | D15: Projected TB/PB growth per year. Archival and tiering requirements. | G15: 20 | H15: =IF(ISNUMBER(F15),F15*G15/5,"[Auto]") -> [Auto] | J15: =IF(ISNUMBER(I15),I15*G15/5,"[Auto]") -> [Auto] | L15: =IF(ISNUMBER(K15),K15*G15/5,"[Auto]") -> [Auto] | N15: [Enter AWS assessment...] | O15: [Enter Azure assessment...] | P15: [Enter GCP assessment...]
B16: SCL-4 | C16: Global Distribution | D16: Multi-region deployment and data replication capabilities. | G16: 15 | H16: =IF(ISNUMBER(F16),F16*G16/5,"[Auto]") -> [Auto] | J16: =IF(ISNUMBER(I16),I16*G16/5,"[Auto]") -> [Auto] | L16: =IF(ISNUMBER(K16),K16*G16/5,"[Auto]") -> [Auto] | N16: [Enter AWS assessment...] | O16: [Enter Azure assessment...] | P16: [Enter GCP assessment...]
A17: Security | B17: SEC-1 | C17: Regulatory Compliance Alignment | D17: Certifications (ISO 27001, SOC 2, PCI DSS) and compliance (GDPR, HIPAA, CCPA). | G17: 25 | H17: =IF(ISNUMBER(F17),F17*G17/5,"[Auto]") -> [Auto] | J17: =IF(ISNUMBER(I17),I17*G17/5,"[Auto]") -> [Auto] | L17: =IF(ISNUMBER(K17),K17*G17/5,"[Auto]") -> [Auto] | N17: [Enter AWS assessment...] | O17: [Enter Azure assessment...] | P17: [Enter GCP assessment...]
B18: SEC-2 | C18: Identity & Access Maturity | D18: Enterprise IdP integration. Zero-trust and conditional access requirements. | G18: 20 | H18: =IF(ISNUMBER(F18),F18*G18/5,"[Auto]") -> [Auto] | J18: =IF(ISNUMBER(I18),I18*G18/5,"[Auto]") -> [Auto] | L18: =IF(ISNUMBER(K18),K18*G18/5,"[Auto]") -> [Auto] | N18: [Enter AWS assessment...] | O18: [Enter Azure assessment...] | P18: [Enter GCP assessment...]
B19: SEC-3 | C19: Data Encryption | D19: Encryption at rest, in transit, and key management capabilities. | G19: 20 | H19: =IF(ISNUMBER(F19),F19*G19/5,"[Auto]") -> [Auto] | J19: =IF(ISNUMBER(I19),I19*G19/5,"[Auto]") -> [Auto] | L19: =IF(ISNUMBER(K19),K19*G19/5,"[Auto]") -> [Auto] | N19: [Enter AWS assessment...] | O19: [Enter Azure assessment...] | P19: [Enter GCP assessment...]
B20: SEC-4 | C20: Threat Detection & SOC Integration | D20: Native SIEM/XDR maturity or integration with existing SOC tooling. | G20: 20 | H20: =IF(ISNUMBER(F20),F20*G20/5,"[Auto]") -> [Auto] | J20: =IF(ISNUMBER(I20),I20*G20/5,"[Auto]") -> [Auto] | L20: =IF(ISNUMBER(K20),K20*G20/5,"[Auto]") -> [Auto] | N20: [Enter AWS assessment...] | O20: [Enter Azure assessment...] | P20: [Enter GCP assessment...]
B21: SEC-5 | C21: Network Security | D21: VPC isolation, firewall capabilities, DDoS protection, and private connectivity. | G21: 15 | H21: =IF(ISNUMBER(F21),F21*G21/5,"[Auto]") -> [Auto] | J21: =IF(ISNUMBER(I21),I21*G21/5,"[Auto]") -> [Auto] | L21: =IF(ISNUMBER(K21),K21*G21/5,"[Auto]") -> [Auto] | N21: [Enter AWS assessment...] | O21: [Enter Azure assessment...] | P21: [Enter GCP assessment...]
A22: Performance | B22: PERF-1 | C22: Latency Sensitivity | D22: Maximum acceptable latency (ms). Requirement for edge locations. | G22: 20 | H22: =IF(ISNUMBER(F22),F22*G22/5,"[Auto]") -> [Auto] | J22: =IF(ISNUMBER(I22),I22*G22/5,"[Auto]") -> [Auto] | L22: =IF(ISNUMBER(K22),K22*G22/5,"[Auto]") -> [Auto] | N22: [Enter AWS assessment...] | O22: [Enter Azure assessment...] | P22: [Enter GCP assessment...]
B23: PERF-2 | C23: Compute Performance | D23: CPU, GPU, and specialized hardware availability and performance. | G23: 20 | H23: =IF(ISNUMBER(F23),F23*G23/5,"[Auto]") -> [Auto] | J23: =IF(ISNUMBER(I23),I23*G23/5,"[Auto]") -> [Auto] | L23: =IF(ISNUMBER(K23),K23*G23/5,"[Auto]") -> [Auto] | N23: [Enter AWS assessment...] | O23: [Enter Azure assessment...] | P23: [Enter GCP assessment...]
B24: PERF-3 | C24: Storage Throughput | D24: Required IOPS and throughput for databases or analytics platforms. | G24: 20 | H24: =IF(ISNUMBER(F24),F24*G24/5,"[Auto]") -> [Auto] | J24: =IF(ISNUMBER(I24),I24*G24/5,"[Auto]") -> [Auto] | L24: =IF(ISNUMBER(K24),K24*G24/5,"[Auto]") -> [Auto] | N24: [Enter AWS assessment...] | O24: [Enter Azure assessment...] | P24: [Enter GCP assessment...]
B25: PERF-4 | C25: Network Backbone Quality | D25: Deterministic private backbone routing vs public internet transit. | G25: 20 | H25: =IF(ISNUMBER(F25),F25*G25/5,"[Auto]") -> [Auto] | J25: =IF(ISNUMBER(I25),I25*G25/5,"[Auto]") -> [Auto] | L25: =IF(ISNUMBER(K25),K25*G25/5,"[Auto]") -> [Auto] | N25: [Enter AWS assessment...] | O25: [Enter Azure assessment...] | P25: [Enter GCP assessment...]
A26: Business Analytics | B26: BA-1 | C26: Data Warehouse Capabilities | D26: Native data warehouse performance, scalability, and integration. | G26: 20 | H26: =IF(ISNUMBER(F26),F26*G26/5,"[Auto]") -> [Auto] | J26: =IF(ISNUMBER(I26),I26*G26/5,"[Auto]") -> [Auto] | L26: =IF(ISNUMBER(K26),K26*G26/5,"[Auto]") -> [Auto] | N26: [Enter AWS assessment...] | O26: [Enter Azure assessment...] | P26: [Enter GCP assessment...]
B27: BA-2 | C27: ML/AI Services | D27: Machine learning platform maturity and pre-built AI services. | G27: 20 | H27: =IF(ISNUMBER(F27),F27*G27/5,"[Auto]") -> [Auto] | J27: =IF(ISNUMBER(I27),I27*G27/5,"[Auto]") -> [Auto] | L27: =IF(ISNUMBER(K27),K27*G27/5,"[Auto]") -> [Auto] | N27: [Enter AWS assessment...] | O27: [Enter Azure assessment...] | P27: [Enter GCP assessment...]
B28: BA-3 | C28: BI Tool Integration | D28: Integration with Power BI, Tableau, Looker, and other BI tools. | G28: 15 | H28: =IF(ISNUMBER(F28),F28*G28/5,"[Auto]") -> [Auto] | J28: =IF(ISNUMBER(I28),I28*G28/5,"[Auto]") -> [Auto] | L28: =IF(ISNUMBER(K28),K28*G28/5,"[Auto]") -> [Auto] | N28: [Enter AWS assessment...] | O28: [Enter Azure assessment...] | P28: [Enter GCP assessment...]
B29: BA-4 | C29: Real-time Analytics | D29: Streaming analytics and real-time data processing capabilities. | G29: 15 | H29: =IF(ISNUMBER(F29),F29*G29/5,"[Auto]") -> [Auto] | J29: =IF(ISNUMBER(I29),I29*G29/5,"[Auto]") -> [Auto] | L29: =IF(ISNUMBER(K29),K29*G29/5,"[Auto]") -> [Auto] | N29: [Enter AWS assessment...] | O29: [Enter Azure assessment...] | P29: [Enter GCP assessment...]
A30: Transparency | B30: TRN-1 | C30: Service Health Dashboard | D30: Real-time service health visibility and historical incident data. | G30: 15 | H30: =IF(ISNUMBER(F30),F30*G30/5,"[Auto]") -> [Auto] | J30: =IF(ISNUMBER(I30),I30*G30/5,"[Auto]") -> [Auto] | L30: =IF(ISNUMBER(K30),K30*G30/5,"[Auto]") -> [Auto] | N30: [Enter AWS assessment...] | O30: [Enter Azure assessment...] | P30: [Enter GCP assessment...]
B31: TRN-2 | C31: Incident Reporting Detail | D31: Required depth of RCA and incident transparency. | G31: 20 | H31: =IF(ISNUMBER(F31),F31*G31/5,"[Auto]") -> [Auto] | J31: =IF(ISNUMBER(I31),I31*G31/5,"[Auto]") -> [Auto] | L31: =IF(ISNUMBER(K31),K31*G31/5,"[Auto]") -> [Auto] | N31: [Enter AWS assessment...] | O31: [Enter Azure assessment...] | P31: [Enter GCP assessment...]
B32: TRN-3 | C32: Billing Granularity | D32: Near-real-time cost visibility at workload or tag level. | G32: 20 | H32: =IF(ISNUMBER(F32),F32*G32/5,"[Auto]") -> [Auto] | J32: =IF(ISNUMBER(I32),I32*G32/5,"[Auto]") -> [Auto] | L32: =IF(ISNUMBER(K32),K32*G32/5,"[Auto]") -> [Auto] | N32: [Enter AWS assessment...] | O32: [Enter Azure assessment...] | P32: [Enter GCP assessment...]
A33: Cost | B33: CST-1 | C33: Pricing Model Flexibility | D33: On-demand, reserved, spot/preemptible pricing options. | G33: 20 | H33: =IF(ISNUMBER(F33),F33*G33/5,"[Auto]") -> [Auto] | J33: =IF(ISNUMBER(I33),I33*G33/5,"[Auto]") -> [Auto] | L33: =IF(ISNUMBER(K33),K33*G33/5,"[Auto]") -> [Auto] | N33: [Enter AWS assessment...] | O33: [Enter Azure assessment...] | P33: [Enter GCP assessment...]
B34: CST-2 | C34: Committed Use Discounts | D34: Savings plans, reserved instances, and commitment discounts. | G34: 20 | H34: =IF(ISNUMBER(F34),F34*G34/5,"[Auto]") -> [Auto] | J34: =IF(ISNUMBER(I34),I34*G34/5,"[Auto]") -> [Auto] | L34: =IF(ISNUMBER(K34),K34*G34/5,"[Auto]") -> [Auto] | N34: [Enter AWS assessment...] | O34: [Enter Azure assessment...] | P34: [Enter GCP assessment...]
B35: CST-3 | C35: Egress Costs | D35: Data transfer and egress pricing competitiveness. | G35: 20 | H35: =IF(ISNUMBER(F35),F35*G35/5,"[Auto]") -> [Auto] | J35: =IF(ISNUMBER(I35),I35*G35/5,"[Auto]") -> [Auto] | L35: =IF(ISNUMBER(K35),K35*G35/5,"[Auto]") -> [Auto] | N35: [Enter AWS assessment...] | O35: [Enter Azure assessment...] | P35: [Enter GCP assessment...]
B36: CST-4 | C36: Cost Management Tools | D36: Native cost optimization and FinOps tooling. | G36: 15 | H36: =IF(ISNUMBER(F36),F36*G36/5,"[Auto]") -> [Auto] | J36: =IF(ISNUMBER(I36),I36*G36/5,"[Auto]") -> [Auto] | L36: =IF(ISNUMBER(K36),K36*G36/5,"[Auto]") -> [Auto] | N36: [Enter AWS assessment...] | O36: [Enter Azure assessment...] | P36: [Enter GCP assessment...]
B37: CST-5 | C37: License Portability | D37: BYOL options and existing license utilization. | G37: 15 | H37: =IF(ISNUMBER(F37),F37*G37/5,"[Auto]") -> [Auto] | J37: =IF(ISNUMBER(I37),I37*G37/5,"[Auto]") -> [Auto] | L37: =IF(ISNUMBER(K37),K37*G37/5,"[Auto]") -> [Auto] | N37: [Enter AWS assessment...] | O37: [Enter Azure assessment...] | P37: [Enter GCP assessment...]
B38: CST-6 | C38: TCO Comparison | D38: Total cost of ownership analysis and migration cost considerations. | G38: 20 | H38: =IF(ISNUMBER(F38),F38*G38/5,"[Auto]") -> [Auto] | J38: =IF(ISNUMBER(I38),I38*G38/5,"[Auto]") -> [Auto] | L38: =IF(ISNUMBER(K38),K38*G38/5,"[Auto]") -> [Auto] | N38: [Enter AWS assessment...] | O38: [Enter Azure assessment...] | P38: [Enter GCP assessment...]
A39: Sovereignty | B39: SOV-1 | C39: Data Residency Controls | D39: Ability to guarantee data stays within specific geographic boundaries. | G39: 25 | H39: =IF(ISNUMBER(F39),F39*G39/5,"[Auto]") -> [Auto] | J39: =IF(ISNUMBER(I39),I39*G39/5,"[Auto]") -> [Auto] | L39: =IF(ISNUMBER(K39),K39*G39/5,"[Auto]") -> [Auto] | N39: [Enter AWS assessment...] | O39: [Enter Azure assessment...] | P39: [Enter GCP assessment...]
B40: SOV-2 | C40: Operational Sovereignty | D40: Control over who can access and operate on your data. | G40: 20 | H40: =IF(ISNUMBER(F40),F40*G40/5,"[Auto]") -> [Auto] | J40: =IF(ISNUMBER(I40),I40*G40/5,"[Auto]") -> [Auto] | L40: =IF(ISNUMBER(K40),K40*G40/5,"[Auto]") -> [Auto] | N40: [Enter AWS assessment...] | O40: [Enter Azure assessment...] | P40: [Enter GCP assessment...]
...

Sheet Lookup
A1: 📚 LOOKUP REFERENCE TABLE | Priority to Multiplier Mapping (Do Not Modify)
A2: Priority | B2: Multiplier
A3: Very Low Importance | B3: 1
A4: Low Importance | B4: 2
A5: Moderate Importance | B5: 3
A6: High Importance | B6: 4
A7: Very High Importance | B7: 5
