Workbook

Sheet Instructions
A1: HYPERSCALER DECISION MATRIX
A2: CRA Framework -- Phase 3: Hyperscaler Evaluation
A3: PURPOSE
B4: Produce a weighted, evidence-backed score for each hyperscaler and generate a
B5: documented primary recommendation. This is the single most customer-visible
B6: deliverable in Phase 3. Scores that look arbitrary or pre-determined will undermine
B7: the entire engagement. Every score MUST cite a specific evidence data point.
A9: WHO FILLS THIS IN
B10: Lead Architect (scoring framework) + Platform Architects (per-cloud scoring)
B11: Criteria & Weights tab: agreed with customer before scoring begins.
A13: WHEN
B14: Phase 3, Weeks 1-3. Must be complete before Phase 3 playback meeting.
B15: GATE: Do not present a recommendation before slides 8-12 of the playback deck.
A17: TAB GUIDE
A18: Instructions | B18: This sheet
A19: Criteria & Weights | B19: Define evaluation criteria and weighting -- agree with customer first
A20: Azure Scoring | B20: Score Azure against each criterion with specific evidence
A21: AWS Scoring | B21: Score AWS against each criterion with specific evidence
A22: GCP Scoring | B22: Score GCP against each criterion with specific evidence
A23: Weighted Summary | B23: Auto-calculated weighted totals + recommendation output
A24: 7Rs Estate View | B24: One row per application: Rehost/Replatform/Rearchitect/Repurchase/Retire/Retain/Relocate
A25: Multi-Cloud Exceptions | B25: Apps that cannot go to the primary cloud -- documented reason
A26: Worked Example | B26: Anonymised reference scoring -- do NOT present to customer
A28: EVIDENCE STANDARD
B29: ACCEPTABLE: 'Azure 3yr RI + AHB: 39% saving vs on-prem -- see TCO Summary tab'
B30: NOT ACCEPTABLE: 'Azure is cheaper'
B31: ACCEPTABLE: '1,200 Windows + 347 SQL Server AHB-eligible -- saving estimated Xm/yr'
B32: NOT ACCEPTABLE: 'Good licensing options'
A34: PROCESS
B35: 1. Present Criteria & Weights to customer and get written agreement (email OK)
B36: 2. Complete Azure Scoring, AWS Scoring, GCP Scoring tabs with evidence
B37: 3. Weighted Summary calculates automatically
B38: 4. Complete 7Rs Estate View for all in-scope applications
B39: 5. Document any multi-cloud exceptions in Multi-Cloud Exceptions tab
B40: 6. Present Weighted Summary in Phase 3 playback (slide 12, BEFORE recommendation)
A42: QUESTIONS? | B42: Refer to docs/guides/03-evaluation-phase-guide.md

Sheet Decision Matrix
A1: Hyperscaler Comparison & Decision Matrix
A2: Version 1.0 | Phase: Evaluation | Task 4.4 | Requirements 4.4, 4.5, 4.7, 4.8
A4: Section 1 — Technical Comparison
A5: Criterion | B5: Weight | C5: AWS Score | D5: Azure Score | E5: GCP Score | F5: Notes
A6: Compute service fit | B6: 0.15
A7: Database service fit | B7: 0.15
A8: Storage service fit | B8: 0.1
A9: Networking capabilities | B9: 0.1
A10: Migration tooling | B10: 0.1
A11: Container/K8s support | B11: 0.1
A12: AI/ML services | B12: 0.1
A13: Security services | B13: 0.1
A14: Regional availability | B14: 0.1
A15: Technical Score | B15: =SUM(B6:B14) | C15: =IFERROR(SUMPRODUCT(B6:B14,C6:C14),0) | D15: =IFERROR(SUMPRODUCT(B6:B14,D6:D14),0) | E15: =IFERROR(SUMPRODUCT(B6:B14,E6:E14),0)
A17: Section 2 — Financial Comparison
A18: Criterion | B18: Weight | C18: AWS (£) | D18: Azure (£) | E18: GCP (£) | F18: Notes
A19: Monthly run-rate (PAYG) | B19: 0.15
A20: Monthly run-rate (committed) | B20: 0.2
A21: Migration cost | B21: 0.15
A22: 3-Year TCO | B22: 0.3
A23: Licensing optimization (savings) | B23: 0.1
A24: Support cost | B24: 0.1
A25: Financial Score (0-100, lower cost = higher score) | B25: =SUM(B19:B24) | C25: =IFERROR(MIN(SUMPRODUCT(B19:B24,C19:C24),SUMPRODUCT(B19:B24,D19:D24),SUMPRODUCT(B19:B24,E19:E24))/SUMPRODUCT(B19:B24,C19:C24)*100,0) | D25: =IFERROR(MIN(SUMPRODUCT(B19:B24,C19:C24),SUMPRODUCT(B19:B24,D19:D24),SUMPRODUCT(B19:B24,E19:E24))/SUMPRODUCT(B19:B24,D19:D24)*100,0) | E25: =IFERROR(MIN(SUMPRODUCT(B19:B24,C19:C24),SUMPRODUCT(B19:B24,D19:D24),SUMPRODUCT(B19:B24,E19:E24))/SUMPRODUCT(B19:B24,E19:E24)*100,0) | F25: Auto-calc: 100 if lowest, scaled otherwise
A27: Section 3 — Organizational Comparison
A28: Criterion | B28: Weight | C28: AWS Score | D28: Azure Score | E28: GCP Score | F28: Notes
A29: Existing cloud investment | B29: 0.2
A30: Team expertise/skills | B30: 0.2
A31: Vendor relationship | B31: 0.15
A32: Training availability | B32: 0.1
A33: Partner ecosystem | B33: 0.1
A34: Enterprise agreement | B34: 0.15
A35: Strategic alignment | B35: 0.1
A36: Organizational Score | B36: =SUM(B29:B35) | C36: =IFERROR(SUMPRODUCT(B29:B35,C29:C35),0) | D36: =IFERROR(SUMPRODUCT(B29:B35,D29:D35),0) | E36: =IFERROR(SUMPRODUCT(B29:B35,E29:E35),0)
A38: Section 4 — Compliance & Risk Comparison
A39: Criterion | B39: Required | C39: AWS | D39: Azure | E39: GCP | F39: Notes
A40: SOC 2 Type II
A41: ISO 27001
A42: PCI DSS
A43: HIPAA
A44: GDPR
...

Sheet Criteria & Weights
A1: CRITERIA & WEIGHTS -- Agree with customer BEFORE scoring begins
A2: Edit the Weight % column to reflect customer-agreed weightings. Total must equal 100%.
A3: # | B3: Criterion | C3: Description | D3: Weight % | E3: Notes
A4: 1 | B4: Total Cost of Ownership (3yr) | C4: L4L and optimised scenarios across all tiers. Include Year 1 dual-running and partner credits. | D4: 30% | E4: Highest weight -- customers care most about cost
A5: 2 | B5: Licensing Advantage | C5: AHB / BYOL / SA portability; SQL Server, Windows Server, Oracle BYOL options. | D5: 20% | E5: High impact for Microsoft-heavy estates (Windows/SQL)
A6: 3 | B6: Technical Fit | C6: Workload type compatibility; managed services availability; GPU / HPC / storage options. | D6: 15% | E6: Consider .NET, Oracle, Linux, container workloads
A7: 4 | B7: Regulatory & Compliance | C7: Certifications (ISO 27001, SOC 2, FCA, GDPR); data residency; UK region footprint. | D7: 15% | E7: Critical for regulated sectors (media, finance, health)
A8: 5 | B8: Partner Commercial (AMM/MAP/PSO) | C8: Funded programme eligibility; estimated credit value; deal registration status. | D8: 10% | E8: Rackspace differentiator -- must be quantified
A9: 6 | B9: Strategic Alignment | C9: Existing enterprise agreements; roadmap alignment; executive relationships; support contracts. | D9: 10% | E9: EA and Unified Support carry weight for enterprise customers
B10: TOTAL | D10: 100% | E10: Must equal 100% before scoring begins

Sheet Azure Scoring
A1: AZURE SCORING -- Evidence-backed scoring
A2: Score = Lead Architect assessment (1-10). Evidence MUST be specific -- cite tab, date, or source.
A3: Criterion | B3: Weight % | C3: Score (1-10) | D3: Evidence (specific data point) | E3: Source | F3: Weighted Score
A4: Total Cost of Ownership (3yr) | B4: 30% | C4: [0-10] | D4: [Enter specific evidence -- e.g. 'Azure 3yr RI: 39% saving vs on-prem -- TCO tab'] | E4: [TCO tab / interview / public doc] | F4: =VALUE(LEFT(B4,LEN(B4)-1))/100*C4
A5: Licensing Advantage | B5: 20% | C5: [0-10] | D5: [Enter specific evidence -- e.g. 'Azure 3yr RI: 39% saving vs on-prem -- TCO tab'] | E5: [TCO tab / interview / public doc] | F5: =VALUE(LEFT(B5,LEN(B5)-1))/100*C5
A6: Technical Fit | B6: 15% | C6: [0-10] | D6: [Enter specific evidence -- e.g. 'Azure 3yr RI: 39% saving vs on-prem -- TCO tab'] | E6: [TCO tab / interview / public doc] | F6: =VALUE(LEFT(B6,LEN(B6)-1))/100*C6
A7: Regulatory & Compliance | B7: 15% | C7: [0-10] | D7: [Enter specific evidence -- e.g. 'Azure 3yr RI: 39% saving vs on-prem -- TCO tab'] | E7: [TCO tab / interview / public doc] | F7: =VALUE(LEFT(B7,LEN(B7)-1))/100*C7
A8: Partner Commercial (AMM/MAP/PSO) | B8: 10% | C8: [0-10] | D8: [Enter specific evidence -- e.g. 'Azure 3yr RI: 39% saving vs on-prem -- TCO tab'] | E8: [TCO tab / interview / public doc] | F8: =VALUE(LEFT(B8,LEN(B8)-1))/100*C8
A9: Strategic Alignment | B9: 10% | C9: [0-10] | D9: [Enter specific evidence -- e.g. 'Azure 3yr RI: 39% saving vs on-prem -- TCO tab'] | E9: [TCO tab / interview / public doc] | F9: =VALUE(LEFT(B9,LEN(B9)-1))/100*C9
A10: WEIGHTED TOTAL | F10: =SUM(F4:F9)
A12: EVIDENCE QUALITY REMINDER
A13: ACCEPTABLE evidence: | B13: 'Azure 3yr RI + AHB: 39% saving -- see TCO tab' | '1,200 Windows AHB-eligible -- saving XM/yr'
A14: NOT ACCEPTABLE: | B14: 'Azure is cheaper' | 'Good licensing options' | 'Strong compliance'

Sheet AWS Scoring
A1: AWS SCORING -- Evidence-backed scoring
A2: Score = Lead Architect assessment (1-10). Evidence MUST be specific -- cite tab, date, or source.
A3: Criterion | B3: Weight % | C3: Score (1-10) | D3: Evidence (specific data point) | E3: Source | F3: Weighted Score
A4: Total Cost of Ownership (3yr) | B4: 30% | C4: [0-10] | D4: [Enter specific evidence -- e.g. 'Azure 3yr RI: 39% saving vs on-prem -- TCO tab'] | E4: [TCO tab / interview / public doc] | F4: =VALUE(LEFT(B4,LEN(B4)-1))/100*C4
A5: Licensing Advantage | B5: 20% | C5: [0-10] | D5: [Enter specific evidence -- e.g. 'Azure 3yr RI: 39% saving vs on-prem -- TCO tab'] | E5: [TCO tab / interview / public doc] | F5: =VALUE(LEFT(B5,LEN(B5)-1))/100*C5
A6: Technical Fit | B6: 15% | C6: [0-10] | D6: [Enter specific evidence -- e.g. 'Azure 3yr RI: 39% saving vs on-prem -- TCO tab'] | E6: [TCO tab / interview / public doc] | F6: =VALUE(LEFT(B6,LEN(B6)-1))/100*C6
A7: Regulatory & Compliance | B7: 15% | C7: [0-10] | D7: [Enter specific evidence -- e.g. 'Azure 3yr RI: 39% saving vs on-prem -- TCO tab'] | E7: [TCO tab / interview / public doc] | F7: =VALUE(LEFT(B7,LEN(B7)-1))/100*C7
A8: Partner Commercial (AMM/MAP/PSO) | B8: 10% | C8: [0-10] | D8: [Enter specific evidence -- e.g. 'Azure 3yr RI: 39% saving vs on-prem -- TCO tab'] | E8: [TCO tab / interview / public doc] | F8: =VALUE(LEFT(B8,LEN(B8)-1))/100*C8
A9: Strategic Alignment | B9: 10% | C9: [0-10] | D9: [Enter specific evidence -- e.g. 'Azure 3yr RI: 39% saving vs on-prem -- TCO tab'] | E9: [TCO tab / interview / public doc] | F9: =VALUE(LEFT(B9,LEN(B9)-1))/100*C9
A10: WEIGHTED TOTAL | F10: =SUM(F4:F9)
A12: EVIDENCE QUALITY REMINDER
A13: ACCEPTABLE evidence: | B13: 'Azure 3yr RI + AHB: 39% saving -- see TCO tab' | '1,200 Windows AHB-eligible -- saving XM/yr'
A14: NOT ACCEPTABLE: | B14: 'Azure is cheaper' | 'Good licensing options' | 'Strong compliance'

Sheet GCP Scoring
A1: GCP SCORING -- Evidence-backed scoring
A2: Score = Lead Architect assessment (1-10). Evidence MUST be specific -- cite tab, date, or source.
A3: Criterion | B3: Weight % | C3: Score (1-10) | D3: Evidence (specific data point) | E3: Source | F3: Weighted Score
A4: Total Cost of Ownership (3yr) | B4: 30% | C4: [0-10] | D4: [Enter specific evidence -- e.g. 'Azure 3yr RI: 39% saving vs on-prem -- TCO tab'] | E4: [TCO tab / interview / public doc] | F4: =VALUE(LEFT(B4,LEN(B4)-1))/100*C4
A5: Licensing Advantage | B5: 20% | C5: [0-10] | D5: [Enter specific evidence -- e.g. 'Azure 3yr RI: 39% saving vs on-prem -- TCO tab'] | E5: [TCO tab / interview / public doc] | F5: =VALUE(LEFT(B5,LEN(B5)-1))/100*C5
A6: Technical Fit | B6: 15% | C6: [0-10] | D6: [Enter specific evidence -- e.g. 'Azure 3yr RI: 39% saving vs on-prem -- TCO tab'] | E6: [TCO tab / interview / public doc] | F6: =VALUE(LEFT(B6,LEN(B6)-1))/100*C6
A7: Regulatory & Compliance | B7: 15% | C7: [0-10] | D7: [Enter specific evidence -- e.g. 'Azure 3yr RI: 39% saving vs on-prem -- TCO tab'] | E7: [TCO tab / interview / public doc] | F7: =VALUE(LEFT(B7,LEN(B7)-1))/100*C7
A8: Partner Commercial (AMM/MAP/PSO) | B8: 10% | C8: [0-10] | D8: [Enter specific evidence -- e.g. 'Azure 3yr RI: 39% saving vs on-prem -- TCO tab'] | E8: [TCO tab / interview / public doc] | F8: =VALUE(LEFT(B8,LEN(B8)-1))/100*C8
A9: Strategic Alignment | B9: 10% | C9: [0-10] | D9: [Enter specific evidence -- e.g. 'Azure 3yr RI: 39% saving vs on-prem -- TCO tab'] | E9: [TCO tab / interview / public doc] | F9: =VALUE(LEFT(B9,LEN(B9)-1))/100*C9
A10: WEIGHTED TOTAL | F10: =SUM(F4:F9)
A12: EVIDENCE QUALITY REMINDER
A13: ACCEPTABLE evidence: | B13: 'Azure 3yr RI + AHB: 39% saving -- see TCO tab' | '1,200 Windows AHB-eligible -- saving XM/yr'
A14: NOT ACCEPTABLE: | B14: 'Azure is cheaper' | 'Good licensing options' | 'Strong compliance'

Sheet Weighted Summary
A1: WEIGHTED SUMMARY -- Phase 3 Playback Output
A2: This tab is the output presented in the Phase 3 playback deck (slide 12). Scores auto-calculate from scoring tabs.
A3: Criterion | B3: Weight | C3: Azure | D3: AWS | E3: GCP
A4: Total Cost of Ownership (3yr) | B4: 30% | C4: ='Azure Scoring'!F4 | D4: ='AWS Scoring'!F4 | E4: ='GCP Scoring'!F4
A5: Licensing Advantage | B5: 20% | C5: ='Azure Scoring'!F5 | D5: ='AWS Scoring'!F5 | E5: ='GCP Scoring'!F5
A6: Technical Fit | B6: 15% | C6: ='Azure Scoring'!F6 | D6: ='AWS Scoring'!F6 | E6: ='GCP Scoring'!F6
A7: Regulatory & Compliance | B7: 15% | C7: ='Azure Scoring'!F7 | D7: ='AWS Scoring'!F7 | E7: ='GCP Scoring'!F7
A8: Partner Commercial (AMM/MAP/PSO) | B8: 10% | C8: ='Azure Scoring'!F8 | D8: ='AWS Scoring'!F8 | E8: ='GCP Scoring'!F8
A9: Strategic Alignment | B9: 10% | C9: ='Azure Scoring'!F9 | D9: ='AWS Scoring'!F9 | E9: ='GCP Scoring'!F9
A10: WEIGHTED TOTAL | C10: =SUM(C4:C9) | D10: =SUM(D4:D9) | E10: =SUM(E4:E9)
A11: RANK | C11: [Rank auto or manual: 1st / 2nd / 3rd] | D11: [Rank auto or manual: 1st / 2nd / 3rd] | E11: [Rank auto or manual: 1st / 2nd / 3rd]
A13: RECOMMENDATION OUTPUT
A14: Primary Recommendation | B14: [HYPERSCALER] is recommended as the primary cloud platform
A15: Region | B15: [PRIMARY REGION] primary / [DR REGION] DR
A16: Rationale 1 | B16: [Specific data point -- e.g. 'Highest 3yr TCO saving: 39% -- see slide 9']
A17: Rationale 2 | B17: [Specific data point -- e.g. '1,200+ Windows + 347 SQL AHB-eligible -- saving XM/yr']
A18: Rationale 3 | B18: [Specific data point -- e.g. 'UK South holds FCA, ISO 27001, SOC 2 -- data residency confirmed']
A19: Rationale 4 | B19: [Specific data point -- e.g. 'AMM eligibility confirmed: estimated 800K-1.2M funded services']
A20: Rationale 5 | B20: [Specific data point -- optional 5th bullet]
A21: Secondary Cloud | B21: [HYPERSCALER] for [specific use case or DR]
A22: Multi-Cloud Note | B22: [N] workload exceptions -- see Multi-Cloud Exceptions tab
A24: EVIDENCE-BEFORE-RECOMMENDATION CHECKLIST
A25: [ ] | B25: 1. Estate summary (what was assessed) -- presented before scoring
A26: [ ] | B26: 2. Readiness profile (Phase 2 output) -- presented before scoring
A27: [ ] | B27: 3. Cloud comparison: cost, licensing, compliance -- all 3 clouds treated equally
A28: [ ] | B28: 4. Scoring matrix (weights agreed with customer) -- presented before recommendation
A29: [ ] | B29: 5. Recommendation -- appears AFTER all of the above. If not: restructure the deck.

Sheet 7Rs Estate View
A1: 7Rs ESTATE VIEW -- Named SOW Deliverable
A2: Flag every application with a migration pattern. Complete before Phase 3 playback.
A3: SUMMARY (auto-calculated from data below)
A4: Pattern | B4: Count | C4: % of Estate | D4: Notes
A5: Rehost | B5: =COUNTIF(E:E,"Rehost") | C5: =IF(B5>0,B5/B13,"") | D5: Target: 50-70% of typical estate
A6: Replatform | B6: =COUNTIF(E:E,"Replatform") | C6: =IF(B6>0,B6/B13,"") | D6: Target: 15-25%
A7: Rearchitect | B7: =COUNTIF(E:E,"Rearchitect") | C7: =IF(B7>0,B7/B13,"") | D7: Target: 5-10% (high cost/complexity)
A8: Repurchase | B8: =COUNTIF(E:E,"Repurchase") | C8: =IF(B8>0,B8/B13,"") | D8: Replace with SaaS
A9: Retire | B9: =COUNTIF(E:E,"Retire") | C9: =IF(B9>0,B9/B13,"") | D9: Cost saving -- quantify decommission saving
A10: Retain | B10: =COUNTIF(E:E,"Retain") | C10: =IF(B10>0,B10/B13,"") | D10: Multi-cloud exceptions -- see that tab
A11: Relocate | B11: =COUNTIF(E:E,"Relocate") | C11: =IF(B11>0,B11/B13,"") | D11: DC consolidation without cloud
A12: TOTAL | B12: =COUNTA(E18:E500)-COUNTBLANK(E18:E500)
A14: 7Rs CLASSIFICATION REFERENCE
A15: Pattern | B15: Definition | C15: When to Use
A16: Rehost | B16: Lift-and-shift to IaaS VM. No code changes. | C16: No code changes needed; fastest migration path; most of the estate (50-70%)
A17: Replatform | B17: Migrate with minor changes to use managed services. | C17: e.g., SQL Server -> Azure SQL Managed Instance; saves patching overhead
A18: Rearchitect | B18: Significant redesign to use cloud-native services. | C18: e.g., monolith -> containers; high complexity / high long-term benefit
A19: Repurchase | B19: Replace with a SaaS product. | C19: e.g., on-prem CRM -> Salesforce; vendor SaaS now covers the need
A20: Retire | B20: Decommission -- do not migrate. | C20: Application confirmed redundant or replaced; stop paying for it
A21: Retain | B21: Keep on-premises -- cannot migrate. | C21: Regulatory / latency / dependency constraint prevents migration
A22: Relocate | B22: Move to different DC without cloud. | C22: Consolidate DCs without migrating to cloud
A24: APPLICATION DATA -- One row per application
A25: App ID | B25: Application Name | C25: Business Criticality | D25: Current Platform | E25: 7R Classification | F25: Justification | G25: Complexity | H25: Target Service | I25: Wave (Indicative) | J25: Notes
A26: APP-001 | B26: [App Name] | C26: Critical | D26: VMware vSphere | E26: Rehost | F26: No code changes needed; fast migration path | G26: Low | H26: Azure VM D4sv5 / AWS m6i.xlarge / GCP n2-standard-4 | I26: 2
A27: APP-002 | B27: [App Name] | C27: High | D27: VMware vSphere | E27: Replatform | F27: SQL Server -> Azure SQL Managed Instance; reduces patching overhead | G27: Medium | H27: Azure SQL Managed Instance | I27: 3 | J27: Validate compatibility
A28: APP-003 | B28: [App Name] | C28: Medium | D28: Physical | E28: Retire | F28: Confirmed redundant -- replaced by SaaS product | G28: Low | H28: Decommission | I28: 0 | J28: Save decommission cost
A29: APP-004 | B29: [App Name] | C29: High | D29: VMware vSphere | E29: Retain | F29: Latency requirement <5ms to on-prem payment system | G29: N/A | H29: On-premises (retain) | I29: N/A | J29: See Multi-Cloud Exceptions tab

Sheet Multi-Cloud Exceptions
A1: MULTI-CLOUD EXCEPTIONS -- Every enterprise engagement has workloads that cannot go to the primary cloud
A2: Document ALL exceptions explicitly before the Phase 3 playback. Prevents post-recommendation disputes.
A3: App ID | B3: Application Name | C3: Why It Cannot Go to Primary Cloud | D3: Recommended Alternative | E3: Complexity | F3: Commercial Impact | G3: Action Required
A4: APP-XXX | B4: [App Name] | C4: Oracle RAC workload -- OCI significantly cheaper for Oracle ULA customers | D4: Oracle OCI (for Oracle DB tier) | E4: Medium | F4: OCI vs Azure: model at Part 2 design phase | G4: Model OCI cost; present as optimisation option in Part 2
A5: APP-XXX | B5: [App Name] | C5: Latency-sensitive -- must be <5ms from on-prem payment gateway | D5: Retain on-premises | E5: N/A | F5: No cloud migration cost; on-prem running cost continues | G5: Include in Part 2 network design; review if DC exit changes topology
A6: APP-XXX | B6: [App Name] | C6: SaaS vendor data locked in AWS S3; extraction not commercially viable | D6: Retain in vendor SaaS; integrate via API from landing zone | E6: Low | F6: Integration cost at Part 2 | G6: Scope API integration in Part 2 landing zone workstream
A7: APP-XXX | B7: [App Name] | C7: Oracle Forms -- no cloud-native equivalent; requires specialist IaaS rehost | D7: Rehost on primary cloud OR retain (assess Oracle practice) | E7: High | F7: Oracle practice engagement required -- cost TBD | G7: Escalate to Oracle Practice Lead; include in Phase 3 risk register
A9: COMMON EXCEPTION CHECKLIST -- Review at Phase 3 start
A10: Exception Type | B10: Example | C10: Action
A11: Oracle on OCI | B11: Customer has Oracle workloads; OCI may be cheaper for Oracle ULA | C11: Model OCI cost; present as cost optimisation option in Part 2
A12: Latency-sensitive to on-prem | B12: App must stay <5ms from a specific on-prem system | C12: Retain on-prem; include in Part 2 network design
A13: Regulatory -- data residency | B13: Specific data must remain in-country; primary cloud lacks required region | C13: Check all three clouds for compliant regions
A14: SaaS vendor lock-in | B14: Vendor data in their own cloud; cannot extract | C14: Retain; integrate via API from primary cloud landing zone
A15: Oracle Forms / legacy | B15: No cloud-native equivalent; IaaS rehost minimum | C15: Rehost on primary cloud if technically possible; else Retain

Sheet Worked Example -- Reference
A1: WORKED EXAMPLE -- Reference only. Do not edit. Replace with your own scoring in the Azure/AWS/GCP Scoring tabs.
A2: Source: Reference Engagement -- Media Sector UK (anonymised). Weights and evidence are illustrative.
A3: Criterion | B3: Weight | C3: Azure Score | D3: AWS Score | E3: GCP Score | F3: Evidence (anonymised)
A4: Total Cost of Ownership (3yr) | B4: 30% | C4: 8.5 | D4: 7.2 | E4: 7.8 | F4: Azure optimised (3yr RI + AHB): ~39% saving vs on-prem | AWS: ~30% | GCP: ~34% -- see TCO tab
A5: Licensing Advantage | B5: 20% | C5: 9 | D5: 6.5 | E5: 5 | F5: 1,200+ Windows Server + 340+ SQL Server AHB-eligible; no AWS or GCP equivalent programme
A6: Technical Fit | B6: 15% | C6: 8 | D6: 7.5 | E6: 7.5 | F6: All 3 clouds support workload types; Azure strongest for .NET/Windows stack (85% of estate)
A7: Regulatory & Compliance | B7: 15% | C7: 8.5 | D7: 8 | E7: 7.5 | F7: All 3 hold UK data residency; Azure FCA alignment strongest for regulated media operations
A8: Partner Commercial (AMM/MAP/PSO) | B8: 10% | C8: 8.5 | D8: 7 | E8: 6 | F8: AMM eligibility confirmed: estimated 800K-1.2M funded services | MAP partial | GCP PSO eligible
A9: Strategic Alignment | B9: 10% | C9: 8 | D9: 6.5 | E9: 6 | F9: Existing Microsoft EA + Unified Support; no equivalent AWS/GCP enterprise agreement
A10: WEIGHTED TOTAL | C10: 8.6 | D10: 7.1 | E10: 6.9 | F10: Calculated: Score x Weight for each criterion
A11: RANK | C11: 1st (Primary) | D11: 2nd (Secondary) | E11: 3rd
A13: RECOMMENDATION (Reference)
A14: Primary Cloud | B14: Microsoft Azure (UK South primary / UK West DR)
A15: Rationale 1 | B15: Highest 3yr TCO saving: ~39% vs on-prem (Azure RI + AHB) vs 30% AWS, 34% GCP
A16: Rationale 2 | B16: AHB advantage: 1,200+ Windows + 340+ SQL licences eligible; estimated Xm/yr saving
A17: Rationale 3 | B17: Azure UK South holds FCA, ISO 27001, SOC 2 Type II -- required for regulated media
A18: Rationale 4 | B18: AMM eligibility confirmed: 800K-1.2M funded services available
A19: Rationale 5 | B19: Existing Microsoft EA + Unified Support -- commercial continuity for customer
A20: Secondary | B20: AWS London (eu-west-2) for DR and batch processing workloads
A21: Multi-Cloud | B21: 4 workload exceptions -- see Multi-Cloud Exceptions tab
