Workbook
Name altcostAdv: [1]Costs!$AH$48:$AT$57
Name altcostAdv: PriceTbls!$AJ$48:$AV$57
Name altcostAdv: Costs!$AJ$51:$AV$60
Name altcostAps: [1]Costs!$AH$4:$AT$13
Name altcostAps: PriceTbls!$AJ$4:$AV$13
Name altcostAps: Costs!$AJ$4:$AV$13
Name altcostData: [1]Costs!$AH$18:$AT$27
Name altcostData: PriceTbls!$AJ$18:$AV$27
Name altcostData: Costs!$AJ$18:$AV$27
Name altcostErp: [1]Costs!$AH$111:$AT$122
Name altcostErp: PriceTbls!$AJ$111:$AV$122
Name altcostErp: Costs!$AJ$114:$AV$125
Name altcostProd: [1]Costs!$AH$63:$AT$72
Name altcostProd: PriceTbls!$AJ$63:$AV$72
Name altcostProd: Costs!$AJ$66:$AV$75
Name altcostPvtCld: [1]Costs!$AH$77:$AT$88
Name altcostPvtCld: PriceTbls!$AJ$77:$AV$88
Name altcostPvtCld: Costs!$AJ$80:$AV$91
Name altcostSdaia: [1]Costs!$AH$94:$AT$105
Name altcostSdaia: PriceTbls!$AJ$94:$AW$105
Name altcostSdaia: Costs!$AJ$97:$AW$108
Name altcostSec: [1]Costs!$AH$33:$AT$42
Name altcostSec: PriceTbls!$AJ$33:$AV$42
Name altcostSec: Costs!$AJ$36:$AV$45
Name Contingency: [1]Calculator!$I$17
Name Contingency: Calculator!$I$17
Name Contingency_amount: [1]Calculator!$F$19
Name Contingency_amount: Calculator!$F$19
Name costAdv: [1]Costs!$C$48:$O$57
Name costAdv: PriceTbls!$C$50:$O$59
Name costAdv: Costs!$C$51:$O$60
Name costAps: [1]Costs!$C$4:$O$15
Name costAps: Costs!$C$4:$O$15
Name costData: TbCostData[[US]:[VN]]
Name costData: [1]!TbCostData[[US]:[VN]]
Name costData: TbCostData25[[US]:[VN]]
Name costData: TbCostData[[US]:[VN]]
Name costErp: [1]Costs!$C$111:$O$122
Name costErp: PriceTbls!$C$113:$O$124
Name costErp: Costs!$C$114:$O$125
Name costHealth: PriceTbls!$C$128:$P$141
Name costHealth: Costs!$C$129:$P$142
Name costProd: [1]Costs!$C$63:$O$72
Name costProd: PriceTbls!$C$65:$O$74
Name costProd: Costs!$C$66:$O$75
Name costPvtCld: [1]Costs!$C$77:$O$88
Name costPvtCld: PriceTbls!$C$79:$O$90
Name costPvtCld: Costs!$C$80:$O$91
Name costSdaia: [1]Costs!$C$94:$O$105
Name costSdaia: PriceTbls!$C$96:$P$107
Name costSdaia: Costs!$C$97:$P$108
Name costSec: TbCostSec[[US]:[VN]]
Name costSec: [1]!TbCostSec[[US]:[VN]]
Name costSec: PriceTbls!$C$35:$O$44
Name costSec: TbCostSec[[US]:[VN]]
Name countAdv: [1]!TbCountAdv[[US]:[VN]]
Name countAdv: TbCountAdv27[[US]:[VN]]
Name countAdv: TbCountAdv[[US]:[VN]]
Name countAps: TbCountAps[[US]:[VN]]
Name countAps: [1]!TbCountAps[[US]:[VN]]

Sheet Version History
B4: Version No. | C4: Release Date | D4: Updated by | E4: Changes
B5: 1 | C5: 3.15.2024 | D5: Brijesh | E5: Base version
B6: 2 | C6: 5.12.2024 | D6: Brijesh | E6: 1. Summary sheet modified: a. Approval Matrix updated b. Contingency costs updated
B7: 3 | C7: 5.25.2024 | D7: Brijesh | E7: 1. Healthcare PS added 2. Exchange rate adjusted
B8: 4 | C8: 6.17.2024 | D8: Brijesh | E8: 1. Approval Matrix Updated 2. Channel Partner sub-classified
B9: 5 | C9: 7.2.2024 | D9: Brijesh | E9: 1. Expiry date issue (EMEA) is fixed 2. Approval matrix for RIG (Anything outside US) has been updated
B10: 6 | C10: 10.14.2024 | D10: Brijesh | E10: 1. EGY Pricing Fixed 2. Approval matrix for Pvt Cloud Updated
B11: 7 | C11: 1.31.2025 | D11: Brijesh | E11: 1. Costs and utilization assumptions revised 2. Data levels further defined for Eng and Arch
B12: 8 | C12: 2.15.2025 | D12: Brijesh | E12: 1. Discounted Price/hr (after strategic discounts or overall discount) is provided in column Q

Sheet Summary
AA1: =AA2&TEXT(AB2,"mm-dd-yy")&" at " & TEXT(AB2,"hh-mm") -> Snapshot on 05-08-26 at 10-13
B2: Financial and Approval Summary | D2: ="ver " & Calculator!E1 -> ver Updated: 2/15/2025 | AA2: Snapshot on | AB2: =NOW() -> 46150.426
B3: SalesForce ID | D3: e.g. 44404522 | F3: =IF(expiry_code=1,"The rate card has expired. Please download the latest version from Solution hub","") | AB3: =NOW() -> 46150.426
B4: Financial Force Project (if any) | D4: e.g. PR-010641
B5: Region | C5: =Calculator!F4 -> UK
B6: Customer
B7: Opportunity Name
C8: Enter details (Names) Below | D8: Date approved on
B9: Cost Model Estimates by
B10: Regional Director Approved
B11: Delivery Approved by
B12: GTM Regional Leader
B13: Finance/ Pricing
B14: Offering
B15: Delivery Type
B16: Project Start Date
B17: Project End Date
B18: Units of Service
B19: Currency
B22: Revenue | C22: =Calculator!I11/(1-Calculator!I9) -> 218571
B23: Approved Negotiated Discount | C23: =-Calculator!I11/(1-Calculator!I9)*Calculator!I9 -> -118879.22
B24: Minimum Approved Revenue | C24: =C22+C23 -> 99691.785
B25: Resource Costs | C25: =IF(Calculator!F8="Yes",75%/85%,1)*Calculator!F14 -> 94942.841 | D25: =Calculator!I12 & " " & Calculator!J12 & " efforts" -> 160 Days efforts
B26: 3rd Party Costs/Other BU costs | C26: =Calculator!F16 -> 0
B27: Materials and Expenses | C27: =Calculator!F11 -> 0
B28: Channel Partner Costs | C28: =Calculator!F17 -> 0
B29: Contingency | C29: =Contingency_amount -> 4747.142
B30: Contingency % | C30: =IFERROR(Contingency_amount/C24,"") -> 0.047618187 | D30: of the Revenue!
B31: Total Costs | C31: =SUBTOTAL(9,C25:C29) -> 99689.983
B32: Project Profit | C32: =C24-C31 -> 1.8019795
B33: Project Gross Margin | C33: =IFERROR(C32/C24,"") -> 1.8075507e-05 | D33: =IF(C33<40%,"Approval needed: Please fill in the appovers in summary above once approved", "Approved margins") -> Approval needed: Please fill in the appovers in summary above once approved
B37: Approval Matrices
B68: Include pricing@rackspace.com or pricingintl@rackspace.com (for other than AMER) on cc for any deal <35% margins
B84: Approvers | F84: Approval Level
B85: Delivery Lead | F85: None - Signs off that the technical approach is able to be delivered subject to the documented assumptions. Specifically: • Milestones and mobilization of delivery resources (if sign on from customer is delayed, then revenue milestones will be adjusted – if no option to mitigate) • Technical Delivery and Project Management delivery • Level of requirements / details within SOW • Highlight of any risks or concerns • Resources required outside of PS (e.g. GTS, contractors, etc.)
B86: Regional Director | F86: 35% MIN. Project Gross Margin (Fixed Price, T&M) 10% MIN. Contingency (Fixed Price) $200K MAX. Revenue on Fixed Price, $300 T&M
B87: Regional Leader | C87: Mahesh Desai (UK, Nordics, NL and Middle East) Juergen Stauber (DACH) | F87: 30% MIN Project Gross Margin (Fixed Price, T&M) 10% MIN Contingency (Fixed Price) $200K MAX revenue on Fixed Price, $300k T&M
B88: Finance | C88: Karthik Gurumurthy/John Vernikos/Sriram Mathew Cozens (backup) | F88: 20% MIN Project Gross Margin (Fixed Price, T&M) 5% MIN Contingency (Fixed Price) $5m Max Revenue
B89: RIG Managing Director & Finance | C89: John Vernikos Dorothea Bruggler Chax Poduri (backup) | F89: 0% MIN Project Gross Margin (Fixed Price, T&M) 0% MIN Contingency (Fixed price) No limit Max Revenue

Sheet Reference
W1: Mapping for SOW | Z1: Unique list at Z2 | AC1: Role Example | BZ1: lock | CA1: Date Lock/Expiry
C2: tb_practices | E2: TbCountries | G2: tb_roles | J2: USD exchange rates | W2: Role | X2: SOW Roles | Z2: {=_xlfn.UNIQUE(tb_role_map[Role])} -> Arch | AC2: Senior Advisory Consultant | CA2: Date updated | CB2: =VALUE(TRIM(MID(Calculator!E1,9,10))) -> #VALUE!
C3: Practice Area | E3: Region Sourced from | G3: Role | H3: Job Profile | J3: currency | K3: fx | W3: Arch | X3: Security Architect | Z3: Advisory Consultant | CA3: Previous update | CB3: 45322 | CD3: mm | CE3: dd | CF3: yyyy
C4: Platform and Apps | E4: US | G4: Jr. Eng | H4: Engineer I | J4: USD | K4: 1 | W4: Arch | X4: Solutions Architect | Z4: Sr. Advisory Consultant | CA4: Today is | CB4: =TODAY() -> 46150 | CD4: =MONTH(CB4) -> 5 | CE4: =DAY(CB4) -> 8 | CF4: =YEAR(CB4) -> 2026
C5: Data | E5: UK | G5: Eng | H5: Engineer II | J5: GBP | K5: 0.83 | W5: Arch | X5: SME (Subject Matter Expert) | Z5: Developer | CA5: Expiry date | CB5: =150+CB2 -> #VALUE! | CD5: =MONTH(CB5) -> #VALUE! | CE5: =DAY(CB5) -> #VALUE! | CF5: =YEAR(CB5) -> #VALUE!
C6: Security | E6: DE | G6: Sr. Eng | H6: Engineer III/IV/V | J6: EUR | K6: 0.95 | W6: Advisory Consultant | X6: Consultant | Z6: EM/PJM | CA6: Is expired | CB6: =CB10 -> 0 | CD6: =IF(DATE(CF4,CD4,CE4)>DATE(CF5,CD5,CE5),1,0) -> #VALUE!
C7: Advisory | E7: PL | G7: Arch | H7: Architect, Sr. and Staff Consulting Architect | J7: AUD | K7: 1.54 | W7: Advisory Consultant | X7: Advisory Consultant | Z7: Eng | CA7: There is error | CB7: =IFERROR(IF(DATE(CF4,CD4,CE4)>DATE(CF5,CD5,CE5),0,1),"Error in date") -> Error in date
C8: Productivity | E8: NL | G8: Sr. Arch | H8: Sr. Architect | J8: CAD | K8: 1.35 | W8: Advisory Consultant | X8: Security Consultant | Z8: Jr. Eng
C9: PS Private Cloud | E9: MX | G9: TCT/Lead Arch | H9: Practice Lead & Principal Consultant | W9: Sr. Advisory Consultant | X9: Sr. Advisory Consultant | Z9: Manager
C10: SDAIA | E10: IN | G10: Manager | H10: Manager | W10: Sr. Advisory Consultant | X10: Sr. Advisory Consultant | Z10: Prog Mgr | CA10: Input from Macro | CB10: =Calculator!F1 -> 0
C11: ERP | E11: EG | G11: Sr. Mgr | H11: Sr. Manager | W11: Sr. Advisory Consultant | X11: Sr. Advisory Consultant | Z11: Project Coordinator | CA11: (you need to change the date on macro button 9… to set the expiry)
C12: Healthcare PS | E12: CAN | G12: EM/PJM | H12: Engagement Manager | W12: Developer | X12: Developer | Z12: Project Mgr
E13: AU | G13: Sr. EM/Sr. PJM/PGM | H13: Sr. Engagement Manager | W13: EM/PJM | X13: Engagement Manager (EM) | Z13: Sr. Arch
E14: AE | W14: EM/PJM | X14: Project Manager | Z14: Sr. Consultant
C15: Lock sheets | E15: SG | W15: Eng | X15: Security Engineer | Z15: Sr. Developer
C16: Reference | E16: VN | W16: Eng | X16: Cloud Engineer (CE) | Z16: Sr. EM/Sr. PJM/PGM
C17: Data | E17: SA | W17: Eng | X17: Software Development Engineer (SDE) | Z17: Sr. Eng
C18: price at custom | W18: Eng | X18: Firmware Engineer (FWE) | Z18: Sr. Mgr
C19: All but security | W19: Eng | X19: Business Analyst (BA) | Z19: Sr. Proj Mgr
C20: Price Tables | G20: Roles | H20: mapped to | W20: Eng | X20: Data Engineer (DE) | Z20: TCT/Lead Arch
C21: Summary | G21: Subject Matter Expert (SME) & Security Consultant | H21: Arch | W21: Eng | X21: DBA
G22: Project Manager | H22: EM/PJM | W22: Jr. Eng | X22: Junior Engineer
G23: Engineer II, Software Development Engineer (SDE) & Business Analyst (BA) | H23: Eng | W23: Manager | X23: Managing Consultant
B24: Region | C24: Level | D24: Approvers | G24: Engineer III, IV | H24: Sr. Eng | W24: Manager | X24: Program Manager
B25: US | C25: Regional Director Approved | G25: Engineer I | H25: Jr. Eng | W25: Manager | X25: Project Manager
B26: US | C26: Delivery Approved by | G26: Advisory Consultant | H26: Arch | W26: Prog Mgr | X26: Program Manager
B27: US | C27: GTM Regional Leader | G27: Sr. Advisory Consultant | H27: Sr. Arch | W27: Project Coordinator | X27: Project Coordinator
B28: EMEA | C28: Regional Director Approved | G28: Program Manager | H28: Sr. EM/Sr. PJM/PGM | W28: Project Mgr | X28: Project Manager
B29: EMEA | C29: Delivery Approved by | G29: Security Engineer/HW Eng/Firmware Eng/Managing Consultant | H29: Sr. Eng | W29: Sr. Arch | X29: Senior Advisory Consultant
B30: EMEA | C30: GTM Regional Leader | G30: Practice Lead & Principal Consultant | H30: TCT/Lead Arch | W30: Sr. Arch | X30: Advisory Consultant
B31: APJ | C31: Regional Director Approved | W31: Sr. Arch | X31: Senior Solutions Architect
B32: APJ | C32: Delivery Approved by | W32: Sr. Arch | X32: Senior Data Scientist (SDS)
B33: APJ | C33: GTM Regional Leader | W33: Sr. Arch | X33: Senior Solutions Architect (SSA)
W34: Sr. Consultant | X34: Senior Consultant
W35: Sr. Developer | X35: Senior Developer
W36: Sr. EM/Sr. PJM/PGM | X36: Program Manager
D37: 2 | E37: 3 | F37: 4 | G37: 5 | H37: 6 | I37: 7 | J37: 8 | K37: 9 | W37: Sr. EM/Sr. PJM/PGM | X37: Senior Engagement Manager
C38: 1 | D38: Data | E38: Security | F38: Advisory | G38: Productivity | H38: PS Pvt Cloud | I38: PS SADIA | J38: erp | K38: Healthcare PS | W38: Sr. EM/Sr. PJM/PGM | X38: Senior Project Manager
C39: Platform and Apps | D39: data_roles | E39: sec_roles | F39: adv_roles | G39: prod_roles | H39: pvc_roles | I39: sadia_roles | J39: erp_roles | W39: Sr. Eng | X39: Senior Cloud Engineer (CE)
C40: pa_roles | D40: Associate Eng | E40: Jr. Eng | F40: Advisory Consultant | G40: Specialty Architect | H40: Jr. Engineer | I40: Jr. Engineer | J40: Jr. Engineer | K40: WSS Eng | W40: Sr. Eng | X40: Senior DBA
...

Sheet price at custom
C1: *AE=UAE,PL=Poland,DE=Germany, VN=Veitnam,AU=Australia,SG=Singapore, EG=Egypt,CAN=Canada | AQ1: Check
B3: Platform and Apps | E3: At Margins | F3: 0.4 | Q3: Platform and Apps | T3: At Margins | U3: 0.5
B5: Price | C5: AE | D5: US | E5: UK | F5: AU | G5: MX | H5: PL | I5: SG | J5: VN | K5: IN | L5: EG | M5: NL | N5: DE | O5: CAN | Q5: Price | R5: AE | S5: US | T5: UK | U5: AU | V5: MX | W5: PL | X5: SG | Y5: VN | Z5: IN | AA5: EG | AB5: NL | AC5: DE | AD5: CAN
B6: Eng | C6: =ROUND(Costs!C4/(1-$F$3),0) -> 0 | D6: =ROUND(Costs!D4/(1-$F$3),0) -> 115 | E6: =ROUND(Costs!E4/(1-$F$3),0) -> 108 | F6: =ROUND(Costs!F4/(1-$F$3),0) -> 110 | G6: =ROUND(Costs!G4/(1-$F$3),0) -> 0 | H6: =ROUND(Costs!H4/(1-$F$3),0) -> 0 | I6: =ROUND(Costs!I4/(1-$F$3),0) -> 27 | J6: =ROUND(Costs!J4/(1-$F$3),0) -> 0 | ... O6: =ROUND(Costs!O4/(1-$F$3),0) -> 0 | Q6: Eng | R6: =ROUND(Costs!C4/(1-$U$3),0) -> 0 | S6: =ROUND(Costs!D4/(1-$U$3),0) -> 139 | T6: =ROUND(Costs!E4/(1-$U$3),0) -> 129 | U6: =ROUND(Costs!F4/(1-$U$3),0) -> 132 | V6: =ROUND(Costs!G4/(1-$U$3),0) -> 0 | W6: =ROUND(Costs!H4/(1-$U$3),0) -> 0 | X6: =ROUND(Costs!I4/(1-$U$3),0) -> 32 | Y6: =ROUND(Costs!J4/(1-$U$3),0) -> 0 | ... AD6: =ROUND(Costs!O4/(1-$U$3),0) -> 0
B7: Sr. Eng | C7: =ROUND(Costs!C5/(1-$F$3),0) -> 193 | D7: =ROUND(Costs!D5/(1-$F$3),0) -> 167 | E7: =ROUND(Costs!E5/(1-$F$3),0) -> 156 | F7: =ROUND(Costs!F5/(1-$F$3),0) -> 118 | G7: =ROUND(Costs!G5/(1-$F$3),0) -> 144 | H7: =ROUND(Costs!H5/(1-$F$3),0) -> 53 | I7: =ROUND(Costs!I5/(1-$F$3),0) -> 35 | J7: =ROUND(Costs!J5/(1-$F$3),0) -> 43 | ... O7: =ROUND(Costs!O5/(1-$F$3),0) -> 0 | Q7: Sr. Eng | R7: =ROUND(Costs!C5/(1-$U$3),0) -> 232 | S7: =ROUND(Costs!D5/(1-$U$3),0) -> 200 | T7: =ROUND(Costs!E5/(1-$U$3),0) -> 187 | U7: =ROUND(Costs!F5/(1-$U$3),0) -> 142 | V7: =ROUND(Costs!G5/(1-$U$3),0) -> 172 | W7: =ROUND(Costs!H5/(1-$U$3),0) -> 63 | X7: =ROUND(Costs!I5/(1-$U$3),0) -> 42 | Y7: =ROUND(Costs!J5/(1-$U$3),0) -> 52 | ... AD7: =ROUND(Costs!O5/(1-$U$3),0) -> 0
B8: Arch | C8: =ROUND(Costs!C6/(1-$F$3),0) -> 271 | D8: =ROUND(Costs!D6/(1-$F$3),0) -> 199 | E8: =ROUND(Costs!E6/(1-$F$3),0) -> 178 | F8: =ROUND(Costs!F6/(1-$F$3),0) -> 153 | G8: =ROUND(Costs!G6/(1-$F$3),0) -> 193 | H8: =ROUND(Costs!H6/(1-$F$3),0) -> 85 | I8: =ROUND(Costs!I6/(1-$F$3),0) -> 60 | J8: =ROUND(Costs!J6/(1-$F$3),0) -> 58 | ... O8: =ROUND(Costs!O6/(1-$F$3),0) -> 0 | Q8: Arch | R8: =ROUND(Costs!C6/(1-$U$3),0) -> 325 | S8: =ROUND(Costs!D6/(1-$U$3),0) -> 238 | T8: =ROUND(Costs!E6/(1-$U$3),0) -> 214 | U8: =ROUND(Costs!F6/(1-$U$3),0) -> 183 | V8: =ROUND(Costs!G6/(1-$U$3),0) -> 232 | W8: =ROUND(Costs!H6/(1-$U$3),0) -> 102 | X8: =ROUND(Costs!I6/(1-$U$3),0) -> 72 | Y8: =ROUND(Costs!J6/(1-$U$3),0) -> 70 | ... AD8: =ROUND(Costs!O6/(1-$U$3),0) -> 0
B9: Sr. Arch | C9: =ROUND(Costs!C7/(1-$F$3),0) -> 297 | D9: =ROUND(Costs!D7/(1-$F$3),0) -> 236 | E9: =ROUND(Costs!E7/(1-$F$3),0) -> 224 | F9: =ROUND(Costs!F7/(1-$F$3),0) -> 178 | G9: =ROUND(Costs!G7/(1-$F$3),0) -> 177 | H9: =ROUND(Costs!H7/(1-$F$3),0) -> 96 | I9: =ROUND(Costs!I7/(1-$F$3),0) -> 70 | J9: =ROUND(Costs!J7/(1-$F$3),0) -> 62 | ... O9: =ROUND(Costs!O7/(1-$F$3),0) -> 0 | Q9: Sr. Arch | R9: =ROUND(Costs!C7/(1-$U$3),0) -> 356 | S9: =ROUND(Costs!D7/(1-$U$3),0) -> 283 | T9: =ROUND(Costs!E7/(1-$U$3),0) -> 269 | U9: =ROUND(Costs!F7/(1-$U$3),0) -> 214 | V9: =ROUND(Costs!G7/(1-$U$3),0) -> 212 | W9: =ROUND(Costs!H7/(1-$U$3),0) -> 115 | X9: =ROUND(Costs!I7/(1-$U$3),0) -> 84 | Y9: =ROUND(Costs!J7/(1-$U$3),0) -> 75 | ... AD9: =ROUND(Costs!O7/(1-$U$3),0) -> 0
B10: TCT | C10: =ROUND(Costs!C8/(1-$F$3),0) -> 310 | D10: =ROUND(Costs!D8/(1-$F$3),0) -> 259 | E10: =ROUND(Costs!E8/(1-$F$3),0) -> 0 | F10: =ROUND(Costs!F8/(1-$F$3),0) -> 0 | G10: =ROUND(Costs!G8/(1-$F$3),0) -> 231 | H10: =ROUND(Costs!H8/(1-$F$3),0) -> 105 | I10: =ROUND(Costs!I8/(1-$F$3),0) -> 72 | J10: =ROUND(Costs!J8/(1-$F$3),0) -> 0 | ... O10: =ROUND(Costs!O8/(1-$F$3),0) -> 0 | Q10: TCT | R10: =ROUND(Costs!C8/(1-$U$3),0) -> 372 | S10: =ROUND(Costs!D8/(1-$U$3),0) -> 311 | T10: =ROUND(Costs!E8/(1-$U$3),0) -> 0 | U10: =ROUND(Costs!F8/(1-$U$3),0) -> 0 | V10: =ROUND(Costs!G8/(1-$U$3),0) -> 277 | W10: =ROUND(Costs!H8/(1-$U$3),0) -> 126 | X10: =ROUND(Costs!I8/(1-$U$3),0) -> 86 | Y10: =ROUND(Costs!J8/(1-$U$3),0) -> 0 | ... AD10: =ROUND(Costs!O8/(1-$U$3),0) -> 0
B11: Manager | C11: =ROUND(Costs!C9/(1-$F$3),0) -> 0 | D11: =ROUND(Costs!D9/(1-$F$3),0) -> 266 | E11: =ROUND(Costs!E9/(1-$F$3),0) -> 0 | F11: =ROUND(Costs!F9/(1-$F$3),0) -> 0 | G11: =ROUND(Costs!G9/(1-$F$3),0) -> 386 | H11: =ROUND(Costs!H9/(1-$F$3),0) -> 0 | I11: =ROUND(Costs!I9/(1-$F$3),0) -> 0 | J11: =ROUND(Costs!J9/(1-$F$3),0) -> 0 | ... O11: =ROUND(Costs!O9/(1-$F$3),0) -> 0 | Q11: Manager | R11: =ROUND(Costs!C9/(1-$U$3),0) -> 0 | S11: =ROUND(Costs!D9/(1-$U$3),0) -> 319 | T11: =ROUND(Costs!E9/(1-$U$3),0) -> 0 | U11: =ROUND(Costs!F9/(1-$U$3),0) -> 0 | V11: =ROUND(Costs!G9/(1-$U$3),0) -> 463 | W11: =ROUND(Costs!H9/(1-$U$3),0) -> 0 | X11: =ROUND(Costs!I9/(1-$U$3),0) -> 0 | Y11: =ROUND(Costs!J9/(1-$U$3),0) -> 0 | ... AD11: =ROUND(Costs!O9/(1-$U$3),0) -> 0
B12: Sr. Mgr | C12: =ROUND(Costs!C10/(1-$F$3),0) -> 374 | D12: =ROUND(Costs!D10/(1-$F$3),0) -> 247 | E12: =ROUND(Costs!E10/(1-$F$3),0) -> 262 | F12: =ROUND(Costs!F10/(1-$F$3),0) -> 0 | G12: =ROUND(Costs!G10/(1-$F$3),0) -> 306 | H12: =ROUND(Costs!H10/(1-$F$3),0) -> 0 | I12: =ROUND(Costs!I10/(1-$F$3),0) -> 32 | J12: =ROUND(Costs!J10/(1-$F$3),0) -> 51 | ... O12: =ROUND(Costs!O10/(1-$F$3),0) -> 0 | Q12: Sr. Mgr | R12: =ROUND(Costs!C10/(1-$U$3),0) -> 449 | S12: =ROUND(Costs!D10/(1-$U$3),0) -> 297 | T12: =ROUND(Costs!E10/(1-$U$3),0) -> 315 | U12: =ROUND(Costs!F10/(1-$U$3),0) -> 0 | V12: =ROUND(Costs!G10/(1-$U$3),0) -> 368 | W12: =ROUND(Costs!H10/(1-$U$3),0) -> 0 | X12: =ROUND(Costs!I10/(1-$U$3),0) -> 38 | Y12: =ROUND(Costs!J10/(1-$U$3),0) -> 61 | ... AD12: =ROUND(Costs!O10/(1-$U$3),0) -> 0
B13: EM | C13: =ROUND(Costs!C11/(1-$F$3),0) -> 615 | D13: =ROUND(Costs!D11/(1-$F$3),0) -> 354 | E13: =ROUND(Costs!E11/(1-$F$3),0) -> 0 | F13: =ROUND(Costs!F11/(1-$F$3),0) -> 0 | G13: =ROUND(Costs!G11/(1-$F$3),0) -> 337 | H13: =ROUND(Costs!H11/(1-$F$3),0) -> 0 | I13: =ROUND(Costs!I11/(1-$F$3),0) -> 49 | J13: =ROUND(Costs!J11/(1-$F$3),0) -> 0 | ... O13: =ROUND(Costs!O11/(1-$F$3),0) -> 0 | Q13: EM | R13: =ROUND(Costs!C11/(1-$U$3),0) -> 738 | S13: =ROUND(Costs!D11/(1-$U$3),0) -> 425 | T13: =ROUND(Costs!E11/(1-$U$3),0) -> 0 | U13: =ROUND(Costs!F11/(1-$U$3),0) -> 0 | V13: =ROUND(Costs!G11/(1-$U$3),0) -> 404 | W13: =ROUND(Costs!H11/(1-$U$3),0) -> 0 | X13: =ROUND(Costs!I11/(1-$U$3),0) -> 58 | Y13: =ROUND(Costs!J11/(1-$U$3),0) -> 0 | ... AD13: =ROUND(Costs!O11/(1-$U$3),0) -> 0
B14: Jr. Eng | C14: =ROUND(Costs!C12/(1-$F$3),0) -> 0 | D14: =ROUND(Costs!D12/(1-$F$3),0) -> 120 | E14: =ROUND(Costs!E12/(1-$F$3),0) -> 181 | F14: =ROUND(Costs!F12/(1-$F$3),0) -> 0 | G14: =ROUND(Costs!G12/(1-$F$3),0) -> 0 | H14: =ROUND(Costs!H12/(1-$F$3),0) -> 96 | I14: =ROUND(Costs!I12/(1-$F$3),0) -> 34 | J14: =ROUND(Costs!J12/(1-$F$3),0) -> 26 | ... O14: =ROUND(Costs!O12/(1-$F$3),0) -> 0 | Q14: Jr. Eng | R14: =ROUND(Costs!C12/(1-$U$3),0) -> 0 | S14: =ROUND(Costs!D12/(1-$U$3),0) -> 144 | T14: =ROUND(Costs!E12/(1-$U$3),0) -> 217 | U14: =ROUND(Costs!F12/(1-$U$3),0) -> 0 | V14: =ROUND(Costs!G12/(1-$U$3),0) -> 0 | W14: =ROUND(Costs!H12/(1-$U$3),0) -> 115 | X14: =ROUND(Costs!I12/(1-$U$3),0) -> 41 | Y14: =ROUND(Costs!J12/(1-$U$3),0) -> 31 | ... AD14: =ROUND(Costs!O12/(1-$U$3),0) -> 0
B18: Data | E18: At Margins | F18: 0.4 | Q18: Data | T18: At Margins | U18: 0.5
B20: Price | C20: AE | D20: US | E20: UK | F20: AU | G20: MX | H20: PL | I20: SG | J20: VN | K20: IN | L20: EG | M20: NL | N20: DE | O20: CAN | Q20: Price | R20: AE | S20: US | T20: UK | U20: AU | V20: MX | W20: PL | X20: SG | Y20: VN | Z20: IN | AA20: EG | AB20: NL | AC20: DE | AD20: CAN
B21: Eng | C21: =ROUND(Costs!C18/(1-$F$18),0) -> 147 | D21: =ROUND(Costs!D18/(1-$F$18),0) -> 0 | E21: =ROUND(Costs!E18/(1-$F$18),0) -> 0 | F21: =ROUND(Costs!F18/(1-$F$18),0) -> 0 | G21: =ROUND(Costs!G18/(1-$F$18),0) -> 0 | H21: =ROUND(Costs!H18/(1-$F$18),0) -> 0 | I21: =ROUND(Costs!I18/(1-$F$18),0) -> 21 | J21: =ROUND(Costs!J18/(1-$F$18),0) -> 36 | ... O21: =ROUND(Costs!O18/(1-$F$18),0) -> 20 | Q21: Eng | R21: =ROUND(Costs!C18/(1-$U$18),0) -> 176 | S21: =ROUND(Costs!D18/(1-$U$18),0) -> 0 | T21: =ROUND(Costs!E18/(1-$U$18),0) -> 0 | U21: =ROUND(Costs!F18/(1-$U$18),0) -> 0 | V21: =ROUND(Costs!G18/(1-$U$18),0) -> 0 | W21: =ROUND(Costs!H18/(1-$U$18),0) -> 0 | X21: =ROUND(Costs!I18/(1-$U$18),0) -> 25 | Y21: =ROUND(Costs!J18/(1-$U$18),0) -> 43 | ... AD21: =ROUND(Costs!O18/(1-$U$18),0) -> 23
B22: Sr. Eng | C22: =ROUND(Costs!C19/(1-$F$18),0) -> 230 | D22: =ROUND(Costs!D19/(1-$F$18),0) -> 0 | E22: =ROUND(Costs!E19/(1-$F$18),0) -> 0 | F22: =ROUND(Costs!F19/(1-$F$18),0) -> 0 | G22: =ROUND(Costs!G19/(1-$F$18),0) -> 172 | H22: =ROUND(Costs!H19/(1-$F$18),0) -> 0 | I22: =ROUND(Costs!I19/(1-$F$18),0) -> 42 | J22: =ROUND(Costs!J19/(1-$F$18),0) -> 50 | ... O22: =ROUND(Costs!O19/(1-$F$18),0) -> 37 | Q22: Sr. Eng | R22: =ROUND(Costs!C19/(1-$U$18),0) -> 277 | S22: =ROUND(Costs!D19/(1-$U$18),0) -> 0 | T22: =ROUND(Costs!E19/(1-$U$18),0) -> 0 | U22: =ROUND(Costs!F19/(1-$U$18),0) -> 0 | V22: =ROUND(Costs!G19/(1-$U$18),0) -> 207 | W22: =ROUND(Costs!H19/(1-$U$18),0) -> 0 | X22: =ROUND(Costs!I19/(1-$U$18),0) -> 51 | Y22: =ROUND(Costs!J19/(1-$U$18),0) -> 60 | ... AD22: =ROUND(Costs!O19/(1-$U$18),0) -> 45
B23: Arch | C23: =ROUND(Costs!C20/(1-$F$18),0) -> 277 | D23: =ROUND(Costs!D20/(1-$F$18),0) -> 0 | E23: =ROUND(Costs!E20/(1-$F$18),0) -> 0 | F23: =ROUND(Costs!F20/(1-$F$18),0) -> 0 | G23: =ROUND(Costs!G20/(1-$F$18),0) -> 0 | H23: =ROUND(Costs!H20/(1-$F$18),0) -> 0 | I23: =ROUND(Costs!I20/(1-$F$18),0) -> 60 | J23: =ROUND(Costs!J20/(1-$F$18),0) -> 51 | ... O23: =ROUND(Costs!O20/(1-$F$18),0) -> 65 | Q23: Arch | R23: =ROUND(Costs!C20/(1-$U$18),0) -> 333 | S23: =ROUND(Costs!D20/(1-$U$18),0) -> 0 | T23: =ROUND(Costs!E20/(1-$U$18),0) -> 0 | U23: =ROUND(Costs!F20/(1-$U$18),0) -> 0 | V23: =ROUND(Costs!G20/(1-$U$18),0) -> 0 | W23: =ROUND(Costs!H20/(1-$U$18),0) -> 0 | X23: =ROUND(Costs!I20/(1-$U$18),0) -> 72 | Y23: =ROUND(Costs!J20/(1-$U$18),0) -> 61 | ... AD23: =ROUND(Costs!O20/(1-$U$18),0) -> 78
B24: Sr. Arch | C24: =ROUND(Costs!C21/(1-$F$18),0) -> 354 | D24: =ROUND(Costs!D21/(1-$F$18),0) -> 0 | E24: =ROUND(Costs!E21/(1-$F$18),0) -> 0 | F24: =ROUND(Costs!F21/(1-$F$18),0) -> 0 | G24: =ROUND(Costs!G21/(1-$F$18),0) -> 0 | H24: =ROUND(Costs!H21/(1-$F$18),0) -> 0 | I24: =ROUND(Costs!I21/(1-$F$18),0) -> 66 | J24: =ROUND(Costs!J21/(1-$F$18),0) -> 0 | ... O24: =ROUND(Costs!O21/(1-$F$18),0) -> 0 | Q24: Sr. Arch | R24: =ROUND(Costs!C21/(1-$U$18),0) -> 425 | S24: =ROUND(Costs!D21/(1-$U$18),0) -> 0 | T24: =ROUND(Costs!E21/(1-$U$18),0) -> 0 | U24: =ROUND(Costs!F21/(1-$U$18),0) -> 0 | V24: =ROUND(Costs!G21/(1-$U$18),0) -> 0 | W24: =ROUND(Costs!H21/(1-$U$18),0) -> 0 | X24: =ROUND(Costs!I21/(1-$U$18),0) -> 79 | Y24: =ROUND(Costs!J21/(1-$U$18),0) -> 0 | ... AD24: =ROUND(Costs!O21/(1-$U$18),0) -> 0
B25: TCT | C25: =ROUND(Costs!C22/(1-$F$18),0) -> 528 | D25: =ROUND(Costs!D22/(1-$F$18),0) -> 0 | E25: =ROUND(Costs!E22/(1-$F$18),0) -> 0 | F25: =ROUND(Costs!F22/(1-$F$18),0) -> 0 | G25: =ROUND(Costs!G22/(1-$F$18),0) -> 0 | H25: =ROUND(Costs!H22/(1-$F$18),0) -> 0 | I25: =ROUND(Costs!I22/(1-$F$18),0) -> 90 | J25: =ROUND(Costs!J22/(1-$F$18),0) -> 0 | ... O25: =ROUND(Costs!O22/(1-$F$18),0) -> 0 | Q25: TCT | R25: =ROUND(Costs!C22/(1-$U$18),0) -> 634 | S25: =ROUND(Costs!D22/(1-$U$18),0) -> 0 | T25: =ROUND(Costs!E22/(1-$U$18),0) -> 0 | U25: =ROUND(Costs!F22/(1-$U$18),0) -> 0 | V25: =ROUND(Costs!G22/(1-$U$18),0) -> 0 | W25: =ROUND(Costs!H22/(1-$U$18),0) -> 0 | X25: =ROUND(Costs!I22/(1-$U$18),0) -> 108 | Y25: =ROUND(Costs!J22/(1-$U$18),0) -> 0 | ... AD25: =ROUND(Costs!O22/(1-$U$18),0) -> 0
B26: Manager | C26: =ROUND(Costs!C23/(1-$F$18),0) -> 290 | D26: =ROUND(Costs!D23/(1-$F$18),0) -> 0 | E26: =ROUND(Costs!E23/(1-$F$18),0) -> 0 | F26: =ROUND(Costs!F23/(1-$F$18),0) -> 0 | G26: =ROUND(Costs!G23/(1-$F$18),0) -> 0 | H26: =ROUND(Costs!H23/(1-$F$18),0) -> 0 | I26: =ROUND(Costs!I23/(1-$F$18),0) -> 99 | J26: =ROUND(Costs!J23/(1-$F$18),0) -> 74 | ... O26: =ROUND(Costs!O23/(1-$F$18),0) -> 69 | Q26: Manager | R26: =ROUND(Costs!C23/(1-$U$18),0) -> 348 | S26: =ROUND(Costs!D23/(1-$U$18),0) -> 0 | T26: =ROUND(Costs!E23/(1-$U$18),0) -> 0 | U26: =ROUND(Costs!F23/(1-$U$18),0) -> 0 | V26: =ROUND(Costs!G23/(1-$U$18),0) -> 0 | W26: =ROUND(Costs!H23/(1-$U$18),0) -> 0 | X26: =ROUND(Costs!I23/(1-$U$18),0) -> 119 | Y26: =ROUND(Costs!J23/(1-$U$18),0) -> 88 | ... AD26: =ROUND(Costs!O23/(1-$U$18),0) -> 83
B27: Sr. Mgr | C27: =ROUND(Costs!C24/(1-$F$18),0) -> 370 | D27: =ROUND(Costs!D24/(1-$F$18),0) -> 0 | E27: =ROUND(Costs!E24/(1-$F$18),0) -> 0 | F27: =ROUND(Costs!F24/(1-$F$18),0) -> 0 | G27: =ROUND(Costs!G24/(1-$F$18),0) -> 0 | H27: =ROUND(Costs!H24/(1-$F$18),0) -> 0 | I27: =ROUND(Costs!I24/(1-$F$18),0) -> 79 | J27: =ROUND(Costs!J24/(1-$F$18),0) -> 0 | ... O27: =ROUND(Costs!O24/(1-$F$18),0) -> 0 | Q27: Sr. Mgr | R27: =ROUND(Costs!C24/(1-$U$18),0) -> 444 | S27: =ROUND(Costs!D24/(1-$U$18),0) -> 0 | T27: =ROUND(Costs!E24/(1-$U$18),0) -> 0 | U27: =ROUND(Costs!F24/(1-$U$18),0) -> 0 | V27: =ROUND(Costs!G24/(1-$U$18),0) -> 0 | W27: =ROUND(Costs!H24/(1-$U$18),0) -> 0 | X27: =ROUND(Costs!I24/(1-$U$18),0) -> 95 | Y27: =ROUND(Costs!J24/(1-$U$18),0) -> 0 | ... AD27: =ROUND(Costs!O24/(1-$U$18),0) -> 0
B28: EM | C28: =ROUND(Costs!C25/(1-$F$18),0) -> 361 | D28: =ROUND(Costs!D25/(1-$F$18),0) -> 0 | E28: =ROUND(Costs!E25/(1-$F$18),0) -> 0 | F28: =ROUND(Costs!F25/(1-$F$18),0) -> 0 | G28: =ROUND(Costs!G25/(1-$F$18),0) -> 0 | H28: =ROUND(Costs!H25/(1-$F$18),0) -> 0 | I28: =ROUND(Costs!I25/(1-$F$18),0) -> 0 | J28: =ROUND(Costs!J25/(1-$F$18),0) -> 0 | ... O28: =ROUND(Costs!O25/(1-$F$18),0) -> 0 | Q28: EM | R28: =ROUND(Costs!C25/(1-$U$18),0) -> 433 | S28: =ROUND(Costs!D25/(1-$U$18),0) -> 0 | T28: =ROUND(Costs!E25/(1-$U$18),0) -> 0 | U28: =ROUND(Costs!F25/(1-$U$18),0) -> 0 | V28: =ROUND(Costs!G25/(1-$U$18),0) -> 0 | W28: =ROUND(Costs!H25/(1-$U$18),0) -> 0 | X28: =ROUND(Costs!I25/(1-$U$18),0) -> 0 | Y28: =ROUND(Costs!J25/(1-$U$18),0) -> 0 | ... AD28: =ROUND(Costs!O25/(1-$U$18),0) -> 0
B29: Jr. Eng | C29: =ROUND(Costs!C26/(1-$F$18),0) -> 545 | D29: =ROUND(Costs!D26/(1-$F$18),0) -> 0 | E29: =ROUND(Costs!E26/(1-$F$18),0) -> 0 | F29: =ROUND(Costs!F26/(1-$F$18),0) -> 0 | G29: =ROUND(Costs!G26/(1-$F$18),0) -> 0 | H29: =ROUND(Costs!H26/(1-$F$18),0) -> 0 | I29: =ROUND(Costs!I26/(1-$F$18),0) -> 58 | J29: =ROUND(Costs!J26/(1-$F$18),0) -> 55 | ... O29: =ROUND(Costs!O26/(1-$F$18),0) -> 0 | Q29: Jr. Eng | R29: =ROUND(Costs!C26/(1-$U$18),0) -> 654 | S29: =ROUND(Costs!D26/(1-$U$18),0) -> 0 | T29: =ROUND(Costs!E26/(1-$U$18),0) -> 0 | U29: =ROUND(Costs!F26/(1-$U$18),0) -> 0 | V29: =ROUND(Costs!G26/(1-$U$18),0) -> 0 | W29: =ROUND(Costs!H26/(1-$U$18),0) -> 0 | X29: =ROUND(Costs!I26/(1-$U$18),0) -> 69 | Y29: =ROUND(Costs!J26/(1-$U$18),0) -> 66 | ... AD29: =ROUND(Costs!O26/(1-$U$18),0) -> 0
B33: Security | E33: At Margins | F33: 0.4 | Q33: Security | T33: At Margins | U33: 0.5
B35: Price | C35: AE | D35: US | E35: UK | F35: AU | G35: MX | H35: PL | I35: SG | J35: VN | K35: IN | L35: EG | M35: NL | N35: DE | O35: CAN | Q35: Price | R35: AE | S35: US | T35: UK | U35: AU | V35: MX | W35: PL | X35: SG | Y35: VN | Z35: IN | AA35: EG | AB35: NL | AC35: DE | AD35: CAN
B36: Eng | C36: =ROUND(Costs!C36/(1-$F$33),0) -> 0 | D36: =ROUND(Costs!D36/(1-$F$33),0) -> 0 | E36: =ROUND(Costs!E36/(1-$F$33),0) -> 0 | F36: =ROUND(Costs!F36/(1-$F$33),0) -> 0 | G36: =ROUND(Costs!G36/(1-$F$33),0) -> 0 | H36: =ROUND(Costs!H36/(1-$F$33),0) -> 0 | I36: =ROUND(Costs!I36/(1-$F$33),0) -> 25 | J36: =ROUND(Costs!J36/(1-$F$33),0) -> 0 | ... O36: =ROUND(Costs!O36/(1-$F$33),0) -> 0 | Q36: Eng | R36: =ROUND(Costs!C36/(1-$U$33),0) -> 0 | S36: =ROUND(Costs!D36/(1-$U$33),0) -> 0 | T36: =ROUND(Costs!E36/(1-$U$33),0) -> 0 | U36: =ROUND(Costs!F36/(1-$U$33),0) -> 0 | V36: =ROUND(Costs!G36/(1-$U$33),0) -> 0 | W36: =ROUND(Costs!H36/(1-$U$33),0) -> 0 | X36: =ROUND(Costs!I36/(1-$U$33),0) -> 30 | Y36: =ROUND(Costs!J36/(1-$U$33),0) -> 0 | ... AD36: =ROUND(Costs!O36/(1-$U$33),0) -> 0
B37: Sr. Eng | C37: =ROUND(Costs!C37/(1-$F$33),0) -> 0 | D37: =ROUND(Costs!D37/(1-$F$33),0) -> 0 | E37: =ROUND(Costs!E37/(1-$F$33),0) -> 0 | F37: =ROUND(Costs!F37/(1-$F$33),0) -> 0 | G37: =ROUND(Costs!G37/(1-$F$33),0) -> 0 | H37: =ROUND(Costs!H37/(1-$F$33),0) -> 72 | I37: =ROUND(Costs!I37/(1-$F$33),0) -> 34 | J37: =ROUND(Costs!J37/(1-$F$33),0) -> 0 | ... O37: =ROUND(Costs!O37/(1-$F$33),0) -> 0 | Q37: Sr. Eng | R37: =ROUND(Costs!C37/(1-$U$33),0) -> 0 | S37: =ROUND(Costs!D37/(1-$U$33),0) -> 0 | T37: =ROUND(Costs!E37/(1-$U$33),0) -> 0 | U37: =ROUND(Costs!F37/(1-$U$33),0) -> 0 | V37: =ROUND(Costs!G37/(1-$U$33),0) -> 0 | W37: =ROUND(Costs!H37/(1-$U$33),0) -> 86 | X37: =ROUND(Costs!I37/(1-$U$33),0) -> 40 | Y37: =ROUND(Costs!J37/(1-$U$33),0) -> 0 | ... AD37: =ROUND(Costs!O37/(1-$U$33),0) -> 0
B38: Arch | C38: =ROUND(Costs!C38/(1-$F$33),0) -> 223 | D38: =ROUND(Costs!D38/(1-$F$33),0) -> 0 | E38: =ROUND(Costs!E38/(1-$F$33),0) -> 0 | F38: =ROUND(Costs!F38/(1-$F$33),0) -> 0 | G38: =ROUND(Costs!G38/(1-$F$33),0) -> 0 | H38: =ROUND(Costs!H38/(1-$F$33),0) -> 84 | I38: =ROUND(Costs!I38/(1-$F$33),0) -> 53 | J38: =ROUND(Costs!J38/(1-$F$33),0) -> 0 | ... O38: =ROUND(Costs!O38/(1-$F$33),0) -> 0 | Q38: Arch | R38: =ROUND(Costs!C38/(1-$U$33),0) -> 268 | S38: =ROUND(Costs!D38/(1-$U$33),0) -> 0 | T38: =ROUND(Costs!E38/(1-$U$33),0) -> 0 | U38: =ROUND(Costs!F38/(1-$U$33),0) -> 0 | V38: =ROUND(Costs!G38/(1-$U$33),0) -> 0 | W38: =ROUND(Costs!H38/(1-$U$33),0) -> 101 | X38: =ROUND(Costs!I38/(1-$U$33),0) -> 64 | Y38: =ROUND(Costs!J38/(1-$U$33),0) -> 0 | ... AD38: =ROUND(Costs!O38/(1-$U$33),0) -> 0
B39: Sr. Arch | C39: =ROUND(Costs!C39/(1-$F$33),0) -> 280 | D39: =ROUND(Costs!D39/(1-$F$33),0) -> 207 | E39: =ROUND(Costs!E39/(1-$F$33),0) -> 214 | F39: =ROUND(Costs!F39/(1-$F$33),0) -> 0 | G39: =ROUND(Costs!G39/(1-$F$33),0) -> 238 | H39: =ROUND(Costs!H39/(1-$F$33),0) -> 119 | I39: =ROUND(Costs!I39/(1-$F$33),0) -> 0 | J39: =ROUND(Costs!J39/(1-$F$33),0) -> 0 | ... O39: =ROUND(Costs!O39/(1-$F$33),0) -> 0 | Q39: Sr. Arch | R39: =ROUND(Costs!C39/(1-$U$33),0) -> 336 | S39: =ROUND(Costs!D39/(1-$U$33),0) -> 248 | T39: =ROUND(Costs!E39/(1-$U$33),0) -> 257 | U39: =ROUND(Costs!F39/(1-$U$33),0) -> 0 | V39: =ROUND(Costs!G39/(1-$U$33),0) -> 286 | W39: =ROUND(Costs!H39/(1-$U$33),0) -> 143 | X39: =ROUND(Costs!I39/(1-$U$33),0) -> 0 | Y39: =ROUND(Costs!J39/(1-$U$33),0) -> 0 | ... AD39: =ROUND(Costs!O39/(1-$U$33),0) -> 0
B40: TCT | C40: =ROUND(Costs!C40/(1-$F$33),0) -> 322 | D40: =ROUND(Costs!D40/(1-$F$33),0) -> 0 | E40: =ROUND(Costs!E40/(1-$F$33),0) -> 0 | F40: =ROUND(Costs!F40/(1-$F$33),0) -> 0 | G40: =ROUND(Costs!G40/(1-$F$33),0) -> 261 | H40: =ROUND(Costs!H40/(1-$F$33),0) -> 0 | I40: =ROUND(Costs!I40/(1-$F$33),0) -> 0 | J40: =ROUND(Costs!J40/(1-$F$33),0) -> 0 | ... O40: =ROUND(Costs!O40/(1-$F$33),0) -> 0 | Q40: TCT | R40: =ROUND(Costs!C40/(1-$U$33),0) -> 387 | S40: =ROUND(Costs!D40/(1-$U$33),0) -> 0 | T40: =ROUND(Costs!E40/(1-$U$33),0) -> 0 | U40: =ROUND(Costs!F40/(1-$U$33),0) -> 0 | V40: =ROUND(Costs!G40/(1-$U$33),0) -> 313 | W40: =ROUND(Costs!H40/(1-$U$33),0) -> 0 | X40: =ROUND(Costs!I40/(1-$U$33),0) -> 0 | Y40: =ROUND(Costs!J40/(1-$U$33),0) -> 0 | ... AD40: =ROUND(Costs!O40/(1-$U$33),0) -> 0
B41: Manager | C41: =ROUND(Costs!C41/(1-$F$33),0) -> 0 | D41: =ROUND(Costs!D41/(1-$F$33),0) -> 0 | E41: =ROUND(Costs!E41/(1-$F$33),0) -> 0 | F41: =ROUND(Costs!F41/(1-$F$33),0) -> 0 | G41: =ROUND(Costs!G41/(1-$F$33),0) -> 0 | H41: =ROUND(Costs!H41/(1-$F$33),0) -> 0 | I41: =ROUND(Costs!I41/(1-$F$33),0) -> 0 | J41: =ROUND(Costs!J41/(1-$F$33),0) -> 0 | ... O41: =ROUND(Costs!O41/(1-$F$33),0) -> 0 | Q41: Manager | R41: =ROUND(Costs!C41/(1-$U$33),0) -> 0 | S41: =ROUND(Costs!D41/(1-$U$33),0) -> 0 | T41: =ROUND(Costs!E41/(1-$U$33),0) -> 0 | U41: =ROUND(Costs!F41/(1-$U$33),0) -> 0 | V41: =ROUND(Costs!G41/(1-$U$33),0) -> 0 | W41: =ROUND(Costs!H41/(1-$U$33),0) -> 0 | X41: =ROUND(Costs!I41/(1-$U$33),0) -> 0 | Y41: =ROUND(Costs!J41/(1-$U$33),0) -> 0 | ... AD41: =ROUND(Costs!O41/(1-$U$33),0) -> 0
B42: Sr. Mgr | C42: =ROUND(Costs!C42/(1-$F$33),0) -> 0 | D42: =ROUND(Costs!D42/(1-$F$33),0) -> 168 | E42: =ROUND(Costs!E42/(1-$F$33),0) -> 0 | F42: =ROUND(Costs!F42/(1-$F$33),0) -> 0 | G42: =ROUND(Costs!G42/(1-$F$33),0) -> 0 | H42: =ROUND(Costs!H42/(1-$F$33),0) -> 0 | I42: =ROUND(Costs!I42/(1-$F$33),0) -> 65 | J42: =ROUND(Costs!J42/(1-$F$33),0) -> 0 | ... O42: =ROUND(Costs!O42/(1-$F$33),0) -> 0 | Q42: Sr. Mgr | R42: =ROUND(Costs!C42/(1-$U$33),0) -> 0 | S42: =ROUND(Costs!D42/(1-$U$33),0) -> 202 | T42: =ROUND(Costs!E42/(1-$U$33),0) -> 0 | U42: =ROUND(Costs!F42/(1-$U$33),0) -> 0 | V42: =ROUND(Costs!G42/(1-$U$33),0) -> 0 | W42: =ROUND(Costs!H42/(1-$U$33),0) -> 0 | X42: =ROUND(Costs!I42/(1-$U$33),0) -> 78 | Y42: =ROUND(Costs!J42/(1-$U$33),0) -> 0 | ... AD42: =ROUND(Costs!O42/(1-$U$33),0) -> 0
B43: EM | C43: =ROUND(Costs!C43/(1-$F$33),0) -> 636 | D43: =ROUND(Costs!D43/(1-$F$33),0) -> 462 | E43: =ROUND(Costs!E43/(1-$F$33),0) -> 0 | F43: =ROUND(Costs!F43/(1-$F$33),0) -> 0 | G43: =ROUND(Costs!G43/(1-$F$33),0) -> 0 | H43: =ROUND(Costs!H43/(1-$F$33),0) -> 0 | I43: =ROUND(Costs!I43/(1-$F$33),0) -> 0 | J43: =ROUND(Costs!J43/(1-$F$33),0) -> 0 | ... O43: =ROUND(Costs!O43/(1-$F$33),0) -> 0 | Q43: EM | R43: =ROUND(Costs!C43/(1-$U$33),0) -> 763 | S43: =ROUND(Costs!D43/(1-$U$33),0) -> 555 | T43: =ROUND(Costs!E43/(1-$U$33),0) -> 0 | U43: =ROUND(Costs!F43/(1-$U$33),0) -> 0 | V43: =ROUND(Costs!G43/(1-$U$33),0) -> 0 | W43: =ROUND(Costs!H43/(1-$U$33),0) -> 0 | X43: =ROUND(Costs!I43/(1-$U$33),0) -> 0 | Y43: =ROUND(Costs!J43/(1-$U$33),0) -> 0 | ... AD43: =ROUND(Costs!O43/(1-$U$33),0) -> 0
B44: Jr. Eng | C44: =ROUND(Costs!C44/(1-$F$33),0) -> 0 | D44: =ROUND(Costs!D44/(1-$F$33),0) -> 0 | E44: =ROUND(Costs!E44/(1-$F$33),0) -> 0 | F44: =ROUND(Costs!F44/(1-$F$33),0) -> 0 | G44: =ROUND(Costs!G44/(1-$F$33),0) -> 0 | H44: =ROUND(Costs!H44/(1-$F$33),0) -> 0 | I44: =ROUND(Costs!I44/(1-$F$33),0) -> 0 | J44: =ROUND(Costs!J44/(1-$F$33),0) -> 0 | ... O44: =ROUND(Costs!O44/(1-$F$33),0) -> 0 | Q44: Jr. Eng | R44: =ROUND(Costs!C44/(1-$U$33),0) -> 0 | S44: =ROUND(Costs!D44/(1-$U$33),0) -> 0 | T44: =ROUND(Costs!E44/(1-$U$33),0) -> 0 | U44: =ROUND(Costs!F44/(1-$U$33),0) -> 0 | V44: =ROUND(Costs!G44/(1-$U$33),0) -> 0 | W44: =ROUND(Costs!H44/(1-$U$33),0) -> 0 | X44: =ROUND(Costs!I44/(1-$U$33),0) -> 0 | Y44: =ROUND(Costs!J44/(1-$U$33),0) -> 0 | ... AD44: =ROUND(Costs!O44/(1-$U$33),0) -> 0

Sheet Calculator
E1: Updated: 2/15/2025 | F1: 0 | Q1: Work Area
F2: Choose from dropdowns below | J2: =IF(expiry_code=1,"The rate card has expired. Please download the latest version from Solution hub","")
E3: Is this a T&M or a Fixed price project? | F3: Fixed Price | H3: =IF(expiry_code=1,"The rate card has expired. Please download the latest version from Solution hub","")
E4: Which market is the project being delivered | F4: UK | H4: =IF(F5="Yes"," Enter details in table below (click here)","")
E5: Is there another RXT BU/3rd party/contractor involved? | F5: No | H5: Total cost from BU/3rd Party | I5: {=SUMPRODUCT(tb_supplier[Cost (per unit/ per hr/per day rate) to Rackspace],tb_supplier[Qty (In same as cost units)],(1+tb_supplier[Add contingency]))} -> 3500
E6: Currency | F6: GBP | H6: Internal BU/3rd Party margins | I6: =IFERROR(1-I5/I7,"") -> 0.35
E7: Days or Hours | F7: Days | H7: 3rd Party/Contractor Priced at | I7: =SUM(tb_supplier[Extended Price]) -> 5384.6154
E8: Is TCV likely >1M or is it a Govt. Project | F8: No | H8: Margins under high utilization assumptions | I8: =IFERROR(1-(F14*75%/85%*(1+Contingency) +SUM(F10:F11)*(1+Contingency)+F17+IF(F5="Yes",I5,0) ) /I11,"") -> 0.11766301
E9: Channel Partner (if any) | F9: None | H9: Any strategic discounts | I9: 0.5438929
H10: Summary
E11: Non Billable travel and other expenses | H11: Total Price | I11: =IFERROR((SUM(tb_resource[Extended Price],F10)+IF(F5="Yes",I7,0))*(1-I9),"") -> 99691.785 | J11: (from configuration below)
H12: ="Total " & F7 -> Total Days | I12: =IFERROR(SUMIFS(Calculator!$H$23:$H$43,Calculator!$B$23:$B$43,">"&0),"") -> 160 | J12: =F7 -> Days
H13: Deal Margin (Gross)* | I13: =IFERROR(1-F18/I11,"") -> 1.8075507e-05 | J13: =IF(I13<40%, "Approval Needed!","") -> Approval Needed!
E14: Resource cost estimate based on hrs | F14: =SUMPRODUCT($B$23:$B$43,$H$23:$H$43) -> 94942.841 | H14: *The gross margin is based on direct costs to deliver. Other company overheads such as Sales, Marketing,
H15: Corporate, R&D, etc ranges from 20-27%. We need to be greater than that!
E16: 3rd Party Delivery Partner cost w/o contingency | F16: =IF(F5="Yes",SUMPRODUCT(tb_supplier[Cost (per unit/ per hr/per day rate) to Rackspace],tb_supplier[Qty (In same as cost units)]),0) -> 0
E17: Channel Partner Cost | F17: =I11*IF($F$9="Master",10%,IF($F$9="Sub-agent",5%,0)) -> 0 | H17: Contingency | I17: =IF(F3="T&M",I19,I18) -> 0.05
E18: Total Cost | F18: =SUM(F10:F11,F14)*(1+Contingency) + SUM(IF(F5="Yes",I5,0),F17) -> 99689.983 | H18: Contingency Factored (enter) | I18: 0.05
E19: Contingency | F19: =IF(F8="Yes",F14*75%/85%,F14)*Contingency+SUM(F10:F11,F15)*(Contingency)+SUMPRODUCT(tb_supplier[Cost (per unit/ per hr/per day rate) to Rackspace],tb_supplier[Qty (In same as cost units)],tb_supplier[Add contingency])*IF(F5="Yes",1,0) -> 4747.142 | H19: Contingency (enter if any) | I19: 0
B21: Cost | C21: Flag if role is not planned | D21: SN | E21: Practice Area | F21: Region Sourced from | G21: Role | H21: =F7 -> Days | I21: ="Price/"& IF(F7="Hours","hr","day") -> Price/day | J21: Choose between "List price" or "Strategic margin/Price" | K21: Enter custom price or custom margin value | L21: Extended Price | M21: ="Cost/"& IF(F7="Hours","hr","day") -> Cost/day | N21: Margins | O21: ="Discounted Price/"& IF(F7="Hours","hr","day") & " after strategic discount" -> Discounted Price/day after strategic discount | P21: Note (requirements, if any) | Q21: Enter Comments | R21: Count of resources available in region | S21: Suggested min. Price | T21: Possible Cost | U21: Notes on the chosen role | V21: SOW Role (please select for the resourcing)
B22: Cost | C22: Flag if role is not planned | D22: SN | E22: Practice Area | F22: Region Sourced from | G22: Role | H22: Hours | I22: Price/hr | J22: Default Price or Strategic Margin | K22: Enter Margin Value | L22: Extended Price | M22: Column1 | N22: Margins | O22: Price | P22: Note (requirements, if any) | Q22: Comments | R22: Count of resources available in region | S22: Suggested min. Price | T22: cost of unavailable | U22: Other comments | V22: Sow roles
B23: =IFERROR( INDEX( CHOOSE( MATCH(E23, practices, 0), costAps, costData, costSec, costAdv, costProd, costPvtCld, costSdaia, costErp, costHealth ), MATCH($G23,INDIRECT( "roles_"&MATCH(E23, practices, 0)), 0), MATCH($F23, countries, 0)) * INDEX(fx, MATCH($F$6, currency, 0)) * IF($F$7 = "Days", 8, 1), "" ) -> 860.93851 | C23: =IF(AND( tb_resource[[#This Row],[Practice Area]]<>0,OR(R23=0,R23="")),1,0) -> 0 | D23: 1 | E23: Platform and Apps | F23: UK | G23: Sr. EM/Sr. PJM/PGM | H23: =LOE!N40 -> 37.5 | I23: =IFERROR(ROUNDUP(IF(J23="List Price",S23*IF($F$9="Master",1.1,IF($F$9="Sub-agent",1.05,1))*IF($F$3="Fixed Price",1.1,1),IF(K23<1,B23/(1-K23),K23)),0),"") -> 1863 | J23: List Price | K23: 186 | L23: =IF(S23="","",H23*I23) -> 69862.5 | M23: =B23 -> 860.93851 | N23: =IFERROR(1-B23/I23,"") -> 0.5378752 | O23: =IFERROR(tb_resource[[#This Row],[Price/hr]]*(1-$I$9),"") -> 849.72753 | P23: =IF(Calculator!$C23=-1,"No resource in region, please work with delivery and finance to get approvals for using this rate",IF(Calculator!$C23=1,"No resource in region or planned in future. Please get special approval from Finance and HR","")) | Q23: PM | R23: =IFERROR( INDEX( CHOOSE( MATCH(E23, practices, 0), countAps, countData, countSec, countAdv, countProd, CountPvtCld, countSdaia, countErp, CountHealth ), MATCH($G23, INDIRECT( "roles_"&MATCH(E23, practices, 0)), 0), MATCH($F23, countries, 0)), "" ) -> 129.65941 | S23: =IFERROR( INDEX( CHOOSE( MATCH(E23, practices, 0), priceAps, priceData, priceSec, priceAdv, priceProd, pricePvtCld, priceSdaia, priceErp, priceHealth ), MATCH($G23,INDIRECT( "roles_"&MATCH(E23, practices, 0)), 0), MATCH($F23, countries, 0)) * INDEX(fx, MATCH($F$6, currency, 0)) * IF($F$7 = "Days", 8, 1), "" ) -> 1693.2 | T23: =ROUNDUP(IFERROR( INDEX( CHOOSE( MATCH(E23, practices, 0), altcostAps, altcostData, altcostSec, altcostAdv, altcostProd, altcostPvtCld, altcostSdaia, altcostErp ), MATCH($G23,INDIRECT( "roles_"&MATCH(E23, practices, 0)), 0), MATCH($F23, countries, 0)) * INDEX(fx, MATCH($F$6, currency, 0)) * IF($F$7 = "Days", 8, 1), 0 ), 0) -> 809 | U23: =IF(AND(OR(T23=0,T23=""),tb_resource[[#This Row],[Flag if role is not planned]]=1),"This resource is not planned for this region. Check with PS delivery",IF(tb_resource[[#This Row],[Flag if role is not planned]]=1,"This resource is not available. Use cost = " & tb_resource[[#This Row],[cost of unavailable]] & " in the Table B below and check with PS delivery team",IFERROR("role also mapped to " & INDEX(Other_roles[Roles],MATCH(Calculator!$G23,Other_roles[mapped to],0)),""))) -> role also mapped to Program Manager
B24: =IFERROR( INDEX( CHOOSE( MATCH(E24, practices, 0), costAps, costData, costSec, costAdv, costProd, costPvtCld, costSdaia, costErp, costHealth ), MATCH($G24,INDIRECT( "roles_"&MATCH(E24, practices, 0)), 0), MATCH($F24, countries, 0)) * INDEX(fx, MATCH($F$6, currency, 0)) * IF($F$7 = "Days", 8, 1), "" ) -> 703.6593 | C24: =IF(AND( tb_resource[[#This Row],[Practice Area]]<>0,OR(R24=0,R24="")),1,0) -> 0 | D24: =IF(E24="","",D23+1) -> 2 | E24: Platform and Apps | F24: NL | G24: Arch | H24: =LOE!N41 -> 40 | I24: =IFERROR(ROUNDUP(IF(J24="List Price",S24*IF($F$9="Master",1.1,IF($F$9="Sub-agent",1.05,1))*IF($F$3="Fixed Price",1.1,1),IF(K24<1,B24/(1-K24),K24)),0),"") -> 1644 | J24: List Price | K24: 0.5 | L24: =IF(S24="","",H24*I24) -> 65760 | M24: =B24 -> 703.6593 | N24: =IFERROR(1-B24/I24,"") -> 0.57198339 | O24: =IFERROR(tb_resource[[#This Row],[Price/hr]]*(1-$I$9),"") -> 749.84007 | P24: =IF(Calculator!$C24=-1,"No resource in region, please work with delivery and finance to get approvals for using this rate",IF(Calculator!$C24=1,"No resource in region or planned in future. Please get special approval from Finance and HR","")) | Q24: Lead Consulting Architect | R24: =IFERROR( INDEX( CHOOSE( MATCH(E24, practices, 0), countAps, countData, countSec, countAdv, countProd, CountPvtCld, countSdaia, countErp, CountHealth ), MATCH($G24, INDIRECT( "roles_"&MATCH(E24, practices, 0)), 0), MATCH($F24, countries, 0)), "" ) -> 133.37062 | S24: =IFERROR( INDEX( CHOOSE( MATCH(E24, practices, 0), priceAps, priceData, priceSec, priceAdv, priceProd, pricePvtCld, priceSdaia, priceErp, priceHealth ), MATCH($G24,INDIRECT( "roles_"&MATCH(E24, practices, 0)), 0), MATCH($F24, countries, 0)) * INDEX(fx, MATCH($F$6, currency, 0)) * IF($F$7 = "Days", 8, 1), "" ) -> 1494 | T24: =ROUNDUP(IFERROR( INDEX( CHOOSE( MATCH(E24, practices, 0), altcostAps, altcostData, altcostSec, altcostAdv, altcostProd, altcostPvtCld, altcostSdaia, altcostErp ), MATCH($G24,INDIRECT( "roles_"&MATCH(E24, practices, 0)), 0), MATCH($F24, countries, 0)) * INDEX(fx, MATCH($F$6, currency, 0)) * IF($F$7 = "Days", 8, 1), 0 ), 0) -> 804 | U24: =IF(AND(OR(T24=0,T24=""),tb_resource[[#This Row],[Flag if role is not planned]]=1),"This resource is not planned for this region. Check with PS delivery",IF(tb_resource[[#This Row],[Flag if role is not planned]]=1,"This resource is not available. Use cost = " & tb_resource[[#This Row],[cost of unavailable]] & " in the Table B below and check with PS delivery team",IFERROR("role also mapped to " & INDEX(Other_roles[Roles],MATCH(Calculator!$G24,Other_roles[mapped to],0)),""))) -> role also mapped to Subject Matter Expert (SME) & Security Consultant
B25: =IFERROR( INDEX( CHOOSE( MATCH(E25, practices, 0), costAps, costData, costSec, costAdv, costProd, costPvtCld, costSdaia, costErp, costHealth ), MATCH($G25,INDIRECT( "roles_"&MATCH(E25, practices, 0)), 0), MATCH($F25, countries, 0)) * INDEX(fx, MATCH($F$6, currency, 0)) * IF($F$7 = "Days", 8, 1), "" ) -> 940.26243 | C25: =IF(AND( tb_resource[[#This Row],[Practice Area]]<>0,OR(R25=0,R25="")),1,0) -> 0 | D25: =IF(E25="","",D24+1) -> 3 | E25: Platform and Apps | F25: UK | G25: Arch | H25: =LOE!N46 -> 4 | I25: =IFERROR(ROUNDUP(IF(J25="List Price",S25*IF($F$9="Master",1.1,IF($F$9="Sub-agent",1.05,1))*IF($F$3="Fixed Price",1.1,1),IF(K25<1,B25/(1-K25),K25)),0),"") -> 1826 | J25: List Price | K25: 0.5 | L25: =IF(S25="","",H25*I25) -> 7304 | M25: =B25 -> 940.26243 | N25: =IFERROR(1-B25/I25,"") -> 0.48506986 | O25: =IFERROR(tb_resource[[#This Row],[Price/hr]]*(1-$I$9),"") -> 832.85156 | P25: =IF(Calculator!$C25=-1,"No resource in region, please work with delivery and finance to get approvals for using this rate",IF(Calculator!$C25=1,"No resource in region or planned in future. Please get special approval from Finance and HR","")) | Q25: Migration Consultant | R25: =IFERROR( INDEX( CHOOSE( MATCH(E25, practices, 0), countAps, countData, countSec, countAdv, countProd, CountPvtCld, countSdaia, countErp, CountHealth ), MATCH($G25, INDIRECT( "roles_"&MATCH(E25, practices, 0)), 0), MATCH($F25, countries, 0)), "" ) -> 129.99811 | S25: =IFERROR( INDEX( CHOOSE( MATCH(E25, practices, 0), priceAps, priceData, priceSec, priceAdv, priceProd, pricePvtCld, priceSdaia, priceErp, priceHealth ), MATCH($G25,INDIRECT( "roles_"&MATCH(E25, practices, 0)), 0), MATCH($F25, countries, 0)) * INDEX(fx, MATCH($F$6, currency, 0)) * IF($F$7 = "Days", 8, 1), "" ) -> 1660 | T25: =ROUNDUP(IFERROR( INDEX( CHOOSE( MATCH(E25, practices, 0), altcostAps, altcostData, altcostSec, altcostAdv, altcostProd, altcostPvtCld, altcostSdaia, altcostErp ), MATCH($G25,INDIRECT( "roles_"&MATCH(E25, practices, 0)), 0), MATCH($F25, countries, 0)) * INDEX(fx, MATCH($F$6, currency, 0)) * IF($F$7 = "Days", 8, 1), 0 ), 0) -> 884 | U25: =IF(AND(OR(T25=0,T25=""),tb_resource[[#This Row],[Flag if role is not planned]]=1),"This resource is not planned for this region. Check with PS delivery",IF(tb_resource[[#This Row],[Flag if role is not planned]]=1,"This resource is not available. Use cost = " & tb_resource[[#This Row],[cost of unavailable]] & " in the Table B below and check with PS delivery team",IFERROR("role also mapped to " & INDEX(Other_roles[Roles],MATCH(Calculator!$G25,Other_roles[mapped to],0)),""))) -> role also mapped to Subject Matter Expert (SME) & Security Consultant
B26: =IFERROR( INDEX( CHOOSE( MATCH(E26, practices, 0), costAps, costData, costSec, costAdv, costProd, costPvtCld, costSdaia, costErp, costHealth ), MATCH($G26,INDIRECT( "roles_"&MATCH(E26, practices, 0)), 0), MATCH($F26, countries, 0)) * INDEX(fx, MATCH($F$6, currency, 0)) * IF($F$7 = "Days", 8, 1), "" ) -> 278.88 | C26: =IF(AND( tb_resource[[#This Row],[Practice Area]]<>0,OR(R26=0,R26="")),1,0) -> 0 | D26: =IF(E26="","",D25+1) -> 4 | E26: Platform and Apps | F26: IN | G26: Arch | H26: =LOE!N42 -> 22 | I26: =IFERROR(ROUNDUP(IF(J26="List Price",S26*IF($F$9="Master",1.1,IF($F$9="Sub-agent",1.05,1))*IF($F$3="Fixed Price",1.1,1),IF(K26<1,B26/(1-K26),K26)),0),"") -> 731 | J26: List Price | K26: 0.5 | L26: =IF(S26="","",H26*I26) -> 16082 | M26: =B26 -> 278.88 | N26: =IFERROR(1-B26/I26,"") -> 0.61849521 | O26: =IFERROR(tb_resource[[#This Row],[Price/hr]]*(1-$I$9),"") -> 333.41429 | P26: =IF(Calculator!$C26=-1,"No resource in region, please work with delivery and finance to get approvals for using this rate",IF(Calculator!$C26=1,"No resource in region or planned in future. Please get special approval from Finance and HR","")) | Q26: Platform Architect (AWS) | R26: =IFERROR( INDEX( CHOOSE( MATCH(E26, practices, 0), countAps, countData, countSec, countAdv, countProd, CountPvtCld, countSdaia, countErp, CountHealth ), MATCH($G26, INDIRECT( "roles_"&MATCH(E26, practices, 0)), 0), MATCH($F26, countries, 0)), "" ) -> 41.69704 | S26: =IFERROR( INDEX( CHOOSE( MATCH(E26, practices, 0), priceAps, priceData, priceSec, priceAdv, priceProd, pricePvtCld, priceSdaia, priceErp, priceHealth ), MATCH($G26,INDIRECT( "roles_"&MATCH(E26, practices, 0)), 0), MATCH($F26, countries, 0)) * INDEX(fx, MATCH($F$6, currency, 0)) * IF($F$7 = "Days", 8, 1), "" ) -> 664 | T26: =ROUNDUP(IFERROR( INDEX( CHOOSE( MATCH(E26, practices, 0), altcostAps, altcostData, altcostSec, altcostAdv, altcostProd, altcostPvtCld, altcostSdaia, altcostErp ), MATCH($G26,INDIRECT( "roles_"&MATCH(E26, practices, 0)), 0), MATCH($F26, countries, 0)) * INDEX(fx, MATCH($F$6, currency, 0)) * IF($F$7 = "Days", 8, 1), 0 ), 0) -> 244 | U26: =IF(AND(OR(T26=0,T26=""),tb_resource[[#This Row],[Flag if role is not planned]]=1),"This resource is not planned for this region. Check with PS delivery",IF(tb_resource[[#This Row],[Flag if role is not planned]]=1,"This resource is not available. Use cost = " & tb_resource[[#This Row],[cost of unavailable]] & " in the Table B below and check with PS delivery team",IFERROR("role also mapped to " & INDEX(Other_roles[Roles],MATCH(Calculator!$G26,Other_roles[mapped to],0)),""))) -> role also mapped to Subject Matter Expert (SME) & Security Consultant
B27: =IFERROR( INDEX( CHOOSE( MATCH(E27, practices, 0), costAps, costData, costSec, costAdv, costProd, costPvtCld, costSdaia, costErp, costHealth ), MATCH($G27,INDIRECT( "roles_"&MATCH(E27, practices, 0)), 0), MATCH($F27, countries, 0)) * INDEX(fx, MATCH($F$6, currency, 0)) * IF($F$7 = "Days", 8, 1), "" ) -> 278.88 | C27: =IF(AND( tb_resource[[#This Row],[Practice Area]]<>0,OR(R27=0,R27="")),1,0) -> 0 | D27: =IF(E27="","",D26+1) -> 5 | E27: Platform and Apps | F27: IN | G27: Arch | H27: =LOE!N43 -> 22 | I27: =IFERROR(ROUNDUP(IF(J27="List Price",S27*IF($F$9="Master",1.1,IF($F$9="Sub-agent",1.05,1))*IF($F$3="Fixed Price",1.1,1),IF(K27<1,B27/(1-K27),K27)),0),"") -> 731 | J27: List Price | K27: 0.5 | L27: =IF(S27="","",H27*I27) -> 16082 | M27: =B27 -> 278.88 | N27: =IFERROR(1-B27/I27,"") -> 0.61849521 | O27: =IFERROR(tb_resource[[#This Row],[Price/hr]]*(1-$I$9),"") -> 333.41429 | P27: =IF(Calculator!$C27=-1,"No resource in region, please work with delivery and finance to get approvals for using this rate",IF(Calculator!$C27=1,"No resource in region or planned in future. Please get special approval from Finance and HR","")) | Q27: Platform Architect (Azure) | R27: =IFERROR( INDEX( CHOOSE( MATCH(E27, practices, 0), countAps, countData, countSec, countAdv, countProd, CountPvtCld, countSdaia, countErp, CountHealth ), MATCH($G27, INDIRECT( "roles_"&MATCH(E27, practices, 0)), 0), MATCH($F27, countries, 0)), "" ) -> 41.69704 | S27: =IFERROR( INDEX( CHOOSE( MATCH(E27, practices, 0), priceAps, priceData, priceSec, priceAdv, priceProd, pricePvtCld, priceSdaia, priceErp, priceHealth ), MATCH($G27,INDIRECT( "roles_"&MATCH(E27, practices, 0)), 0), MATCH($F27, countries, 0)) * INDEX(fx, MATCH($F$6, currency, 0)) * IF($F$7 = "Days", 8, 1), "" ) -> 664 | T27: =ROUNDUP(IFERROR( INDEX( CHOOSE( MATCH(E27, practices, 0), altcostAps, altcostData, altcostSec, altcostAdv, altcostProd, altcostPvtCld, altcostSdaia, altcostErp ), MATCH($G27,INDIRECT( "roles_"&MATCH(E27, practices, 0)), 0), MATCH($F27, countries, 0)) * INDEX(fx, MATCH($F$6, currency, 0)) * IF($F$7 = "Days", 8, 1), 0 ), 0) -> 244 | U27: =IF(AND(OR(T27=0,T27=""),tb_resource[[#This Row],[Flag if role is not planned]]=1),"This resource is not planned for this region. Check with PS delivery",IF(tb_resource[[#This Row],[Flag if role is not planned]]=1,"This resource is not available. Use cost = " & tb_resource[[#This Row],[cost of unavailable]] & " in the Table B below and check with PS delivery team",IFERROR("role also mapped to " & INDEX(Other_roles[Roles],MATCH(Calculator!$G27,Other_roles[mapped to],0)),""))) -> role also mapped to Subject Matter Expert (SME) & Security Consultant
B28: =IFERROR( INDEX( CHOOSE( MATCH(E28, practices, 0), costAps, costData, costSec, costAdv, costProd, costPvtCld, costSdaia, costErp, costHealth ), MATCH($G28,INDIRECT( "roles_"&MATCH(E28, practices, 0)), 0), MATCH($F28, countries, 0)) * INDEX(fx, MATCH($F$6, currency, 0)) * IF($F$7 = "Days", 8, 1), "" ) -> 703.6593 | C28: =IF(AND( tb_resource[[#This Row],[Practice Area]]<>0,OR(R28=0,R28="")),1,0) -> 0 | D28: =IF(E28="","",D27+1) -> 6 | E28: Platform and Apps | F28: NL | G28: Arch | H28: =LOE!N44 -> 22 | I28: =IFERROR(ROUNDUP(IF(J28="List Price",S28*IF($F$9="Master",1.1,IF($F$9="Sub-agent",1.05,1))*IF($F$3="Fixed Price",1.1,1),IF(K28<1,B28/(1-K28),K28)),0),"") -> 1644 | J28: List Price | K28: 0.4 | L28: =IF(S28="","",H28*I28) -> 36168 | M28: =B28 -> 703.6593 | N28: =IFERROR(1-B28/I28,"") -> 0.57198339 | O28: =IFERROR(tb_resource[[#This Row],[Price/hr]]*(1-$I$9),"") -> 749.84007 | P28: =IF(Calculator!$C28=-1,"No resource in region, please work with delivery and finance to get approvals for using this rate",IF(Calculator!$C28=1,"No resource in region or planned in future. Please get special approval from Finance and HR","")) | Q28: Platform Architect (GCP) | R28: =IFERROR( INDEX( CHOOSE( MATCH(E28, practices, 0), countAps, countData, countSec, countAdv, countProd, CountPvtCld, countSdaia, countErp, CountHealth ), MATCH($G28, INDIRECT( "roles_"&MATCH(E28, practices, 0)), 0), MATCH($F28, countries, 0)), "" ) -> 133.37062 | S28: =IFERROR( INDEX( CHOOSE( MATCH(E28, practices, 0), priceAps, priceData, priceSec, priceAdv, priceProd, pricePvtCld, priceSdaia, priceErp, priceHealth ), MATCH($G28,INDIRECT( "roles_"&MATCH(E28, practices, 0)), 0), MATCH($F28, countries, 0)) * INDEX(fx, MATCH($F$6, currency, 0)) * IF($F$7 = "Days", 8, 1), "" ) -> 1494 | T28: =ROUNDUP(IFERROR( INDEX( CHOOSE( MATCH(E28, practices, 0), altcostAps, altcostData, altcostSec, altcostAdv, altcostProd, altcostPvtCld, altcostSdaia, altcostErp ), MATCH($G28,INDIRECT( "roles_"&MATCH(E28, practices, 0)), 0), MATCH($F28, countries, 0)) * INDEX(fx, MATCH($F$6, currency, 0)) * IF($F$7 = "Days", 8, 1), 0 ), 0) -> 804 | U28: =IF(AND(OR(T28=0,T28=""),tb_resource[[#This Row],[Flag if role is not planned]]=1),"This resource is not planned for this region. Check with PS delivery",IF(tb_resource[[#This Row],[Flag if role is not planned]]=1,"This resource is not available. Use cost = " & tb_resource[[#This Row],[cost of unavailable]] & " in the Table B below and check with PS delivery team",IFERROR("role also mapped to " & INDEX(Other_roles[Roles],MATCH(Calculator!$G28,Other_roles[mapped to],0)),""))) -> role also mapped to Subject Matter Expert (SME) & Security Consultant
B29: =IFERROR( INDEX( CHOOSE( MATCH(E29, practices, 0), costAps, costData, costSec, costAdv, costProd, costPvtCld, costSdaia, costErp, costHealth ), MATCH($G29,INDIRECT( "roles_"&MATCH(E29, practices, 0)), 0), MATCH($F29, countries, 0)) * INDEX(fx, MATCH($F$6, currency, 0)) * IF($F$7 = "Days", 8, 1), "" ) -> 239.92004 | C29: =IF(AND( tb_resource[[#This Row],[Practice Area]]<>0,OR(R29=0,R29="")),1,0) -> 0 | D29: =IF(E29="","",D28+1) -> 7 | E29: Platform and Apps | F29: IN | G29: Sr. Eng | H29: =LOE!N45 -> 12.5 | I29: =IFERROR(ROUNDUP(IF(J29="List Price",S29*IF($F$9="Master",1.1,IF($F$9="Sub-agent",1.05,1))*IF($F$3="Fixed Price",1.1,1),IF(K29<1,B29/(1-K29),K29)),0),"") -> 585 | J29: List Price | K29: 0.5 | L29: =IF(S29="","",H29*I29) -> 7312.5 | M29: =B29 -> 239.92004 | N29: =IFERROR(1-B29/I29,"") -> 0.58988028 | O29: =IFERROR(tb_resource[[#This Row],[Price/hr]]*(1-$I$9),"") -> 266.82265 | P29: =IF(Calculator!$C29=-1,"No resource in region, please work with delivery and finance to get approvals for using this rate",IF(Calculator!$C29=1,"No resource in region or planned in future. Please get special approval from Finance and HR","")) | Q29: Cloud Engineer | R29: =IFERROR( INDEX( CHOOSE( MATCH(E29, practices, 0), countAps, countData, countSec, countAdv, countProd, CountPvtCld, countSdaia, countErp, CountHealth ), MATCH($G29, INDIRECT( "roles_"&MATCH(E29, practices, 0)), 0), MATCH($F29, countries, 0)), "" ) -> 36.132536 | S29: =IFERROR( INDEX( CHOOSE( MATCH(E29, practices, 0), priceAps, priceData, priceSec, priceAdv, priceProd, pricePvtCld, priceSdaia, priceErp, priceHealth ), MATCH($G29,INDIRECT( "roles_"&MATCH(E29, practices, 0)), 0), MATCH($F29, countries, 0)) * INDEX(fx, MATCH($F$6, currency, 0)) * IF($F$7 = "Days", 8, 1), "" ) -> 531.2 | T29: =ROUNDUP(IFERROR( INDEX( CHOOSE( MATCH(E29, practices, 0), altcostAps, altcostData, altcostSec, altcostAdv, altcostProd, altcostPvtCld, altcostSdaia, altcostErp ), MATCH($G29,INDIRECT( "roles_"&MATCH(E29, practices, 0)), 0), MATCH($F29, countries, 0)) * INDEX(fx, MATCH($F$6, currency, 0)) * IF($F$7 = "Days", 8, 1), 0 ), 0) -> 183 | U29: =IF(AND(OR(T29=0,T29=""),tb_resource[[#This Row],[Flag if role is not planned]]=1),"This resource is not planned for this region. Check with PS delivery",IF(tb_resource[[#This Row],[Flag if role is not planned]]=1,"This resource is not available. Use cost = " & tb_resource[[#This Row],[cost of unavailable]] & " in the Table B below and check with PS delivery team",IFERROR("role also mapped to " & INDEX(Other_roles[Roles],MATCH(Calculator!$G29,Other_roles[mapped to],0)),""))) -> role also mapped to Engineer III, IV
B30: =IFERROR( INDEX( CHOOSE( MATCH(E30, practices, 0), costAps, costData, costSec, costAdv, costProd, costPvtCld, costSdaia, costErp, costHealth ), MATCH($G30,INDIRECT( "roles_"&MATCH(E30, practices, 0)), 0), MATCH($F30, countries, 0)) * INDEX(fx, MATCH($F$6, currency, 0)) * IF($F$7 = "Days", 8, 1), "" ) | C30: =IF(AND( tb_resource[[#This Row],[Practice Area]]<>0,OR(R30=0,R30="")),1,0) -> 0 | D30: =IF(E30="","",D29+1) | I30: =IFERROR(ROUNDUP(IF(J30="List Price",S30*IF($F$9="Master",1.1,IF($F$9="Sub-agent",1.05,1))*IF($F$3="Fixed Price",1.1,1),IF(K30<1,B30/(1-K30),K30)),0),"") | J30: List Price | K30: 0.5 | L30: =IF(S30="","",H30*I30) | M30: =B30 | N30: =IFERROR(1-B30/I30,"") | O30: =IFERROR(tb_resource[[#This Row],[Price/hr]]*(1-$I$9),"") | P30: =IF(Calculator!$C30=-1,"No resource in region, please work with delivery and finance to get approvals for using this rate",IF(Calculator!$C30=1,"No resource in region or planned in future. Please get special approval from Finance and HR","")) | R30: =IFERROR( INDEX( CHOOSE( MATCH(E30, practices, 0), countAps, countData, countSec, countAdv, countProd, CountPvtCld, countSdaia, countErp, CountHealth ), MATCH($G30, INDIRECT( "roles_"&MATCH(E30, practices, 0)), 0), MATCH($F30, countries, 0)), "" ) | S30: =IFERROR( INDEX( CHOOSE( MATCH(E30, practices, 0), priceAps, priceData, priceSec, priceAdv, priceProd, pricePvtCld, priceSdaia, priceErp, priceHealth ), MATCH($G30,INDIRECT( "roles_"&MATCH(E30, practices, 0)), 0), MATCH($F30, countries, 0)) * INDEX(fx, MATCH($F$6, currency, 0)) * IF($F$7 = "Days", 8, 1), "" ) | T30: =ROUNDUP(IFERROR( INDEX( CHOOSE( MATCH(E30, practices, 0), altcostAps, altcostData, altcostSec, altcostAdv, altcostProd, altcostPvtCld, altcostSdaia, altcostErp ), MATCH($G30,INDIRECT( "roles_"&MATCH(E30, practices, 0)), 0), MATCH($F30, countries, 0)) * INDEX(fx, MATCH($F$6, currency, 0)) * IF($F$7 = "Days", 8, 1), 0 ), 0) -> 0 | U30: =IF(AND(OR(T30=0,T30=""),tb_resource[[#This Row],[Flag if role is not planned]]=1),"This resource is not planned for this region. Check with PS delivery",IF(tb_resource[[#This Row],[Flag if role is not planned]]=1,"This resource is not available. Use cost = " & tb_resource[[#This Row],[cost of unavailable]] & " in the Table B below and check with PS delivery team",IFERROR("role also mapped to " & INDEX(Other_roles[Roles],MATCH(Calculator!$G30,Other_roles[mapped to],0)),"")))
