Workbook

Sheet Instructions
A1: Instructions — dependency-mapping.xlsx
A2: Read this before opening any other tab
A4: PURPOSE
A5: Map application-to-application and application-to-infrastructure dependencies. This is used to identify dependency clusters in Phase 2 and sequence migration waves in Phase 4. Applications with tightly-coupled dependencies cannot be separated across different migration waves.
A7: WHO FILLS THIS IN
A8: Lead Architect (facilitation) + Application Owners (workshop participants). The dependency data comes from two sources: (1) automated discovery tooling (Azure Migrate network dependencies, AWS ADS, GCP Migration Center), and (2) workshops with application owners.
A10: WHEN TO USE
A11: Phase 1 Weeks 2–6. Workshops with application owners should be scheduled in Phase 1 Week 2 while discovery tooling is still collecting data in the background. Do not wait for Phase 1 to complete.
A13: WHAT 'GOOD DATA' LOOKS LIKE
A14: • Every Tier-1 application has its dependencies validated by its application owner
A15: • Dependency Cluster IDs assigned to all tightly-coupled groups
A16: • External dependencies (SaaS, APIs, third-party services) are documented
... A26: CRA Framework v2.0 | Rackspace Cloud Solutions Architecture | dependency-mapping.xlsx

Sheet Dashboard
A1: CLOUD READINESS ASSESSMENT
A2: DEPENDENCY MAPPING TEMPLATE
A4: PROJECT INFORMATION
A5: Field | B5: Value | E5: Field | F5: Value
A6: Project Name | B6: [Enter Project Name] | E6: Project Manager | F6: [Enter PM Name]
A7: Organization | B7: [Enter Organization] | E7: Technical Lead | F7: [Enter Tech Lead]
A8: Assessment Start Date | B8: [Enter Date] | E8: Target Completion | F8: [Enter Date]
A9: Cloud Target(s) | B9: [AWS/Azure/GCP] | E9: Assessment Phase | F9: [Discovery/Analysis]
A11: DISCOVERY METRICS (Auto-Calculated)
A12: Metric | B12: Count | C12: Source
A13: Total Servers Discovered | B13: =COUNTA(Server_Inventory!A:A)-4 | C13: Server_Inventory
A14: Total Network Connections | B14: =COUNTA(Network_Dependencies!A:A)-4 | C14: Network_Dependencies
A15: Total Application Dependencies | B15: =COUNTA(App_Dependencies!A:A)-4 | C15: App_Dependencies
A16: Total Processes Mapped | B16: =COUNTA(Process_Mapping!A:A)-4 | C16: Process_Mapping
A18: DISCOVERY SOURCE BREAKDOWN
A19: Source | B19: Servers | C19: Network | D19: Apps | E19: Processes
A20: AWS ADS | B20: =COUNTIF(Server_Inventory!M:M,"*AWS*") | C20: =COUNTIF(Network_Dependencies!Q:Q,"*AWS*") | D20: =COUNTIF(App_Dependencies!P:P,"*AWS*") | E20: =COUNTIF(Process_Mapping!R:R,"*AWS*")
A21: Azure Migrate | B21: =COUNTIF(Server_Inventory!M:M,"*Azure*") | C21: =COUNTIF(Network_Dependencies!Q:Q,"*Azure*") | D21: =COUNTIF(App_Dependencies!P:P,"*Azure*") | E21: =COUNTIF(Process_Mapping!R:R,"*Azure*")
A22: GCP Migration Center | B22: =COUNTIF(Server_Inventory!M:M,"*GCP*") | C22: =COUNTIF(Network_Dependencies!Q:Q,"*GCP*") | D22: =COUNTIF(App_Dependencies!P:P,"*GCP*") | E22: =COUNTIF(Process_Mapping!R:R,"*GCP*")
A23: Manual Entry | B23: =COUNTIF(Server_Inventory!M:M,"Manual") | C23: =COUNTIF(Network_Dependencies!Q:Q,"Manual") | D23: =COUNTIF(App_Dependencies!P:P,"Manual") | E23: =COUNTIF(Process_Mapping!R:R,"Manual")
A25: DEPENDENCY CRITICALITY ANALYSIS
A26: Criticality Level | B26: Count | C26: Percentage
A27: Critical | B27: =COUNTIF(App_Dependencies!I:I,"Critical") | C27: =IF($B$15>0,TEXT(B27/$B$15,"0%"),"0%")
A28: High | B28: =COUNTIF(App_Dependencies!I:I,"High") | C28: =IF($B$15>0,TEXT(B28/$B$15,"0%"),"0%")
A29: Medium | B29: =COUNTIF(App_Dependencies!I:I,"Medium") | C29: =IF($B$15>0,TEXT(B29/$B$15,"0%"),"0%")
A30: Low | B30: =COUNTIF(App_Dependencies!I:I,"Low") | C30: =IF($B$15>0,TEXT(B30/$B$15,"0%"),"0%")
A32: READINESS ASSESSMENT STATUS
A33: Assessment Area | B33: Status | C33: Completion % | D33: Owner | E33: Notes
A34: Server Discovery | B34: Not Started | C34: 0
A35: Network Dependency Mapping | B35: Not Started | C35: 0
A36: Application Dependency Analysis | B36: Not Started | C36: 0
A37: Process Inventory | B37: Not Started | C37: 0
A38: Data Validation | B38: Not Started | C38: 0
A39: Stakeholder Review | B39: Not Started | C39: 0
A41: TEMPLATE INSTRUCTIONS
A42: Step 1: Fill in Project Information above
A43: Step 2: Deploy cloud discovery tools (AWS ADS, Azure Migrate, GCP Migration Center)
A44: Step 3: Export data and populate inventory sheets
A45: Step 4: Dashboard metrics auto-calculate as data is added
A46: Step 5: Update status and complete stakeholder review
...

Sheet Overview
A1: CLOUD READINESS ASSESSMENT - DEPENDENCY MAPPING TEMPLATE
A2: Reusable Template for Cloud Migration Dependency Discovery
A4: PURPOSE
A5: This template provides a standardized, cloud-agnostic approach to capture dependency mapping data
A6: as part of cloud readiness assessment projects. It is designed to be populated with data from:
A7: • AWS Application Discovery Service (ADS)
A8: • Azure Migrate Dependency Analysis
A9: • Google Cloud Migration Center
A10: • Manual discovery and documentation
A12: CLOUD PROVIDER TOOLS REFERENCE
A13: Cloud Provider | B13: Migration Tool | C13: Dependency Feature | D13: Discovery Method | E13: Export Format
A14: AWS | B14: Application Discovery Service | C14: Agent & Agentless Discovery | D14: TCP Connections, Processes | E14: CSV via Migration Hub
A15: Azure | B15: Azure Migrate | C15: Dependency Analysis | D15: Service Map, TCP Data | E15: CSV, Log Analytics
A16: Google Cloud | B16: Migration Center | C16: Application Dependency Mapping | D16: Topology Scanning | E16: BigQuery, CSV
A18: TEMPLATE SHEETS OVERVIEW
A19: Sheet Name | B19: Purpose | C19: Data Source | D19: Key Fields
A20: Dashboard | B20: Project overview & auto-calculated metrics | C20: Auto-populated from other sheets | D20: Metrics, Status, Progress
A21: Server_Inventory | B21: Master list of discovered servers | C21: Cloud tool exports | D21: Server ID, IP, OS, Resources
A22: Network_Dependencies | B22: TCP connections between servers | C22: Agent-based discovery | D22: Source, Destination, Ports
A23: App_Dependencies | B23: Application-to-application dependencies | C23: Discovery + Manual input | D23: Apps, Criticality, Protocols
A24: Process_Mapping | B24: Running processes on servers | C24: Agent-based discovery | D24: Processes, Ports, Resources
A25: Tool_Reference | B25: Cloud tool guidance | C25: Reference documentation | D25: Commands, Features, Tips
A26: Process_Data_Guide | B26: Detailed instructions for extracting process data | C26: Reference guide - AWS, Azure, GCP extraction methods | D26: Commands, Queries, Field Mappings
A27: Prerequisites_Remediation | B27: Prerequisites, assumptions & remediation guide | C27: Template reference + project tracking | D27: Prerequisites, Assumptions, Gaps, Remediation
A28: HOW TO USE THIS TEMPLATE
A29: Step | B29: Action | C29: Details
A30: 1 | B30: Initialize Project | C30: Fill in project information on Dashboard sheet
A31: 2 | B31: Deploy Discovery Tools | C31: Install AWS ADS Agent, Azure Migrate Appliance, or GCP collectors
A32: 3 | B32: Run Discovery | C32: Allow tools to collect data (typically 1-4 weeks for complete mapping)
A33: 4 | B33: Export Data | C33: Use native export features to download CSV/BigQuery data
A34: 5 | B34: Populate Sheets | C34: Map exported fields to template columns using Tool_Reference guide
A35: 6 | B35: Validate Data | C35: Cross-check dependencies, identify gaps
A36: 7 | B36: Review & Sign-off | C36: Stakeholder review of dependency mapping completeness
A38: DEPENDENCY MAPPING SCOPE
A39: In Scope | B39: Out of Scope
A40: Server discovery and inventory | B40: Migration wave planning
A41: Network dependency mapping (TCP connections) | B41: Target architecture design
A42: Application-to-application dependencies | B42: Migration execution
A43: Process and service mapping | B43: Cost estimation/TCO
A44: Dependency criticality assessment | B44: Workload right-sizing
...

Sheet Server_Inventory
A1: SERVER INVENTORY
A2: Cloud Readiness Assessment - Dependency Mapping Template
A3: Instructions: Populate with data exported from AWS ADS, Azure Migrate, or GCP Migration Center
A5: Server ID | B5: Hostname | C5: FQDN | D5: Primary IP | E5: Secondary IPs | F5: Operating System | G5: OS Version | H5: CPU Cores | I5: RAM (GB) | J5: Storage (GB) | K5: Environment | L5: Data Center/Location | M5: Application Name | N5: Server Role | O5: Hypervisor/Platform | P5: Discovery Source | Q5: Discovery Date | R5: AWS ADS ID | S5: Azure Migrate ID | T5: GCP MC ID
A6: [Auto/Manual] | B6: [hostname] | C6: [fqdn.domain.com] | D6: [x.x.x.x] | E6: [comma separated] | F6: [Windows/Linux] | G6: [version] | H6: [#] | I6: [#] | J6: [#] | K6: [Prod/Dev/Test] | L6: [DC Name] | M6: [App Name] | N6: [Web/DB/App] | O6: [VMware/HyperV/KVM/Physical] | P6: [AWS ADS/Azure Migrate/GCP Migration Center/Manual] | Q6: [YYYY-MM-DD] | R6: [d-server-xxx] | S6: [srv-xxx] | T6: [mc-xxx]

Sheet Network_Dependencies
A1: NETWORK DEPENDENCIES
A2: Cloud Readiness Assessment - TCP Connection Mapping
A3: Instructions: Capture TCP connections from AWS ADS exports, Azure Migrate, or GCP Migration Center
A5: Connection ID | B5: Source Server ID | C5: Source Hostname | D5: Source IP | E5: Source Process | F5: Source Port | G5: Dest Server ID | H5: Dest Hostname | I5: Dest IP | J5: Dest Port | K5: Dest Process | L5: Protocol | M5: Bytes Transferred | N5: Connection Count | O5: First Observed | P5: Last Observed | Q5: Dependency Type | R5: Discovery Source | S5: Notes
A6: [Auto/CON-xxx] | B6: [SRV-xxx] | C6: [hostname] | D6: [x.x.x.x] | E6: [process name] | F6: [port#] | G6: [SRV-xxx] | H6: [hostname] | I6: [x.x.x.x] | J6: [port#] | K6: [process name] | L6: [TCP/UDP] | M6: [bytes] | N6: [count] | O6: [YYYY-MM-DD] | P6: [YYYY-MM-DD] | Q6: [Database/API/Web/Cache/etc] | R6: [AWS ADS/Azure Migrate/GCP Migration Center/Manual] | S6: [notes]

Sheet App_Dependencies
A1: APPLICATION DEPENDENCIES
A2: Cloud Readiness Assessment - Application-to-Application Dependency Mapping
A3: Instructions: Document dependencies between applications for readiness assessment
A5: Dependency ID | B5: Source Application | C5: Source Owner | D5: Source Environment | E5: Target Application | F5: Target Owner | G5: Target Environment | H5: Dependency Direction | I5: Criticality | J5: Protocol | K5: Port(s) | L5: Data Flow Description | M5: SLA Requirement | N5: Can Operate Independently? | O5: Readiness Impact | P5: Discovery Source | Q5: Validation Status | R5: Notes
A6: [APP-DEP-xxx] | B6: [App Name] | C6: [Team/Owner] | D6: [Prod/Dev/Test] | E6: [App Name] | F6: [Team/Owner] | G6: [Prod/Dev/Test] | H6: [Inbound/Outbound/Bidirectional] | I6: [Critical/High/Medium/Low] | J6: [HTTPS/TCP/REST/SOAP] | K6: [port#] | L6: [description] | M6: [99.99%/99.9%/etc] | N6: [Yes/No/Degraded] | O6: [Critical/High/Medium/Low] | P6: [AWS ADS/Azure Migrate/GCP Migration Center/Manual] | Q6: [Validated/Pending/Failed] | R6: [notes]

Sheet Process_Mapping
A1: PROCESS MAPPING
A2: Cloud Readiness Assessment - Server Process Discovery
A3: Instructions: Populate with process data from agent-based discovery (AWS ADS Agent, Azure Dependency Agent)
A5: Process ID | B5: Server ID | C5: Hostname | D5: Process Name | E5: Process Path | F5: Process User | G5: PID | H5: Parent Process | I5: Application Name | J5: Listening Ports | K5: Active Connections | L5: CPU Usage (%) | M5: Memory Usage (MB) | N5: Start Time | O5: Status | P5: Service Type | Q5: Dependencies | R5: Discovery Source | S5: Notes
A6: [PROC-xxx] | B6: [SRV-xxx] | C6: [hostname] | D6: [process] | E6: [/path/to/process] | F6: [user] | G6: [#] | H6: [parent] | I6: [App Name] | J6: [port,port] | K6: [#] | L6: [%] | M6: [MB] | N6: [datetime] | O6: [Running/Stopped] | P6: [Web/DB/App/Cache/Queue] | Q6: [comma separated] | R6: [AWS ADS/Azure Migrate/GCP Migration Center/Manual] | S6: [notes]

Sheet Tool_Reference
A1: CLOUD DEPENDENCY MAPPING - TOOL REFERENCE GUIDE
A2: Quick Reference for AWS, Azure, and Google Cloud Native Discovery Tools
A4: AWS APPLICATION DISCOVERY SERVICE (ADS)
A5: Feature | B5: Description | C5: Data Captured | D5: Export Method | E5: Best Use Case
A6: Agentless Discovery | B6: VMware vCenter Connector OVA | C6: VM inventory, basic metrics | D6: CSV via Migration Hub | E6: Quick inventory scan
A7: Agent-Based Discovery | B7: Discovery Agent on each server | C7: Processes, TCP connections, performance | D7: CSV Export, API | E7: Deep dependency mapping
A8: Network Connections | B8: TCP connection capture between servers | C8: Source/Dest IP, Port, Bytes | D8: Network CSV Export | E8: Server communication mapping
A9: Migration Hub | B9: Centralized discovery dashboard | C9: Aggregated server data | D9: Console, API | E9: Unified view
A11: AWS ADS Export Commands:
A12: Command | B12: Purpose
A13: aws discovery start-export-task | B13: Export data to S3 bucket
A14: aws discovery describe-configurations | B14: Query server configurations
A15: aws discovery list-configurations | B15: List all discovered items
A17: AZURE MIGRATE - DEPENDENCY ANALYSIS
A18: Feature | B18: Description | C18: Data Captured | D18: Export Method | E18: Best Use Case
A19: Agentless Analysis | B19: Azure Migrate Appliance polls TCP | C19: Source/Dest server, process, port | D19: CSV (30 days retention) | E19: VMware, Hyper-V, Physical
A20: Agent-Based Analysis | B20: Log Analytics + Dependency Agent | C20: Connections, latency, data transfer | D20: Log Analytics Query | E20: Deep analysis with Service Map
A21: Dependency Visualization | B21: Interactive map of connections | C21: Visual graph, connection details | D21: Screenshot, CSV | E21: Understanding architecture
A22: Service Map | B22: Azure Monitor solution | C22: Process-level dependencies | D22: Kusto Query | E22: Complex environments
A24: Azure Migrate Capabilities:
A25: Capability | B25: Details
A26: Polling Frequency | B26: Every 5 minutes for TCP data
A27: Data Retention | B27: 30 days (agentless), configurable (agent)
A28: Supported Platforms | B28: VMware, Hyper-V, Physical, AWS, GCP VMs
A30: GOOGLE CLOUD MIGRATION CENTER
A31: Feature | B31: Description | C31: Data Captured | D31: Export Method | E31: Best Use Case
A32: Migration Center Discovery | B32: Automated asset discovery | C32: Server inventory, dependencies | D32: BigQuery, CSV | E32: Multi-cloud environments
A33: Application Mapping | B33: Cross-workload dependencies | C33: Server interactions, topology | D33: BigQuery, Console | E33: Complex architectures
A34: BigQuery Exporter | B34: Advanced analytics export | C34: Full infrastructure data | D34: BigQuery tables | E34: Custom reporting
A36: GCP Partner Tools:
A37: Tool | B37: Provider | C37: Key Feature
A38: CAST Software | B38: CAST | C38: Static code analysis
A39: Matilda Cloud | B39: Matilda | C39: Agentless topology discovery
A40: Txture | B40: Txture | C40: IT infrastructure mapping
A42: DATA FIELD MAPPING GUIDE
A43: Map exported data from each cloud tool to this template's columns
A45: SERVER_INVENTORY FIELD MAPPING
A46: Template Column
A47: Server ID | B47: configurationId | C47: Machine ID | D47: Asset ID
A48: Hostname | B48: server.hostName | C48: Machine name | D48: Name
...

Sheet Process_Data_Guide
A1: PROCESS MAPPING DATA COLLECTION GUIDE
A2: How to Extract Process Data from AWS, Azure, and GCP Migration Tools
A4: AWS APPLICATION DISCOVERY SERVICE - PROCESS DATA EXTRACTION
A5: ⚠️ PREREQUISITE: Agent-Based Discovery Required - Agentless does NOT capture process data
A7: Method 1: AWS Console Export
A8: Step | B8: Action | C8: Details | D8: Output
A9: 1 | B9: Navigate to Migration Hub | C9: AWS Console → Migration Hub → Discover → Servers | D9: Server list
A10: 2 | B10: Select Server | C10: Click on server hostname | D10: Server detail page
A11: 3 | B11: View Processes Tab | C11: Click 'Running processes' tab | D11: Process list
A12: 4 | B12: Export Data | C12: Click 'Export' → Select 'Running processes' | D12: CSV download
A13: 5 | B13: Repeat for All | C13: Export for each server | D13: Multiple CSVs
A15: Method 2: AWS CLI Bulk Export
A16: Command | B16: Purpose
A17: aws discovery start-export-task --export-data-format CSV | B17: Initiates bulk export to S3
A18: aws discovery describe-export-tasks | B18: Check export status
A19: processes.csv in S3 bucket | B19: Contains all process data
A21: AWS ADS → Process_Mapping Field Mapping
A22: Template Column | B22: AWS ADS Field | C22: Notes
A23: Process Name | B23: process.name | C23: Executable name
A24: Process Path | B24: process.cmdLine | C24: Full command line
A25: Process User | B25: process.user | C25: Running user
A26: Listening Ports | B26: process.transportProtocol + portNumber | C26: Combine fields
A27: CPU Usage (%) | B27: process.cpuUsagePct | C27: Average CPU
A28: Memory Usage (MB) | B28: process.memoryUsageMB | C28: Memory consumption
A31: AZURE MIGRATE - PROCESS DATA EXTRACTION
A32: ⚠️ PREREQUISITE: Agentless = limited data | Agent-Based (Service Map) = full process details
A34: Method 1: Agentless Dependency Analysis (Limited Process Data)
A35: Step | B35: Action | C35: Details | D35: Output
A36: 1 | B36: Enable Dependency Analysis | C36: Azure Portal → Azure Migrate → Enable | D36: Polling starts
A37: 2 | B37: Wait 30 days | C37: Appliance polls every 5 minutes | D37: Data accumulates
A38: 3 | B38: View Dependencies | C38: Click server → Dependencies | D38: Process names & ports
A39: 4 | B39: Export CSV | C39: Click 'Export' button | D39: CSV file
A41: Method 2: Agent-Based (Service Map) - RECOMMENDED for Full Process Data
A42: Step | B42: Action | C42: Details | D42: Output
A43: 1 | B43: Create Log Analytics Workspace | C43: Azure Portal → Log Analytics → Create | D43: Workspace ready
A44: 2 | B44: Enable Service Map | C44: Workspace → Solutions → Add Service Map | D44: Solution enabled
A45: 3 | B45: Install Log Analytics Agent | C45: Download & install on servers | D45: Agent reporting
A46: 4 | B46: Install Dependency Agent | C46: Install after LA Agent | D46: Full capture starts
A47: 5 | B47: Query VMProcess table | C47: Log Analytics → Logs → KQL query | D47: Process data
A48: 6 | B48: Export Results | C48: Export query to CSV | D48: All fields available
...

Sheet Prerequisites_Remediation
A1: PREREQUISITES, ASSUMPTIONS & REMEDIATION GUIDE
A2: Cloud Readiness Assessment - Dependency Mapping Template
A3: Document prerequisites, validate assumptions, and define remediation actions when dependency data cannot be captured
A5: AWS APPLICATION DISCOVERY SERVICE (ADS) - PREREQUISITES
A6: Prerequisite Category | B6: Prerequisite Item | C6: Description/Requirement | D6: Status | E6: Responsible Party | F6: Notes/Remediation
A7: Account & Permissions | B7: AWS Account | C7: Active AWS account with billing enabled | D7: ☐ Not Started | E7: [Assign Owner] | F7: Create AWS account if not available
A8: Account & Permissions | B8: IAM Permissions | C8: AWSApplicationDiscoveryServiceFullAccess policy | D8: ☐ Not Started | E8: [Assign Owner] | F8: Create IAM role with required permissions
A9: Account & Permissions | B9: Migration Hub Access | C9: Access to AWS Migration Hub in target region | D9: ☐ Not Started | E9: [Assign Owner] | F9: Enable Migration Hub in supported region
A10: Network Requirements | B10: Outbound Internet | C10: HTTPS (443) to discovery.us-west-2.amazonaws.com | D10: ☐ Not Started | E10: [Assign Owner] | F10: Configure firewall/proxy rules
A11: Network Requirements | B11: Internal Network | C11: Agent must reach all servers to discover | D11: ☐ Not Started | E11: [Assign Owner] | F11: Review network segmentation
A12: Agent-Based Discovery | B12: Discovery Agent | C12: Download and install AWS Discovery Agent on servers | D12: ☐ Not Started | E12: [Assign Owner] | F12: Plan agent deployment strategy
A13: Agent-Based Discovery | B13: Supported OS | C13: Windows 2008R2+, Amazon Linux, Ubuntu, RHEL, CentOS | D13: ☐ Not Started | E13: [Assign Owner] | F13: Identify unsupported OS - use agentless
A14: Agent-Based Discovery | B14: Root/Admin Access | C14: Administrator (Win) or root (Linux) for installation | D14: ☐ Not Started | E14: [Assign Owner] | F14: Obtain elevated credentials
A15: Agentless Discovery | B15: VMware vCenter | C15: vCenter Server 5.5+ with read-only credentials | D15: ☐ Not Started | E15: [Assign Owner] | F15: Request vCenter access from VMware team
A16: Agentless Discovery | B16: OVA Appliance | C16: Deploy Discovery Connector OVA in VMware env | D16: ☐ Not Started | E16: [Assign Owner] | F16: Download OVA from AWS console
A17: Agentless Discovery | B17: vCenter Permissions | C17: Read-only access to VMs, folders, datacenters | D17: ☐ Not Started | E17: [Assign Owner] | F17: Create service account in vCenter
... A22: Documentation | B22: Server Inventory | C22: Initial server list for agent deployment planning | D22: ☐ Not Started | E22: [Assign Owner] | F22: Export from CMDB or manual collection
A24: AZURE MIGRATE - DEPENDENCY ANALYSIS PREREQUISITES
A25: Prerequisite Category | B25: Prerequisite Item | C25: Description/Requirement | D25: Status | E25: Responsible Party | F25: Notes/Remediation
A26: Subscription & Permissions | B26: Azure Subscription | C26: Active Azure subscription with Contributor access | D26: ☐ Not Started | E26: [Assign Owner] | F26: Create subscription or request access
A27: Subscription & Permissions | B27: Resource Group | C27: Resource group for Azure Migrate project | D27: ☐ Not Started | E27: [Assign Owner] | F27: Create RG in target region
A28: Subscription & Permissions | B28: RBAC Permissions | C28: Contributor role on subscription or resource group | D28: ☐ Not Started | E28: [Assign Owner] | F28: Request RBAC assignment from Azure admin
A29: Subscription & Permissions | B29: Azure Migrate Project | C29: Create Azure Migrate project in portal | D29: ☐ Not Started | E29: [Assign Owner] | F29: Navigate to Azure Migrate > Create project
A30: Agentless Discovery | B30: Azure Migrate Appliance | C30: Deploy appliance VM (OVA for VMware, VHD for Hyper-V) | D30: ☐ Not Started | E30: [Assign Owner] | F30: Download from Azure portal
A31: Agentless Discovery | B31: Appliance Requirements | C31: 16 GB RAM, 8 vCPUs, 80 GB disk minimum | D31: ☐ Not Started | E31: [Assign Owner] | F31: Provision VM meeting requirements
A32: Agentless Discovery | B32: vCenter Credentials | C32: Read-only account for VMware vCenter (VMware only) | D32: ☐ Not Started | E32: [Assign Owner] | F32: Create service account
A33: Agentless Discovery | B33: Hyper-V Credentials | C33: Domain or local admin for Hyper-V hosts | D33: ☐ Not Started | E33: [Assign Owner] | F33: Obtain credentials from Hyper-V team
A34: Network Requirements | B34: Outbound Connectivity | C34: HTTPS 443 to *.azure.com, *.microsoftonline.com | D34: ☐ Not Started | E34: [Assign Owner] | F34: Configure proxy/firewall exceptions
A35: Network Requirements | B35: Port Requirements | C35: TCP 443, 5985 (WinRM), 22 (SSH) for discovery | D35: ☐ Not Started | E35: [Assign Owner] | F35: Open required ports
A36: Agent-Based Analysis | B36: Log Analytics Workspace | C36: Create workspace for dependency data storage | D36: ☐ Not Started | E36: [Assign Owner] | F36: Create in same region as Migrate project
... A43: Timeline | B43: Discovery Duration | C43: Minimum 2-4 weeks for comprehensive mapping | D43: ☐ Not Started | E43: [Assign Owner] | F43: Plan in project schedule
A45: GOOGLE CLOUD MIGRATION CENTER - PREREQUISITES
A46: Prerequisite Category | B46: Prerequisite Item | C46: Description/Requirement | D46: Status | E46: Responsible Party | F46: Notes/Remediation
A47: Project & Permissions | B47: GCP Project | C47: Active GCP project with billing enabled | D47: ☐ Not Started | E47: [Assign Owner] | F47: Create project in GCP Console
A48: Project & Permissions | B48: IAM Roles | C48: Migration Center Admin or Editor role | D48: ☐ Not Started | E48: [Assign Owner] | F48: Assign roles/migrationcenter.admin
A49: Project & Permissions | B49: API Enablement | C49: Enable Migration Center API | D49: ☐ Not Started | E49: [Assign Owner] | F49: gcloud services enable migrationcenter.googleapis.com
A50: Project & Permissions | B50: Service Account | C50: Service account for discovery collectors | D50: ☐ Not Started | E50: [Assign Owner] | F50: Create SA with required permissions
A51: Discovery Methods | B51: Discovery Client CLI | C51: Install mcdc (Migration Center Discovery Client) | D51: ☐ Not Started | E51: [Assign Owner] | F51: Download from GCP documentation
A52: Discovery Methods | B52: VMware Discovery | C52: vSphere credentials for VMware environments | D52: ☐ Not Started | E52: [Assign Owner] | F52: Create read-only vCenter account
A53: Discovery Methods | B53: AWS Import | C53: AWS credentials for cross-cloud discovery | D53: ☐ Not Started | E53: [Assign Owner] | F53: Create IAM user with read permissions
...

Sheet Dependency Heat Map
A1: Dependency Heat Map — Applications by Cluster and Coupling Level
A2: Cluster ID | B2: Application Name | C2: App Tier | D2: Coupling Level | E2: Notes
A3: C001 | B3: [App Name - from inventory] | C3: Tier 1 | D3: Tightly Coupled | E3: Cannot migrate independently - shares DB with C001-B
A4: C001 | B4: [App Name - from inventory] | C4: Tier 2 | D4: Tightly Coupled | E4: C001 cluster must move together in same wave
A5: C002 | B5: [App Name - from inventory] | C5: Tier 3 | D5: Loosely Coupled | E5: Soft dependency - can migrate in adjacent wave
A6: NONE | B6: [App Name - from inventory] | C6: Tier 3 | D6: Independent | E6: No dependencies - Wave 0 PoC candidate
A7: Legend: | B7: Tightly Coupled = must migrate in same wave | C7: Loosely Coupled = adjacent wave | D7: Independent = any wave
