Workbook

Sheet Readiness Scoring
A1: Cloud Readiness Scoring Criteria
A2: Version 1.0 | Phase: Analysis/Evaluation | Task 3.3 | Requirements 3.2, 3.9
A4: Scoring Scale Reference
A5: Score Range | B5: Rating | C5: Description | D5: Migration Readiness | E5: Color | F5: Notes
A6: 76-100 | B6: Excellent | C6: Ready for immediate migration | D6: Proceed with migration planning | E6: Green
A7: 51-75 | B7: Good | C7: Ready with minor remediation | D7: Address gaps, then migrate | E7: Yellow
A8: 26-50 | B8: Fair | C8: Significant remediation needed | D8: Remediate before migration | E8: Orange
A9: 0-25 | B9: Poor | C9: Major remediation or stay on-premises | D9: Re-evaluate migration strategy | E9: Red
A11: Dimension 1 — Technical Readiness (Default Weight 25%)
A12: Criterion | B12: Weight | C12: Score (0-100) | D12: Weighted Score | E12: Evidence | F12: Remediation Needed
A13: Architecture Modernization | B13: 0.25 | C13: =IF(COUNT(C14:C16)=0,"",AVERAGE(C14:C16)) | D13: =IF(C13="","",B13*C13)
A14: Monolithic vs. microservices readiness
A15: Containerization readiness
A16: Stateless design patterns
A17: Dependency Complexity | B17: 0.25 | C17: =IF(COUNT(C18:C20)=0,"",AVERAGE(C18:C20)) | D17: =IF(C17="","",B17*C17)
A18: Number of dependencies
A19: Tight coupling assessment
A20: External service dependencies
A21: Technology Stack Compatibility | B21: 0.25 | C21: =IF(COUNT(C22:C24)=0,"",AVERAGE(C22:C24)) | D21: =IF(C21="","",B21*C21)
A22: Cloud-native service availability
A23: Language/framework cloud support
A24: Database cloud compatibility
A25: Platform Support | B25: 0.25 | C25: =IF(COUNT(C26:C28)=0,"",AVERAGE(C26:C28)) | D25: =IF(C25="","",B25*C25)
A26: OS cloud support
A27: Middleware cloud availability
A28: Hardware dependency assessment
A29: Dimension Score (/100) | D29: =IF(COUNTA(C13,C17,C21,C25)=0,"",SUM(D13,D17,D21,D25)) -> 0
A30: Scoring Rationale
A31: Key Remediation Items
A33: Dimension 2 — Operational Readiness (Default Weight 20%)
A34: Criterion | B34: Weight | C34: Score (0-100) | D34: Weighted Score | E34: Evidence | F34: Remediation Needed
A35: Automation Maturity | B35: 0.25 | C35: =IF(COUNT(C36:C38)=0,"",AVERAGE(C36:C38)) | D35: =IF(C35="","",B35*C35)
A36: CI/CD pipeline maturity
A37: Infrastructure as Code adoption
A38: Automated testing coverage
A39: Monitoring Capabilities | B39: 0.25 | C39: =IF(COUNT(C40:C42)=0,"",AVERAGE(C40:C42)) | D39: =IF(C39="","",B39*C39)
A40: Application monitoring
A41: Infrastructure monitoring
A42: Log management and analysis
A43: Incident Response | B43: 0.25 | C43: =IF(COUNT(C44:C46)=0,"",AVERAGE(C44:C46)) | D43: =IF(C43="","",B43*C43)
...

Sheet Lookup
A1: Priority | B1: Multiplier
A2: Very Low Importance | B2: 1
A3: Low Importance | B3: 2
A4: Moderate Importance | B4: 3
A5: High Importance | B5: 4
A6: Very High Importance | B6: 5

Sheet Selection Criteria
A1: Hyperscaler Selection Criteria Matrix (Customer) | R1: Scoring Scale (1–5)
A2: How to use | R2: Score | S2: Rating | T2: Meaning | U2: Typical Guidance
A3: 1) Select Customer Weighting (Very Low → Very High) for each criterion. | R3: 1 | S3: Poor | T3: Major gaps | U3: Not supported / high risk
A4: 2) Enter AWS/Azure/GCP Score (1–5). Weighted points + totals + Fit Meter update automatically. | R4: 2 | S4: Fair | T4: Significant limitations | U4: Workarounds required
A5: Tip: Replace “TBD” justifications with short rationale for each provider decision. | R5: 3 | S5: Good | T5: Meets baseline | U5: Some gaps to remediate
R6: 4 | S6: Very Good | T6: Strong fit | U6: Minor gaps only
A7: Criteria Scoring Table | R7: 5 | S7: Excellent | T7: Best-in-class | U7: Fully aligned / ideal
A9: Strategic Goal | B9: Code | C9: Value Dial | D9: Measurement | E9: customer Weighting | F9: customer Multiplier | G9: Max | H9: AWS Score | I9: AWS Weighted (customer) | J9: Azure Score | K9: Azure Weighted (customer) | L9: GCP Score | M9: GCP Weighted (customer) | N9: AWS Justification | O9: Azure Justification | P9: GCP Justification | R9: Provider Totals & Fit Meter
A10: Technical | B10: TECH-1 | C10: Architecture Modernization | D10: Readiness criterion: Architecture Modernization | E10: High Importance | F10: =IFERROR(VLOOKUP(SelCriteria[[#This Row],[customer Weighting]],LookupTable[[#All],[Priority]:[Multiplier]],2,FALSE),0) -> 4 | G10: =SelCriteria[[#This Row],[customer Multiplier]]*5 -> 20 | H10: 4 | I10: =SelCriteria[[#This Row],[AWS Score]]*SelCriteria[[#This Row],[customer Multiplier]] -> 16 | J10: 4 | K10: =SelCriteria[[#This Row],[Azure Score]]*SelCriteria[[#This Row],[customer Multiplier]] -> 16 | L10: 4 | M10: =SelCriteria[[#This Row],[GCP Score]]*SelCriteria[[#This Row],[customer Multiplier]] -> 16 | N10: TBD | O10: TBD | P10: TBD | R10: Metric | S10: AWS | T10: Azure | U10: GCP
A11: Technical | B11: TECH-2 | C11: Dependency Complexity | D11: Readiness criterion: Dependency Complexity | E11: High Importance | F11: =IFERROR(VLOOKUP(SelCriteria[[#This Row],[customer Weighting]],LookupTable[[#All],[Priority]:[Multiplier]],2,FALSE),0) -> 4 | G11: =SelCriteria[[#This Row],[customer Multiplier]]*5 -> 20 | H11: 4 | I11: =SelCriteria[[#This Row],[AWS Score]]*SelCriteria[[#This Row],[customer Multiplier]] -> 16 | J11: 4 | K11: =SelCriteria[[#This Row],[Azure Score]]*SelCriteria[[#This Row],[customer Multiplier]] -> 16 | L11: 4 | M11: =SelCriteria[[#This Row],[GCP Score]]*SelCriteria[[#This Row],[customer Multiplier]] -> 16 | N11: TBD | O11: TBD | P11: TBD | R11: Weighted Points | S11: =SUBTOTAL(109,SelCriteria[AWS Weighted (customer)]) -> 320 | T11: =SUBTOTAL(109,SelCriteria[Azure Weighted (customer)]) -> 320 | U11: =SUBTOTAL(109,SelCriteria[GCP Weighted (customer)]) -> 320
A12: Technical | B12: TECH-3 | C12: Technology Stack Compatibility | D12: Readiness criterion: Technology Stack Compatibility | E12: High Importance | F12: =IFERROR(VLOOKUP(SelCriteria[[#This Row],[customer Weighting]],LookupTable[[#All],[Priority]:[Multiplier]],2,FALSE),0) -> 4 | G12: =SelCriteria[[#This Row],[customer Multiplier]]*5 -> 20 | H12: 4 | I12: =SelCriteria[[#This Row],[AWS Score]]*SelCriteria[[#This Row],[customer Multiplier]] -> 16 | J12: 4 | K12: =SelCriteria[[#This Row],[Azure Score]]*SelCriteria[[#This Row],[customer Multiplier]] -> 16 | L12: 4 | M12: =SelCriteria[[#This Row],[GCP Score]]*SelCriteria[[#This Row],[customer Multiplier]] -> 16 | N12: TBD | O12: TBD | P12: TBD | R12: Max Points | S12: =SUBTOTAL(109,SelCriteria[Max]) -> 400 | T12: =SUBTOTAL(109,SelCriteria[Max]) -> 400 | U12: =SUBTOTAL(109,SelCriteria[Max]) -> 400
A13: Technical | B13: TECH-4 | C13: Platform Support | D13: Readiness criterion: Platform Support | E13: High Importance | F13: =IFERROR(VLOOKUP(SelCriteria[[#This Row],[customer Weighting]],LookupTable[[#All],[Priority]:[Multiplier]],2,FALSE),0) -> 4 | G13: =SelCriteria[[#This Row],[customer Multiplier]]*5 -> 20 | H13: 4 | I13: =SelCriteria[[#This Row],[AWS Score]]*SelCriteria[[#This Row],[customer Multiplier]] -> 16 | J13: 4 | K13: =SelCriteria[[#This Row],[Azure Score]]*SelCriteria[[#This Row],[customer Multiplier]] -> 16 | L13: 4 | M13: =SelCriteria[[#This Row],[GCP Score]]*SelCriteria[[#This Row],[customer Multiplier]] -> 16 | N13: TBD | O13: TBD | P13: TBD | R13: Fit Meter | S13: =IFERROR(S11/S12,0) -> 0.8 | T13: =IFERROR(T11/T12,0) -> 0.8 | U13: =IFERROR(U11/U12,0) -> 0.8
A14: Operational | B14: OPER-1 | C14: Automation Maturity | D14: Readiness criterion: Automation Maturity | E14: High Importance | F14: =IFERROR(VLOOKUP(SelCriteria[[#This Row],[customer Weighting]],LookupTable[[#All],[Priority]:[Multiplier]],2,FALSE),0) -> 4 | G14: =SelCriteria[[#This Row],[customer Multiplier]]*5 -> 20 | H14: 4 | I14: =SelCriteria[[#This Row],[AWS Score]]*SelCriteria[[#This Row],[customer Multiplier]] -> 16 | J14: 4 | K14: =SelCriteria[[#This Row],[Azure Score]]*SelCriteria[[#This Row],[customer Multiplier]] -> 16 | L14: 4 | M14: =SelCriteria[[#This Row],[GCP Score]]*SelCriteria[[#This Row],[customer Multiplier]] -> 16 | N14: TBD | O14: TBD | P14: TBD | R14: Placing (1=best) | S14: =_xlfn.RANK.EQ(S11,$S$11:$U$11,0) -> 1 | T14: =_xlfn.RANK.EQ(T11,$S$11:$U$11,0) -> 1 | U14: =_xlfn.RANK.EQ(U11,$S$11:$U$11,0) -> 1
A15: Operational | B15: OPER-2 | C15: Monitoring Capabilities | D15: Readiness criterion: Monitoring Capabilities | E15: High Importance | F15: =IFERROR(VLOOKUP(SelCriteria[[#This Row],[customer Weighting]],LookupTable[[#All],[Priority]:[Multiplier]],2,FALSE),0) -> 4 | G15: =SelCriteria[[#This Row],[customer Multiplier]]*5 -> 20 | H15: 4 | I15: =SelCriteria[[#This Row],[AWS Score]]*SelCriteria[[#This Row],[customer Multiplier]] -> 16 | J15: 4 | K15: =SelCriteria[[#This Row],[Azure Score]]*SelCriteria[[#This Row],[customer Multiplier]] -> 16 | L15: 4 | M15: =SelCriteria[[#This Row],[GCP Score]]*SelCriteria[[#This Row],[customer Multiplier]] -> 16 | N15: TBD | O15: TBD | P15: TBD
A16: Operational | B16: OPER-3 | C16: Incident Response | D16: Readiness criterion: Incident Response | E16: High Importance | F16: =IFERROR(VLOOKUP(SelCriteria[[#This Row],[customer Weighting]],LookupTable[[#All],[Priority]:[Multiplier]],2,FALSE),0) -> 4 | G16: =SelCriteria[[#This Row],[customer Multiplier]]*5 -> 20 | H16: 4 | I16: =SelCriteria[[#This Row],[AWS Score]]*SelCriteria[[#This Row],[customer Multiplier]] -> 16 | J16: 4 | K16: =SelCriteria[[#This Row],[Azure Score]]*SelCriteria[[#This Row],[customer Multiplier]] -> 16 | L16: 4 | M16: =SelCriteria[[#This Row],[GCP Score]]*SelCriteria[[#This Row],[customer Multiplier]] -> 16 | N16: TBD | O16: TBD | P16: TBD
A17: Operational | B17: OPER-4 | C17: Operational Complexity | D17: Readiness criterion: Operational Complexity | E17: High Importance | F17: =IFERROR(VLOOKUP(SelCriteria[[#This Row],[customer Weighting]],LookupTable[[#All],[Priority]:[Multiplier]],2,FALSE),0) -> 4 | G17: =SelCriteria[[#This Row],[customer Multiplier]]*5 -> 20 | H17: 4 | I17: =SelCriteria[[#This Row],[AWS Score]]*SelCriteria[[#This Row],[customer Multiplier]] -> 16 | J17: 4 | K17: =SelCriteria[[#This Row],[Azure Score]]*SelCriteria[[#This Row],[customer Multiplier]] -> 16 | L17: 4 | M17: =SelCriteria[[#This Row],[GCP Score]]*SelCriteria[[#This Row],[customer Multiplier]] -> 16 | N17: TBD | O17: TBD | P17: TBD
A18: Security | B18: SECU-1 | C18: Identity Management | D18: Readiness criterion: Identity Management | E18: High Importance | F18: =IFERROR(VLOOKUP(SelCriteria[[#This Row],[customer Weighting]],LookupTable[[#All],[Priority]:[Multiplier]],2,FALSE),0) -> 4 | G18: =SelCriteria[[#This Row],[customer Multiplier]]*5 -> 20 | H18: 4 | I18: =SelCriteria[[#This Row],[AWS Score]]*SelCriteria[[#This Row],[customer Multiplier]] -> 16 | J18: 4 | K18: =SelCriteria[[#This Row],[Azure Score]]*SelCriteria[[#This Row],[customer Multiplier]] -> 16 | L18: 4 | M18: =SelCriteria[[#This Row],[GCP Score]]*SelCriteria[[#This Row],[customer Multiplier]] -> 16 | N18: TBD | O18: TBD | P18: TBD
A19: Security | B19: SECU-2 | C19: Encryption | D19: Readiness criterion: Encryption | E19: High Importance | F19: =IFERROR(VLOOKUP(SelCriteria[[#This Row],[customer Weighting]],LookupTable[[#All],[Priority]:[Multiplier]],2,FALSE),0) -> 4 | G19: =SelCriteria[[#This Row],[customer Multiplier]]*5 -> 20 | H19: 4 | I19: =SelCriteria[[#This Row],[AWS Score]]*SelCriteria[[#This Row],[customer Multiplier]] -> 16 | J19: 4 | K19: =SelCriteria[[#This Row],[Azure Score]]*SelCriteria[[#This Row],[customer Multiplier]] -> 16 | L19: 4 | M19: =SelCriteria[[#This Row],[GCP Score]]*SelCriteria[[#This Row],[customer Multiplier]] -> 16 | N19: TBD | O19: TBD | P19: TBD
A20: Security | B20: SECU-3 | C20: Vulnerability Management | D20: Readiness criterion: Vulnerability Management | E20: High Importance | F20: =IFERROR(VLOOKUP(SelCriteria[[#This Row],[customer Weighting]],LookupTable[[#All],[Priority]:[Multiplier]],2,FALSE),0) -> 4 | G20: =SelCriteria[[#This Row],[customer Multiplier]]*5 -> 20 | H20: 4 | I20: =SelCriteria[[#This Row],[AWS Score]]*SelCriteria[[#This Row],[customer Multiplier]] -> 16 | J20: 4 | K20: =SelCriteria[[#This Row],[Azure Score]]*SelCriteria[[#This Row],[customer Multiplier]] -> 16 | L20: 4 | M20: =SelCriteria[[#This Row],[GCP Score]]*SelCriteria[[#This Row],[customer Multiplier]] -> 16 | N20: TBD | O20: TBD | P20: TBD
A21: Security | B21: SECU-4 | C21: Security Controls | D21: Readiness criterion: Security Controls | E21: High Importance | F21: =IFERROR(VLOOKUP(SelCriteria[[#This Row],[customer Weighting]],LookupTable[[#All],[Priority]:[Multiplier]],2,FALSE),0) -> 4 | G21: =SelCriteria[[#This Row],[customer Multiplier]]*5 -> 20 | H21: 4 | I21: =SelCriteria[[#This Row],[AWS Score]]*SelCriteria[[#This Row],[customer Multiplier]] -> 16 | J21: 4 | K21: =SelCriteria[[#This Row],[Azure Score]]*SelCriteria[[#This Row],[customer Multiplier]] -> 16 | L21: 4 | M21: =SelCriteria[[#This Row],[GCP Score]]*SelCriteria[[#This Row],[customer Multiplier]] -> 16 | N21: TBD | O21: TBD | P21: TBD
A22: Compliance | B22: COMP-1 | C22: Regulatory Requirements | D22: Readiness criterion: Regulatory Requirements | E22: Very High Importance | F22: =IFERROR(VLOOKUP(SelCriteria[[#This Row],[customer Weighting]],LookupTable[[#All],[Priority]:[Multiplier]],2,FALSE),0) -> 5 | G22: =SelCriteria[[#This Row],[customer Multiplier]]*5 -> 25 | H22: 4 | I22: =SelCriteria[[#This Row],[AWS Score]]*SelCriteria[[#This Row],[customer Multiplier]] -> 20 | J22: 4 | K22: =SelCriteria[[#This Row],[Azure Score]]*SelCriteria[[#This Row],[customer Multiplier]] -> 20 | L22: 4 | M22: =SelCriteria[[#This Row],[GCP Score]]*SelCriteria[[#This Row],[customer Multiplier]] -> 20 | N22: TBD | O22: TBD | P22: TBD
A23: Compliance | B23: COMP-2 | C23: Audit Trails | D23: Readiness criterion: Audit Trails | E23: Moderate Importance | F23: =IFERROR(VLOOKUP(SelCriteria[[#This Row],[customer Weighting]],LookupTable[[#All],[Priority]:[Multiplier]],2,FALSE),0) -> 3 | G23: =SelCriteria[[#This Row],[customer Multiplier]]*5 -> 15 | H23: 4 | I23: =SelCriteria[[#This Row],[AWS Score]]*SelCriteria[[#This Row],[customer Multiplier]] -> 12 | J23: 4 | K23: =SelCriteria[[#This Row],[Azure Score]]*SelCriteria[[#This Row],[customer Multiplier]] -> 12 | L23: 4 | M23: =SelCriteria[[#This Row],[GCP Score]]*SelCriteria[[#This Row],[customer Multiplier]] -> 12 | N23: TBD | O23: TBD | P23: TBD
A24: Compliance | B24: COMP-3 | C24: Data Residency | D24: Readiness criterion: Data Residency | E24: Very High Importance | F24: =IFERROR(VLOOKUP(SelCriteria[[#This Row],[customer Weighting]],LookupTable[[#All],[Priority]:[Multiplier]],2,FALSE),0) -> 5 | G24: =SelCriteria[[#This Row],[customer Multiplier]]*5 -> 25 | H24: 4 | I24: =SelCriteria[[#This Row],[AWS Score]]*SelCriteria[[#This Row],[customer Multiplier]] -> 20 | J24: 4 | K24: =SelCriteria[[#This Row],[Azure Score]]*SelCriteria[[#This Row],[customer Multiplier]] -> 20 | L24: 4 | M24: =SelCriteria[[#This Row],[GCP Score]]*SelCriteria[[#This Row],[customer Multiplier]] -> 20 | N24: TBD | O24: TBD | P24: TBD
A25: Compliance | B25: COMP-4 | C25: Certifications | D25: Readiness criterion: Certifications | E25: Moderate Importance | F25: =IFERROR(VLOOKUP(SelCriteria[[#This Row],[customer Weighting]],LookupTable[[#All],[Priority]:[Multiplier]],2,FALSE),0) -> 3 | G25: =SelCriteria[[#This Row],[customer Multiplier]]*5 -> 15 | H25: 4 | I25: =SelCriteria[[#This Row],[AWS Score]]*SelCriteria[[#This Row],[customer Multiplier]] -> 12 | J25: 4 | K25: =SelCriteria[[#This Row],[Azure Score]]*SelCriteria[[#This Row],[customer Multiplier]] -> 12 | L25: 4 | M25: =SelCriteria[[#This Row],[GCP Score]]*SelCriteria[[#This Row],[customer Multiplier]] -> 12 | N25: TBD | O25: TBD | P25: TBD
A26: Business | B26: BUSI-1 | C26: Stakeholder Alignment | D26: Readiness criterion: Stakeholder Alignment | E26: High Importance | F26: =IFERROR(VLOOKUP(SelCriteria[[#This Row],[customer Weighting]],LookupTable[[#All],[Priority]:[Multiplier]],2,FALSE),0) -> 4 | G26: =SelCriteria[[#This Row],[customer Multiplier]]*5 -> 20 | H26: 4 | I26: =SelCriteria[[#This Row],[AWS Score]]*SelCriteria[[#This Row],[customer Multiplier]] -> 16 | J26: 4 | K26: =SelCriteria[[#This Row],[Azure Score]]*SelCriteria[[#This Row],[customer Multiplier]] -> 16 | L26: 4 | M26: =SelCriteria[[#This Row],[GCP Score]]*SelCriteria[[#This Row],[customer Multiplier]] -> 16 | N26: TBD | O26: TBD | P26: TBD
... A29: Business | B29: BUSI-4 | C29: Strategic Fit | D29: Readiness criterion: Strategic Fit | E29: High Importance | F29: =IFERROR(VLOOKUP(SelCriteria[[#This Row],[customer Weighting]],LookupTable[[#All],[Priority]:[Multiplier]],2,FALSE),0) -> 4 | G29: =SelCriteria[[#This Row],[customer Multiplier]]*5 -> 20 | H29: 4 | I29: =SelCriteria[[#This Row],[AWS Score]]*SelCriteria[[#This Row],[customer Multiplier]] -> 16 | J29: 4 | K29: =SelCriteria[[#This Row],[Azure Score]]*SelCriteria[[#This Row],[customer Multiplier]] -> 16 | L29: 4 | M29: =SelCriteria[[#This Row],[GCP Score]]*SelCriteria[[#This Row],[customer Multiplier]] -> 16 | N29: TBD | O29: TBD | P29: TBD
A30: TOTAL | G30: =SUBTOTAL(109,SelCriteria[Max]) -> 400 | I30: =SUBTOTAL(109,SelCriteria[AWS Weighted (customer)]) -> 320 | K30: =SUBTOTAL(109,SelCriteria[Azure Weighted (customer)]) -> 320 | M30: =SUBTOTAL(109,SelCriteria[GCP Weighted (customer)]) -> 320 | P30: =SUBTOTAL(103,SelCriteria[GCP Justification]) -> 20

Sheet ScoringSummary
A1: Strategic Goal | B1: Avg Multiplier | C1: customer Priority | D1: AWS | E1: Azure | F1: GCP | G1: AWS Fit | H1: Azure Fit | I1: GCP Fit
A2: Technical | B2: 4 | C2: High | D2: 4 | E2: 4 | F2: 4 | G2: 0.8 | H2: 0.8 | I2: 0.8
A3: Operational | B3: 4 | C3: High | D3: 4 | E3: 4 | F3: 4 | G3: 0.8 | H3: 0.8 | I3: 0.8
A4: Security | B4: 4 | C4: High | D4: 4 | E4: 4 | F4: 4 | G4: 0.8 | H4: 0.8 | I4: 0.8
A5: Compliance | B5: 4 | C5: High | D5: 4 | E5: 4 | F5: 4 | G5: 0.8 | H5: 0.8 | I5: 0.8
A6: Business | B6: 4 | C6: High | D6: 4 | E6: 4 | F6: 4 | G6: 0.8 | H6: 0.8 | I6: 0.8
A8: WEIGHTED AVERAGE | D8: 4 | E8: 4 | F8: 4
A9: ABSOLUTE SCORE | D9: 320 | E9: 320 | F9: 320
A10: FIT METER | D10: 0.8 | E10: 0.8 | F10: 0.8
A11: PLACING | D11: 1 | E11: 1 | F11: 1
A12: (Replace placeholder scores in Selection Criteria)
